//Schematic to java Structure by jajo_11 | inspired by "MITHION'S .SCHEMATIC TO JAVA CONVERTINGTOOL"

package com.hbm.world.dungeon;

import java.util.Random;

import com.hbm.blocks.ModBlocks;
import com.hbm.config.GeneralConfig;
import com.hbm.itempool.ItemPool;
import com.hbm.itempool.ItemPoolsLegacy;
import com.hbm.lib.Library;
import com.hbm.util.LootGenerator;

import net.minecraft.block.Block;
import net.minecraft.block.material.Material;
import net.minecraft.init.Blocks;
import net.minecraft.tileentity.TileEntityChest;
import net.minecraft.util.WeightedRandomChestContent;
import net.minecraft.world.World;
import net.minecraft.world.gen.feature.WorldGenerator;

public class Satellite extends WorldGenerator
{
	Block dSteel = ModBlocks.deco_steel;
	Block Block3 = ModBlocks.steel_scaffold;
	Block Block4 = ModBlocks.deco_beryllium;
	Block Block5 = ModBlocks.deco_titanium;
	Block dTape = ModBlocks.tape_recorder;
	Block Block7 = ModBlocks.deco_tungsten;
	
	int s2 = 0;
	int s3 = 0;
	int s4 = 8;
	int s5 = 8;
	
	protected Block[] GetValidSpawnBlocks() {
		return new Block[] { Blocks.grass, Blocks.dirt, Blocks.stone, Blocks.sand, Blocks.sandstone };
	}

	public boolean LocationIsValidSpawn(World world, int x, int y, int z) {

		Block checkBlock = world.getBlock(x, y - 1, z);
		Block blockAbove = world.getBlock(x, y, z);
		Block blockBelow = world.getBlock(x, y - 2, z);

		for(Block i : GetValidSpawnBlocks()) {
			if(blockAbove != Blocks.air) {
				return false;
			}
			if(checkBlock == i) {
				return true;
			} else if(checkBlock == Blocks.snow_layer && blockBelow == i) {
				return true;
			} else if(checkBlock.getMaterial() == Material.plants && blockBelow == i) {
				return true;
			}
		}
		return false;
	}

	@Override
	public boolean generate(World world, Random rand, int x, int y, int z) {
		int i = rand.nextInt(1);

		if(i == 0) {
			generate_r0(world, rand, x, y, z);
		}

		return true;
	}

	public boolean generate_r0(World world, Random rand, int x, int y, int z) {
		
		if(!LocationIsValidSpawn(world, x, y, z) || !LocationIsValidSpawn(world, x + 24, y, z) || !LocationIsValidSpawn(world, x + 24, y, z + 30) || !LocationIsValidSpawn(world, x, y, z + 30)) {
			return false;
		}

		world.setBlock(x + 18, y + -3, z + 9, Library.getRandomConcrete(), 0, 3);
		world.setBlock(x + 19, y + -3, z + 9, Library.getRandomConcrete(), 0, 3);
		world.setBlock(x + 20, y + -3, z + 9, Library.getRandomConcrete(), 0, 3);
		world.setBlock(x + 17, y + -3, z + 10, Library.getRandomConcrete(), 0, 3);
		world.setBlock(x + 18, y + -3, z + 10, Library.getRandomConcrete(), 0, 3);
		world.setBlock(x + 19, y + -3, z + 10, Library.getRandomConcrete(), 0, 3);
		world.setBlock(x + 20, y + -3, z + 10, Library.getRandomConcrete(), 0, 3);
		world.setBlock(x + 21, y + -3, z + 10, Library.getRandomConcrete(), 0, 3);
		world.setBlock(x + 16, y + -3, z + 11, Library.getRandomConcrete(), 0, 3);
		world.setBlock(x + 17, y + -3, z + 11, Library.getRandomConcrete(), 0, 3);
		world.setBlock(x + 18, y + -3, z + 11, Library.getRandomConcrete(), 0, 3);
		world.setBlock(x + 19, y + -3, z + 11, Library.getRandomConcrete(), 0, 3);
		world.setBlock(x + 20, y + -3, z + 11, Library.getRandomConcrete(), 0, 3);
		world.setBlock(x + 21, y + -3, z + 11, Library.getRandomConcrete(), 0, 3);
		world.setBlock(x + 22, y + -3, z + 11, Library.getRandomConcrete(), 0, 3);
		world.setBlock(x + 16, y + -3, z + 12, Library.getRandomConcrete(), 0, 3);
		world.setBlock(x + 17, y + -3, z + 12, Library.getRandomConcrete(), 0, 3);
		world.setBlock(x + 18, y + -3, z + 12, Library.getRandomConcrete(), 0, 3);
		world.setBlock(x + 19, y + -3, z + 12, Library.getRandomConcrete(), 0, 3);
		world.setBlock(x + 20, y + -3, z + 12, Library.getRandomConcrete(), 0, 3);
		world.setBlock(x + 21, y + -3, z + 12, Library.getRandomConcrete(), 0, 3);
		world.setBlock(x + 22, y + -3, z + 12, Library.getRandomConcrete(), 0, 3);
		world.setBlock(x + 16, y + -3, z + 13, Library.getRandomConcrete(), 0, 3);
		world.setBlock(x + 17, y + -3, z + 13, Library.getRandomConcrete(), 0, 3);
		world.setBlock(x + 18, y + -3, z + 13, Library.getRandomConcrete(), 0, 3);
		world.setBlock(x + 19, y + -3, z + 13, Library.getRandomConcrete(), 0, 3);
		world.setBlock(x + 20, y + -3, z + 13, Library.getRandomConcrete(), 0, 3);
		world.setBlock(x + 21, y + -3, z + 13, Library.getRandomConcrete(), 0, 3);
		world.setBlock(x + 22, y + -3, z + 13, Library.getRandomConcrete(), 0, 3);
		world.setBlock(x + 17, y + -3, z + 14, Library.getRandomConcrete(), 0, 3);
		world.setBlock(x + 18, y + -3, z + 14, Library.getRandomConcrete(), 0, 3);
		world.setBlock(x + 19, y + -3, z + 14, Library.getRandomConcrete(), 0, 3);
		world.setBlock(x + 20, y + -3, z + 14, Library.getRandomConcrete(), 0, 3);
		world.setBlock(x + 21, y + -3, z + 14, Library.getRandomConcrete(), 0, 3);
		world.setBlock(x + 18, y + -3, z + 15, Library.getRandomConcrete(), 0, 3);
		world.setBlock(x + 19, y + -3, z + 15, Library.getRandomConcrete(), 0, 3);
		world.setBlock(x + 20, y + -3, z + 15, Library.getRandomConcrete(), 0, 3);
		world.setBlock(x + 6, y + -3, z + 16, Library.getRandomConcrete(), 0, 3);
		world.setBlock(x + 7, y + -3, z + 16, Library.getRandomConcrete(), 0, 3);
		world.setBlock(x + 8, y + -3, z + 16, Library.getRandomConcrete(), 0, 3);
		world.setBlock(x + 18, y + -3, z + 16, Library.getRandomConcrete(), 0, 3);
		world.setBlock(x + 19, y + -3, z + 16, Library.getRandomConcrete(), 0, 3);
		world.setBlock(x + 20, y + -3, z + 16, Library.getRandomConcrete(), 0, 3);
		world.setBlock(x + 6, y + -3, z + 17, Library.getRandomConcrete(), 0, 3);
		world.setBlock(x + 7, y + -3, z + 17, Library.getRandomConcrete(), 0, 3);
		world.setBlock(x + 8, y + -3, z + 17, Library.getRandomConcrete(), 0, 3);
		world.setBlock(x + 18, y + -3, z + 17, Library.getRandomConcrete(), 0, 3);
		world.setBlock(x + 19, y + -3, z + 17, Library.getRandomConcrete(), 0, 3);
		world.setBlock(x + 20, y + -3, z + 17, Library.getRandomConcrete(), 0, 3);
		world.setBlock(x + 6, y + -3, z + 18, Library.getRandomConcrete(), 0, 3);
		world.setBlock(x + 7, y + -3, z + 18, Library.getRandomConcrete(), 0, 3);
		world.setBlock(x + 8, y + -3, z + 18, Library.getRandomConcrete(), 0, 3);
		world.setBlock(x + 18, y + -3, z + 18, Library.getRandomConcrete(), 0, 3);
		world.setBlock(x + 19, y + -3, z + 18, Library.getRandomConcrete(), 0, 3);
		world.setBlock(x + 20, y + -3, z + 18, Library.getRandomConcrete(), 0, 3);
		world.setBlock(x + 6, y + -3, z + 28, Library.getRandomConcrete(), 0, 3);
		world.setBlock(x + 7, y + -3, z + 28, Library.getRandomConcrete(), 0, 3);
		world.setBlock(x + 8, y + -3, z + 28, Library.getRandomConcrete(), 0, 3);
		world.setBlock(x + 18, y + -3, z + 28, Library.getRandomConcrete(), 0, 3);
		world.setBlock(x + 19, y + -3, z + 28, Library.getRandomConcrete(), 0, 3);
		world.setBlock(x + 20, y + -3, z + 28, Library.getRandomConcrete(), 0, 3);
		world.setBlock(x + 6, y + -3, z + 29, Library.getRandomConcrete(), 0, 3);
		world.setBlock(x + 7, y + -3, z + 29, Library.getRandomConcrete(), 0, 3);
		world.setBlock(x + 8, y + -3, z + 29, Library.getRandomConcrete(), 0, 3);
		world.setBlock(x + 18, y + -3, z + 29, Library.getRandomConcrete(), 0, 3);
		world.setBlock(x + 19, y + -3, z + 29, Library.getRandomConcrete(), 0, 3);
		world.setBlock(x + 20, y + -3, z + 29, Library.getRandomConcrete(), 0, 3);
		world.setBlock(x + 6, y + -3, z + 30, Library.getRandomConcrete(), 0, 3);
		world.setBlock(x + 7, y + -3, z + 30, Library.getRandomConcrete(), 0, 3);
		world.setBlock(x + 8, y + -3, z + 30, Library.getRandomConcrete(), 0, 3);
		world.setBlock(x + 18, y + -3, z + 30, Library.getRandomConcrete(), 0, 3);
		world.setBlock(x + 19, y + -3, z + 30, Library.getRandomConcrete(), 0, 3);
		world.setBlock(x + 20, y + -3, z + 30, Library.getRandomConcrete(), 0, 3);
		world.setBlock(x + 18, y + -2, z + 9, Library.getRandomConcrete(), 0, 3);
		world.setBlock(x + 19, y + -2, z + 9, Library.getRandomConcrete(), 0, 3);
		world.setBlock(x + 20, y + -2, z + 9, Library.getRandomConcrete(), 0, 3);
		world.setBlock(x + 17, y + -2, z + 10, Library.getRandomConcrete(), 0, 3);
		world.setBlock(x + 18, y + -2, z + 10, Library.getRandomConcrete(), 0, 3);
		world.setBlock(x + 19, y + -2, z + 10, Library.getRandomConcrete(), 0, 3);
		world.setBlock(x + 20, y + -2, z + 10, Library.getRandomConcrete(), 0, 3);
		world.setBlock(x + 21, y + -2, z + 10, Library.getRandomConcrete(), 0, 3);
		world.setBlock(x + 16, y + -2, z + 11, Library.getRandomConcrete(), 0, 3);
		world.setBlock(x + 17, y + -2, z + 11, Library.getRandomConcrete(), 0, 3);
		world.setBlock(x + 18, y + -2, z + 11, Library.getRandomConcrete(), 0, 3);
		world.setBlock(x + 19, y + -2, z + 11, Library.getRandomConcrete(), 0, 3);
		world.setBlock(x + 20, y + -2, z + 11, Library.getRandomConcrete(), 0, 3);
		world.setBlock(x + 21, y + -2, z + 11, Library.getRandomConcrete(), 0, 3);
		world.setBlock(x + 22, y + -2, z + 11, Library.getRandomConcrete(), 0, 3);
		world.setBlock(x + 16, y + -2, z + 12, Library.getRandomConcrete(), 0, 3);
		world.setBlock(x + 17, y + -2, z + 12, Library.getRandomConcrete(), 0, 3);
		world.setBlock(x + 18, y + -2, z + 12, Library.getRandomConcrete(), 0, 3);
		world.setBlock(x + 19, y + -2, z + 12, Library.getRandomConcrete(), 0, 3);
		world.setBlock(x + 20, y + -2, z + 12, Library.getRandomConcrete(), 0, 3);
		world.setBlock(x + 21, y + -2, z + 12, Library.getRandomConcrete(), 0, 3);
		world.setBlock(x + 22, y + -2, z + 12, Library.getRandomConcrete(), 0, 3);
		world.setBlock(x + 16, y + -2, z + 13, Library.getRandomConcrete(), 0, 3);
		world.setBlock(x + 17, y + -2, z + 13, Library.getRandomConcrete(), 0, 3);
		world.setBlock(x + 18, y + -2, z + 13, Library.getRandomConcrete(), 0, 3);
		world.setBlock(x + 19, y + -2, z + 13, Library.getRandomConcrete(), 0, 3);
		world.setBlock(x + 20, y + -2, z + 13, Library.getRandomConcrete(), 0, 3);
		world.setBlock(x + 21, y + -2, z + 13, Library.getRandomConcrete(), 0, 3);
		world.setBlock(x + 22, y + -2, z + 13, Library.getRandomConcrete(), 0, 3);
		world.setBlock(x + 17, y + -2, z + 14, Library.getRandomConcrete(), 0, 3);
		world.setBlock(x + 18, y + -2, z + 14, Library.getRandomConcrete(), 0, 3);
		world.setBlock(x + 19, y + -2, z + 14, Library.getRandomConcrete(), 0, 3);
		world.setBlock(x + 20, y + -2, z + 14, Library.getRandomConcrete(), 0, 3);
		world.setBlock(x + 21, y + -2, z + 14, Library.getRandomConcrete(), 0, 3);
		world.setBlock(x + 18, y + -2, z + 15, Library.getRandomConcrete(), 0, 3);
		world.setBlock(x + 19, y + -2, z + 15, Library.getRandomConcrete(), 0, 3);
		world.setBlock(x + 20, y + -2, z + 15, Library.getRandomConcrete(), 0, 3);
		world.setBlock(x + 6, y + -2, z + 16, Library.getRandomConcrete(), 0, 3);
		world.setBlock(x + 7, y + -2, z + 16, Library.getRandomConcrete(), 0, 3);
		world.setBlock(x + 8, y + -2, z + 16, Library.getRandomConcrete(), 0, 3);
		world.setBlock(x + 18, y + -2, z + 16, Library.getRandomConcrete(), 0, 3);
		world.setBlock(x + 19, y + -2, z + 16, Library.getRandomConcrete(), 0, 3);
		world.setBlock(x + 20, y + -2, z + 16, Library.getRandomConcrete(), 0, 3);
		world.setBlock(x + 6, y + -2, z + 17, Library.getRandomConcrete(), 0, 3);
		world.setBlock(x + 7, y + -2, z + 17, dSteel, 0, 3);
		world.setBlock(x + 8, y + -2, z + 17, Library.getRandomConcrete(), 0, 3);
		world.setBlock(x + 18, y + -2, z + 17, Library.getRandomConcrete(), 0, 3);
		world.setBlock(x + 19, y + -2, z + 17, dSteel, 0, 3);
		world.setBlock(x + 20, y + -2, z + 17, Library.getRandomConcrete(), 0, 3);
		world.setBlock(x + 6, y + -2, z + 18, Library.getRandomConcrete(), 0, 3);
		world.setBlock(x + 7, y + -2, z + 18, Library.getRandomConcrete(), 0, 3);
		world.setBlock(x + 8, y + -2, z + 18, Library.getRandomConcrete(), 0, 3);
		world.setBlock(x + 18, y + -2, z + 18, Library.getRandomConcrete(), 0, 3);
		world.setBlock(x + 19, y + -2, z + 18, Library.getRandomConcrete(), 0, 3);
		world.setBlock(x + 20, y + -2, z + 18, Library.getRandomConcrete(), 0, 3);
		world.setBlock(x + 6, y + -2, z + 28, Library.getRandomConcrete(), 0, 3);
		world.setBlock(x + 7, y + -2, z + 28, Library.getRandomConcrete(), 0, 3);
		world.setBlock(x + 8, y + -2, z + 28, Library.getRandomConcrete(), 0, 3);
		world.setBlock(x + 18, y + -2, z + 28, Library.getRandomConcrete(), 0, 3);
		world.setBlock(x + 19, y + -2, z + 28, Library.getRandomConcrete(), 0, 3);
		world.setBlock(x + 20, y + -2, z + 28, Library.getRandomConcrete(), 0, 3);
		world.setBlock(x + 6, y + -2, z + 29, Library.getRandomConcrete(), 0, 3);
		world.setBlock(x + 7, y + -2, z + 29, dSteel, 0, 3);
		world.setBlock(x + 8, y + -2, z + 29, Library.getRandomConcrete(), 0, 3);
		world.setBlock(x + 18, y + -2, z + 29, Library.getRandomConcrete(), 0, 3);
		world.setBlock(x + 19, y + -2, z + 29, dSteel, 0, 3);
		world.setBlock(x + 20, y + -2, z + 29, Library.getRandomConcrete(), 0, 3);
		world.setBlock(x + 6, y + -2, z + 30, Library.getRandomConcrete(), 0, 3);
		world.setBlock(x + 7, y + -2, z + 30, Library.getRandomConcrete(), 0, 3);
		world.setBlock(x + 8, y + -2, z + 30, Library.getRandomConcrete(), 0, 3);
		world.setBlock(x + 18, y + -2, z + 30, Library.getRandomConcrete(), 0, 3);
		world.setBlock(x + 19, y + -2, z + 30, Library.getRandomConcrete(), 0, 3);
		world.setBlock(x + 20, y + -2, z + 30, Library.getRandomConcrete(), 0, 3);
		world.setBlock(x + 5, y + -1, z + 8, Library.getRandomConcrete(), 0, 3);
		world.setBlock(x + 13, y + -1, z + 8, Library.getRandomConcrete(), 0, 3);
		world.setBlock(x + 21, y + -1, z + 8, dSteel, 0, 3);
		world.setBlock(x + 22, y + -1, z + 8, dSteel, 0, 3);
		world.setBlock(x + 18, y + -1, z + 9, Library.getRandomConcrete(), 0, 3);
		world.setBlock(x + 19, y + -1, z + 9, Library.getRandomConcrete(), 0, 3);
		world.setBlock(x + 20, y + -1, z + 9, Library.getRandomConcrete(), 0, 3);
		world.setBlock(x + 21, y + -1, z + 9, dSteel, 0, 3);
		world.setBlock(x + 22, y + -1, z + 9, dSteel, 0, 3);
		world.setBlock(x + 17, y + -1, z + 10, Library.getRandomConcrete(), 0, 3);
		world.setBlock(x + 18, y + -1, z + 10, Library.getRandomConcrete(), 0, 3);
		world.setBlock(x + 19, y + -1, z + 10, Library.getRandomConcrete(), 0, 3);
		world.setBlock(x + 20, y + -1, z + 10, Library.getRandomConcrete(), 0, 3);
		world.setBlock(x + 21, y + -1, z + 10, Library.getRandomConcrete(), 0, 3);
		world.setBlock(x + 16, y + -1, z + 11, Library.getRandomConcrete(), 0, 3);
		world.setBlock(x + 17, y + -1, z + 11, Library.getRandomConcrete(), 0, 3);
		world.setBlock(x + 18, y + -1, z + 11, Library.getRandomConcrete(), 0, 3);
		world.setBlock(x + 19, y + -1, z + 11, Library.getRandomConcrete(), 0, 3);
		world.setBlock(x + 20, y + -1, z + 11, Library.getRandomConcrete(), 0, 3);
		world.setBlock(x + 21, y + -1, z + 11, Library.getRandomConcrete(), 0, 3);
		world.setBlock(x + 22, y + -1, z + 11, Library.getRandomConcrete(), 0, 3);
		world.setBlock(x + 16, y + -1, z + 12, Library.getRandomConcrete(), 0, 3);
		world.setBlock(x + 17, y + -1, z + 12, Library.getRandomConcrete(), 0, 3);
		world.setBlock(x + 18, y + -1, z + 12, Library.getRandomConcrete(), 0, 3);
		world.setBlock(x + 19, y + -1, z + 12, Library.getRandomConcrete(), 0, 3);
		world.setBlock(x + 20, y + -1, z + 12, Library.getRandomConcrete(), 0, 3);
		world.setBlock(x + 21, y + -1, z + 12, Library.getRandomConcrete(), 0, 3);
		world.setBlock(x + 22, y + -1, z + 12, Library.getRandomConcrete(), 0, 3);
		world.setBlock(x + 16, y + -1, z + 13, Library.getRandomConcrete(), 0, 3);
		world.setBlock(x + 17, y + -1, z + 13, Library.getRandomConcrete(), 0, 3);
		world.setBlock(x + 18, y + -1, z + 13, Library.getRandomConcrete(), 0, 3);
		world.setBlock(x + 19, y + -1, z + 13, Library.getRandomConcrete(), 0, 3);
		world.setBlock(x + 20, y + -1, z + 13, Library.getRandomConcrete(), 0, 3);
		world.setBlock(x + 21, y + -1, z + 13, Library.getRandomConcrete(), 0, 3);
		world.setBlock(x + 22, y + -1, z + 13, Library.getRandomConcrete(), 0, 3);
		world.setBlock(x + 17, y + -1, z + 14, Library.getRandomConcrete(), 0, 3);
		world.setBlock(x + 18, y + -1, z + 14, Library.getRandomConcrete(), 0, 3);
		world.setBlock(x + 19, y + -1, z + 14, Library.getRandomConcrete(), 0, 3);
		world.setBlock(x + 20, y + -1, z + 14, Library.getRandomConcrete(), 0, 3);
		world.setBlock(x + 21, y + -1, z + 14, Library.getRandomConcrete(), 0, 3);
		world.setBlock(x + 18, y + -1, z + 15, Library.getRandomConcrete(), 0, 3);
		world.setBlock(x + 19, y + -1, z + 15, Library.getRandomConcrete(), 0, 3);
		world.setBlock(x + 20, y + -1, z + 15, Library.getRandomConcrete(), 0, 3);
		world.setBlock(x + 6, y + -1, z + 16, Library.getRandomConcrete(), 0, 3);
		world.setBlock(x + 7, y + -1, z + 16, Library.getRandomConcrete(), 0, 3);
		world.setBlock(x + 8, y + -1, z + 16, Library.getRandomConcrete(), 0, 3);
		world.setBlock(x + 18, y + -1, z + 16, Library.getRandomConcrete(), 0, 3);
		world.setBlock(x + 19, y + -1, z + 16, Library.getRandomConcrete(), 0, 3);
		world.setBlock(x + 20, y + -1, z + 16, Library.getRandomConcrete(), 0, 3);
		world.setBlock(x + 6, y + -1, z + 17, Library.getRandomConcrete(), 0, 3);
		world.setBlock(x + 7, y + -1, z + 17, dSteel, 0, 3);
		world.setBlock(x + 8, y + -1, z + 17, Library.getRandomConcrete(), 0, 3);
		world.setBlock(x + 18, y + -1, z + 17, Library.getRandomConcrete(), 0, 3);
		world.setBlock(x + 19, y + -1, z + 17, dSteel, 0, 3);
		world.setBlock(x + 20, y + -1, z + 17, Library.getRandomConcrete(), 0, 3);
		world.setBlock(x + 6, y + -1, z + 18, Library.getRandomConcrete(), 0, 3);
		world.setBlock(x + 7, y + -1, z + 18, Library.getRandomConcrete(), 0, 3);
		world.setBlock(x + 8, y + -1, z + 18, Library.getRandomConcrete(), 0, 3);
		world.setBlock(x + 18, y + -1, z + 18, Library.getRandomConcrete(), 0, 3);
		world.setBlock(x + 19, y + -1, z + 18, Library.getRandomConcrete(), 0, 3);
		world.setBlock(x + 20, y + -1, z + 18, Library.getRandomConcrete(), 0, 3);
		world.setBlock(x + 5, y + -1, z + 23, Library.getRandomConcrete(), 0, 3);
		world.setBlock(x + 6, y + -1, z + 28, Library.getRandomConcrete(), 0, 3);
		world.setBlock(x + 7, y + -1, z + 28, Library.getRandomConcrete(), 0, 3);
		world.setBlock(x + 8, y + -1, z + 28, Library.getRandomConcrete(), 0, 3);
		world.setBlock(x + 18, y + -1, z + 28, Library.getRandomConcrete(), 0, 3);
		world.setBlock(x + 19, y + -1, z + 28, Library.getRandomConcrete(), 0, 3);
		world.setBlock(x + 20, y + -1, z + 28, Library.getRandomConcrete(), 0, 3);
		world.setBlock(x + 6, y + -1, z + 29, Library.getRandomConcrete(), 0, 3);
		world.setBlock(x + 7, y + -1, z + 29, dSteel, 0, 3);
		world.setBlock(x + 8, y + -1, z + 29, Library.getRandomConcrete(), 0, 3);
		world.setBlock(x + 18, y + -1, z + 29, Library.getRandomConcrete(), 0, 3);
		world.setBlock(x + 19, y + -1, z + 29, dSteel, 0, 3);
		world.setBlock(x + 20, y + -1, z + 29, Library.getRandomConcrete(), 0, 3);
		world.setBlock(x + 6, y + -1, z + 30, Library.getRandomConcrete(), 0, 3);
		world.setBlock(x + 7, y + -1, z + 30, Library.getRandomConcrete(), 0, 3);
		world.setBlock(x + 8, y + -1, z + 30, Library.getRandomConcrete(), 0, 3);
		world.setBlock(x + 18, y + -1, z + 30, Library.getRandomConcrete(), 0, 3);
		world.setBlock(x + 19, y + -1, z + 30, Library.getRandomConcrete(), 0, 3);
		world.setBlock(x + 20, y + -1, z + 30, Library.getRandomConcrete(), 0, 3);
		world.setBlock(x + 5, y + 0, z + 8, Block3, s3, 3);
		world.setBlock(x + 13, y + 0, z + 8, Block3, s3, 3);
		world.setBlock(x + 19, y + 0, z + 8, dSteel, 0, 3);
		world.setBlock(x + 20, y + 0, z + 8, dSteel, 0, 3);
		world.setBlock(x + 21, y + 0, z + 8, ModBlocks.fence_metal, 0, 3);
		world.setBlock(x + 22, y + 0, z + 8, ModBlocks.fence_metal, 0, 3);
		world.setBlock(x + 19, y + 0, z + 9, dSteel, 0, 3);
		world.setBlock(x + 20, y + 0, z + 9, dSteel, 0, 3);
		world.setBlock(x + 18, y + 0, z + 10, Library.getRandomConcrete(), 0, 3);
		world.setBlock(x + 19, y + 0, z + 10, Library.getRandomConcrete(), 0, 3);
		world.setBlock(x + 20, y + 0, z + 10, Library.getRandomConcrete(), 0, 3);
		world.setBlock(x + 17, y + 0, z + 11, Library.getRandomConcrete(), 0, 3);
		world.setBlock(x + 18, y + 0, z + 11, Library.getRandomConcrete(), 0, 3);
		world.setBlock(x + 19, y + 0, z + 11, Library.getRandomConcrete(), 0, 3);
		world.setBlock(x + 20, y + 0, z + 11, Library.getRandomConcrete(), 0, 3);
		world.setBlock(x + 21, y + 0, z + 11, Library.getRandomConcrete(), 0, 3);
		world.setBlock(x + 17, y + 0, z + 12, Library.getRandomConcrete(), 0, 3);
		world.setBlock(x + 18, y + 0, z + 12, Library.getRandomConcrete(), 0, 3);
		world.setBlock(x + 19, y + 0, z + 12, Library.getRandomConcrete(), 0, 3);
		world.setBlock(x + 20, y + 0, z + 12, Library.getRandomConcrete(), 0, 3);
		world.setBlock(x + 21, y + 0, z + 12, Library.getRandomConcrete(), 0, 3);
		world.setBlock(x + 17, y + 0, z + 13, Library.getRandomConcrete(), 0, 3);
		world.setBlock(x + 18, y + 0, z + 13, Library.getRandomConcrete(), 0, 3);
		world.setBlock(x + 19, y + 0, z + 13, Library.getRandomConcrete(), 0, 3);
		world.setBlock(x + 20, y + 0, z + 13, Library.getRandomConcrete(), 0, 3);
		world.setBlock(x + 21, y + 0, z + 13, Library.getRandomConcrete(), 0, 3);
		world.setBlock(x + 18, y + 0, z + 14, Library.getRandomConcrete(), 0, 3);
		world.setBlock(x + 19, y + 0, z + 14, Library.getRandomConcrete(), 0, 3);
		world.setBlock(x + 20, y + 0, z + 14, Library.getRandomConcrete(), 0, 3);
		world.setBlock(x + 7, y + 0, z + 17, Block4, 0, 3);
		world.setBlock(x + 19, y + 0, z + 17, Block4, 0, 3);
		world.setBlock(x + 5, y + 0, z + 23, Block3, s5, 3);
		world.setBlock(x + 7, y + 0, z + 29, Block4, 0, 3);
		world.setBlock(x + 19, y + 0, z + 29, Block4, 0, 3);
		world.setBlock(x + 5, y + 1, z + 8, Block3, s3, 3);
		world.setBlock(x + 13, y + 1, z + 8, Block3, s3, 3);
		world.setBlock(x + 17, y + 1, z + 8, dSteel, 0, 3);
		world.setBlock(x + 18, y + 1, z + 8, dSteel, 0, 3);
		world.setBlock(x + 19, y + 1, z + 8, ModBlocks.fence_metal, 0, 3);
		world.setBlock(x + 20, y + 1, z + 8, ModBlocks.fence_metal, 0, 3);
		world.setBlock(x + 21, y + 1, z + 8, ModBlocks.fence_metal, 0, 3);
		world.setBlock(x + 17, y + 1, z + 9, dSteel, 0, 3);
		world.setBlock(x + 18, y + 1, z + 9, dSteel, 0, 3);
		world.setBlock(x + 18, y + 1, z + 10, Library.getRandomConcrete(), 0, 3);
		world.setBlock(x + 19, y + 1, z + 10, Library.getRandomConcrete(), 0, 3);
		world.setBlock(x + 20, y + 1, z + 10, Library.getRandomConcrete(), 0, 3);
		world.setBlock(x + 17, y + 1, z + 11, Library.getRandomConcrete(), 0, 3);
		world.setBlock(x + 18, y + 1, z + 11, Library.getRandomConcrete(), 0, 3);
		world.setBlock(x + 19, y + 1, z + 11, Library.getRandomConcrete(), 0, 3);
		world.setBlock(x + 20, y + 1, z + 11, Library.getRandomConcrete(), 0, 3);
		world.setBlock(x + 21, y + 1, z + 11, Library.getRandomConcrete(), 0, 3);
		world.setBlock(x + 17, y + 1, z + 12, Library.getRandomConcrete(), 0, 3);
		world.setBlock(x + 18, y + 1, z + 12, Library.getRandomConcrete(), 0, 3);
		world.setBlock(x + 19, y + 1, z + 12, Library.getRandomConcrete(), 0, 3);
		world.setBlock(x + 20, y + 1, z + 12, Library.getRandomConcrete(), 0, 3);
		world.setBlock(x + 21, y + 1, z + 12, Library.getRandomConcrete(), 0, 3);
		world.setBlock(x + 17, y + 1, z + 13, Library.getRandomConcrete(), 0, 3);
		world.setBlock(x + 18, y + 1, z + 13, Library.getRandomConcrete(), 0, 3);
		world.setBlock(x + 19, y + 1, z + 13, Library.getRandomConcrete(), 0, 3);
		world.setBlock(x + 20, y + 1, z + 13, Library.getRandomConcrete(), 0, 3);
		world.setBlock(x + 21, y + 1, z + 13, Library.getRandomConcrete(), 0, 3);
		world.setBlock(x + 18, y + 1, z + 14, Library.getRandomConcrete(), 0, 3);
		world.setBlock(x + 19, y + 1, z + 14, Library.getRandomConcrete(), 0, 3);
		world.setBlock(x + 20, y + 1, z + 14, Library.getRandomConcrete(), 0, 3);
		world.setBlock(x + 7, y + 1, z + 17, Block4, 0, 3);
		world.setBlock(x + 19, y + 1, z + 17, Block4, 0, 3);
		world.setBlock(x + 5, y + 1, z + 23, Block3, s5, 3);
		world.setBlock(x + 7, y + 1, z + 29, Block4, 0, 3);
		world.setBlock(x + 19, y + 1, z + 29, Block4, 0, 3);
		world.setBlock(x + 5, y + 2, z + 8, Block3, s3, 3);
		world.setBlock(x + 13, y + 2, z + 8, Block3, s3, 3);
		world.setBlock(x + 15, y + 2, z + 8, dSteel, 0, 3);
		world.setBlock(x + 16, y + 2, z + 8, dSteel, 0, 3);
		world.setBlock(x + 17, y + 2, z + 8, ModBlocks.fence_metal, 0, 3);
		world.setBlock(x + 18, y + 2, z + 8, ModBlocks.fence_metal, 0, 3);
		world.setBlock(x + 19, y + 2, z + 8, ModBlocks.fence_metal, 0, 3);
		world.setBlock(x + 15, y + 2, z + 9, dSteel, 0, 3);
		world.setBlock(x + 16, y + 2, z + 9, dSteel, 0, 3);
		world.setBlock(x + 18, y + 2, z + 10, Library.getRandomConcrete(), 0, 3);
		world.setBlock(x + 19, y + 2, z + 10, Library.getRandomConcrete(), 0, 3);
		world.setBlock(x + 20, y + 2, z + 10, Library.getRandomConcrete(), 0, 3);
		world.setBlock(x + 17, y + 2, z + 11, Library.getRandomConcrete(), 0, 3);
		world.setBlock(x + 18, y + 2, z + 11, Library.getRandomConcrete(), 0, 3);
		world.setBlock(x + 19, y + 2, z + 11, Library.getRandomConcrete(), 0, 3);
		world.setBlock(x + 20, y + 2, z + 11, Library.getRandomConcrete(), 0, 3);
		world.setBlock(x + 21, y + 2, z + 11, Library.getRandomConcrete(), 0, 3);
		world.setBlock(x + 17, y + 2, z + 12, Library.getRandomConcrete(), 0, 3);
		world.setBlock(x + 18, y + 2, z + 12, Library.getRandomConcrete(), 0, 3);
		world.setBlock(x + 19, y + 2, z + 12, Library.getRandomConcrete(), 0, 3);
		world.setBlock(x + 20, y + 2, z + 12, Library.getRandomConcrete(), 0, 3);
		world.setBlock(x + 21, y + 2, z + 12, Library.getRandomConcrete(), 0, 3);
		world.setBlock(x + 17, y + 2, z + 13, Library.getRandomConcrete(), 0, 3);
		world.setBlock(x + 18, y + 2, z + 13, Library.getRandomConcrete(), 0, 3);
		world.setBlock(x + 19, y + 2, z + 13, Library.getRandomConcrete(), 0, 3);
		world.setBlock(x + 20, y + 2, z + 13, Library.getRandomConcrete(), 0, 3);
		world.setBlock(x + 21, y + 2, z + 13, Library.getRandomConcrete(), 0, 3);
		world.setBlock(x + 18, y + 2, z + 14, Library.getRandomConcrete(), 0, 3);
		world.setBlock(x + 19, y + 2, z + 14, Library.getRandomConcrete(), 0, 3);
		world.setBlock(x + 20, y + 2, z + 14, Library.getRandomConcrete(), 0, 3);
		world.setBlock(x + 7, y + 2, z + 17, Block4, 0, 3);
		world.setBlock(x + 19, y + 2, z + 17, Block4, 0, 3);
		world.setBlock(x + 5, y + 2, z + 23, Block3, s5, 3);
		world.setBlock(x + 7, y + 2, z + 29, Block4, 0, 3);
		world.setBlock(x + 19, y + 2, z + 29, Block4, 0, 3);
		world.setBlock(x + 5, y + 3, z + 8, Block3, s3, 3);
		world.setBlock(x + 13, y + 3, z + 8, dSteel, 0, 3);
		world.setBlock(x + 14, y + 3, z + 8, dSteel, 0, 3);
		world.setBlock(x + 15, y + 3, z + 8, ModBlocks.fence_metal, 0, 3);
		world.setBlock(x + 16, y + 3, z + 8, ModBlocks.fence_metal, 0, 3);
		world.setBlock(x + 17, y + 3, z + 8, ModBlocks.fence_metal, 0, 3);
		world.setBlock(x + 13, y + 3, z + 9, dSteel, 0, 3);
		world.setBlock(x + 14, y + 3, z + 9, dSteel, 0, 3);
		world.setBlock(x + 18, y + 3, z + 10, Library.getRandomConcrete(), 0, 3);
		world.setBlock(x + 19, y + 3, z + 10, Library.getRandomConcrete(), 0, 3);
		world.setBlock(x + 20, y + 3, z + 10, Library.getRandomConcrete(), 0, 3);
		world.setBlock(x + 17, y + 3, z + 11, Library.getRandomConcrete(), 0, 3);
		world.setBlock(x + 18, y + 3, z + 11, Library.getRandomConcrete(), 0, 3);
		world.setBlock(x + 19, y + 3, z + 11, Library.getRandomConcrete(), 0, 3);
		world.setBlock(x + 20, y + 3, z + 11, Library.getRandomConcrete(), 0, 3);
		world.setBlock(x + 21, y + 3, z + 11, Library.getRandomConcrete(), 0, 3);
		world.setBlock(x + 17, y + 3, z + 12, Library.getRandomConcrete(), 0, 3);
		world.setBlock(x + 18, y + 3, z + 12, Library.getRandomConcrete(), 0, 3);
		world.setBlock(x + 19, y + 3, z + 12, Library.getRandomConcrete(), 0, 3);
		world.setBlock(x + 20, y + 3, z + 12, Library.getRandomConcrete(), 0, 3);
		world.setBlock(x + 21, y + 3, z + 12, Library.getRandomConcrete(), 0, 3);
		world.setBlock(x + 17, y + 3, z + 13, Library.getRandomConcrete(), 0, 3);
		world.setBlock(x + 18, y + 3, z + 13, Library.getRandomConcrete(), 0, 3);
		world.setBlock(x + 19, y + 3, z + 13, Library.getRandomConcrete(), 0, 3);
		world.setBlock(x + 20, y + 3, z + 13, Library.getRandomConcrete(), 0, 3);
		world.setBlock(x + 21, y + 3, z + 13, Library.getRandomConcrete(), 0, 3);
		world.setBlock(x + 18, y + 3, z + 14, Library.getRandomConcrete(), 0, 3);
		world.setBlock(x + 19, y + 3, z + 14, Library.getRandomConcrete(), 0, 3);
		world.setBlock(x + 20, y + 3, z + 14, Library.getRandomConcrete(), 0, 3);
		world.setBlock(x + 7, y + 3, z + 17, Block4, 0, 3);
		world.setBlock(x + 19, y + 3, z + 17, Block4, 0, 3);
		world.setBlock(x + 5, y + 3, z + 23, Block3, s5, 3);
		world.setBlock(x + 7, y + 3, z + 29, Block4, 0, 3);
		world.setBlock(x + 19, y + 3, z + 29, Block4, 0, 3);
		world.setBlock(x + 5, y + 4, z + 8, Block3, s3, 3);
		world.setBlock(x + 11, y + 4, z + 8, dSteel, 0, 3);
		world.setBlock(x + 12, y + 4, z + 8, dSteel, 0, 3);
		world.setBlock(x + 13, y + 4, z + 8, ModBlocks.fence_metal, 0, 3);
		world.setBlock(x + 14, y + 4, z + 8, ModBlocks.fence_metal, 0, 3);
		world.setBlock(x + 15, y + 4, z + 8, ModBlocks.fence_metal, 0, 3);
		world.setBlock(x + 11, y + 4, z + 9, dSteel, 0, 3);
		world.setBlock(x + 12, y + 4, z + 9, dSteel, 0, 3);
		world.setBlock(x + 18, y + 4, z + 10, Library.getRandomConcrete(), 0, 3);
		world.setBlock(x + 19, y + 4, z + 10, Library.getRandomConcrete(), 0, 3);
		world.setBlock(x + 20, y + 4, z + 10, Library.getRandomConcrete(), 0, 3);
		world.setBlock(x + 17, y + 4, z + 11, Library.getRandomConcrete(), 0, 3);
		world.setBlock(x + 18, y + 4, z + 11, Library.getRandomConcrete(), 0, 3);
		world.setBlock(x + 19, y + 4, z + 11, Library.getRandomConcrete(), 0, 3);
		world.setBlock(x + 20, y + 4, z + 11, Library.getRandomConcrete(), 0, 3);
		world.setBlock(x + 21, y + 4, z + 11, Library.getRandomConcrete(), 0, 3);
		world.setBlock(x + 17, y + 4, z + 12, Library.getRandomConcrete(), 0, 3);
		world.setBlock(x + 18, y + 4, z + 12, Library.getRandomConcrete(), 0, 3);
		world.setBlock(x + 19, y + 4, z + 12, Library.getRandomConcrete(), 0, 3);
		world.setBlock(x + 20, y + 4, z + 12, Library.getRandomConcrete(), 0, 3);
		world.setBlock(x + 21, y + 4, z + 12, Library.getRandomConcrete(), 0, 3);
		world.setBlock(x + 17, y + 4, z + 13, Library.getRandomConcrete(), 0, 3);
		world.setBlock(x + 18, y + 4, z + 13, Library.getRandomConcrete(), 0, 3);
		world.setBlock(x + 19, y + 4, z + 13, Library.getRandomConcrete(), 0, 3);
		world.setBlock(x + 20, y + 4, z + 13, Library.getRandomConcrete(), 0, 3);
		world.setBlock(x + 21, y + 4, z + 13, Library.getRandomConcrete(), 0, 3);
		world.setBlock(x + 18, y + 4, z + 14, Library.getRandomConcrete(), 0, 3);
		world.setBlock(x + 19, y + 4, z + 14, Library.getRandomConcrete(), 0, 3);
		world.setBlock(x + 20, y + 4, z + 14, Library.getRandomConcrete(), 0, 3);
		world.setBlock(x + 7, y + 4, z + 17, Block4, 0, 3);
		world.setBlock(x + 19, y + 4, z + 17, Block4, 0, 3);
		world.setBlock(x + 5, y + 4, z + 23, Block3, s5, 3);
		world.setBlock(x + 7, y + 4, z + 29, Block4, 0, 3);
		world.setBlock(x + 19, y + 4, z + 29, Block4, 0, 3);
		world.setBlock(x + 5, y + 5, z + 8, Block3, s3, 3);
		world.setBlock(x + 9, y + 5, z + 8, dSteel, 0, 3);
		world.setBlock(x + 10, y + 5, z + 8, dSteel, 0, 3);
		world.setBlock(x + 11, y + 5, z + 8, ModBlocks.fence_metal, 0, 3);
		world.setBlock(x + 12, y + 5, z + 8, ModBlocks.fence_metal, 0, 3);
		world.setBlock(x + 13, y + 5, z + 8, ModBlocks.fence_metal, 0, 3);
		world.setBlock(x + 9, y + 5, z + 9, dSteel, 0, 3);
		world.setBlock(x + 10, y + 5, z + 9, dSteel, 0, 3);
		world.setBlock(x + 18, y + 5, z + 10, Library.getRandomConcrete(), 0, 3);
		world.setBlock(x + 19, y + 5, z + 10, Library.getRandomConcrete(), 0, 3);
		world.setBlock(x + 20, y + 5, z + 10, Library.getRandomConcrete(), 0, 3);
		world.setBlock(x + 17, y + 5, z + 11, Library.getRandomConcrete(), 0, 3);
		world.setBlock(x + 18, y + 5, z + 11, Library.getRandomConcrete(), 0, 3);
		world.setBlock(x + 19, y + 5, z + 11, Library.getRandomConcrete(), 0, 3);
		world.setBlock(x + 20, y + 5, z + 11, Library.getRandomConcrete(), 0, 3);
		world.setBlock(x + 21, y + 5, z + 11, Library.getRandomConcrete(), 0, 3);
		world.setBlock(x + 17, y + 5, z + 12, Library.getRandomConcrete(), 0, 3);
		world.setBlock(x + 18, y + 5, z + 12, Library.getRandomConcrete(), 0, 3);
		world.setBlock(x + 19, y + 5, z + 12, Library.getRandomConcrete(), 0, 3);
		world.setBlock(x + 20, y + 5, z + 12, Library.getRandomConcrete(), 0, 3);
		world.setBlock(x + 21, y + 5, z + 12, Library.getRandomConcrete(), 0, 3);
		world.setBlock(x + 17, y + 5, z + 13, Library.getRandomConcrete(), 0, 3);
		world.setBlock(x + 18, y + 5, z + 13, Library.getRandomConcrete(), 0, 3);
		world.setBlock(x + 19, y + 5, z + 13, Library.getRandomConcrete(), 0, 3);
		world.setBlock(x + 20, y + 5, z + 13, Library.getRandomConcrete(), 0, 3);
		world.setBlock(x + 21, y + 5, z + 13, Library.getRandomConcrete(), 0, 3);
		world.setBlock(x + 18, y + 5, z + 14, Library.getRandomConcrete(), 0, 3);
		world.setBlock(x + 19, y + 5, z + 14, Library.getRandomConcrete(), 0, 3);
		world.setBlock(x + 20, y + 5, z + 14, Library.getRandomConcrete(), 0, 3);
		world.setBlock(x + 7, y + 5, z + 17, Block4, 0, 3);
		world.setBlock(x + 19, y + 5, z + 17, Block4, 0, 3);
		world.setBlock(x + 5, y + 5, z + 23, Block3, s5, 3);
		world.setBlock(x + 7, y + 5, z + 29, Block4, 0, 3);
		world.setBlock(x + 19, y + 5, z + 29, Block4, 0, 3);
		world.setBlock(x + 5, y + 6, z + 8, Block3, s3, 3);
		world.setBlock(x + 7, y + 6, z + 8, dSteel, 0, 3);
		world.setBlock(x + 8, y + 6, z + 8, dSteel, 0, 3);
		world.setBlock(x + 9, y + 6, z + 8, ModBlocks.fence_metal, 0, 3);
		world.setBlock(x + 10, y + 6, z + 8, ModBlocks.fence_metal, 0, 3);
		world.setBlock(x + 11, y + 6, z + 8, ModBlocks.fence_metal, 0, 3);
		world.setBlock(x + 7, y + 6, z + 9, dSteel, 0, 3);
		world.setBlock(x + 8, y + 6, z + 9, dSteel, 0, 3);
		world.setBlock(x + 18, y + 6, z + 10, Library.getRandomConcrete(), 0, 3);
		world.setBlock(x + 19, y + 6, z + 10, Library.getRandomConcrete(), 0, 3);
		world.setBlock(x + 20, y + 6, z + 10, Library.getRandomConcrete(), 0, 3);
		world.setBlock(x + 17, y + 6, z + 11, Library.getRandomConcrete(), 0, 3);
		world.setBlock(x + 18, y + 6, z + 11, Library.getRandomConcrete(), 0, 3);
		world.setBlock(x + 19, y + 6, z + 11, Library.getRandomConcrete(), 0, 3);
		world.setBlock(x + 20, y + 6, z + 11, Library.getRandomConcrete(), 0, 3);
		world.setBlock(x + 21, y + 6, z + 11, Library.getRandomConcrete(), 0, 3);
		world.setBlock(x + 17, y + 6, z + 12, Library.getRandomConcrete(), 0, 3);
		world.setBlock(x + 18, y + 6, z + 12, Library.getRandomConcrete(), 0, 3);
		world.setBlock(x + 19, y + 6, z + 12, Library.getRandomConcrete(), 0, 3);
		world.setBlock(x + 20, y + 6, z + 12, Library.getRandomConcrete(), 0, 3);
		world.setBlock(x + 21, y + 6, z + 12, Library.getRandomConcrete(), 0, 3);
		world.setBlock(x + 17, y + 6, z + 13, Library.getRandomConcrete(), 0, 3);
		world.setBlock(x + 18, y + 6, z + 13, Library.getRandomConcrete(), 0, 3);
		world.setBlock(x + 19, y + 6, z + 13, Library.getRandomConcrete(), 0, 3);
		world.setBlock(x + 20, y + 6, z + 13, Library.getRandomConcrete(), 0, 3);
		world.setBlock(x + 21, y + 6, z + 13, Library.getRandomConcrete(), 0, 3);
		world.setBlock(x + 18, y + 6, z + 14, Library.getRandomConcrete(), 0, 3);
		world.setBlock(x + 19, y + 6, z + 14, Library.getRandomConcrete(), 0, 3);
		world.setBlock(x + 20, y + 6, z + 14, Library.getRandomConcrete(), 0, 3);
		world.setBlock(x + 7, y + 6, z + 17, Block4, 0, 3);
		world.setBlock(x + 19, y + 6, z + 17, Block4, 0, 3);
		world.setBlock(x + 5, y + 6, z + 23, Block3, s5, 3);
		world.setBlock(x + 7, y + 6, z + 29, Block4, 0, 3);
		world.setBlock(x + 19, y + 6, z + 29, Block4, 0, 3);
		world.setBlock(x + 5, y + 7, z + 8, dSteel, 0, 3);
		world.setBlock(x + 6, y + 7, z + 8, dSteel, 0, 3);
		world.setBlock(x + 7, y + 7, z + 8, ModBlocks.fence_metal, 0, 3);
		world.setBlock(x + 8, y + 7, z + 8, ModBlocks.fence_metal, 0, 3);
		world.setBlock(x + 9, y + 7, z + 8, ModBlocks.fence_metal, 0, 3);
		world.setBlock(x + 5, y + 7, z + 9, dSteel, 0, 3);
		world.setBlock(x + 6, y + 7, z + 9, dSteel, 0, 3);
		world.setBlock(x + 5, y + 7, z + 10, dSteel, 0, 3);
		world.setBlock(x + 6, y + 7, z + 10, dSteel, 0, 3);
		world.setBlock(x + 18, y + 7, z + 10, Library.getRandomConcrete(), 0, 3);
		world.setBlock(x + 19, y + 7, z + 10, Library.getRandomConcrete(), 0, 3);
		world.setBlock(x + 20, y + 7, z + 10, Library.getRandomConcrete(), 0, 3);
		world.setBlock(x + 5, y + 7, z + 11, dSteel, 0, 3);
		world.setBlock(x + 6, y + 7, z + 11, dSteel, 0, 3);
		world.setBlock(x + 17, y + 7, z + 11, Library.getRandomConcrete(), 0, 3);
		world.setBlock(x + 18, y + 7, z + 11, Library.getRandomConcrete(), 0, 3);
		world.setBlock(x + 19, y + 7, z + 11, Library.getRandomConcrete(), 0, 3);
		world.setBlock(x + 20, y + 7, z + 11, Library.getRandomConcrete(), 0, 3);
		world.setBlock(x + 21, y + 7, z + 11, Library.getRandomConcrete(), 0, 3);
		world.setBlock(x + 5, y + 7, z + 12, dSteel, 0, 3);
		world.setBlock(x + 6, y + 7, z + 12, dSteel, 0, 3);
		world.setBlock(x + 17, y + 7, z + 12, Library.getRandomConcrete(), 0, 3);
		world.setBlock(x + 18, y + 7, z + 12, Library.getRandomConcrete(), 0, 3);
		world.setBlock(x + 19, y + 7, z + 12, Library.getRandomConcrete(), 0, 3);
		world.setBlock(x + 20, y + 7, z + 12, Library.getRandomConcrete(), 0, 3);
		world.setBlock(x + 21, y + 7, z + 12, Library.getRandomConcrete(), 0, 3);
		world.setBlock(x + 5, y + 7, z + 13, dSteel, 0, 3);
		world.setBlock(x + 6, y + 7, z + 13, dSteel, 0, 3);
		world.setBlock(x + 17, y + 7, z + 13, Library.getRandomConcrete(), 0, 3);
		world.setBlock(x + 18, y + 7, z + 13, Library.getRandomConcrete(), 0, 3);
		world.setBlock(x + 19, y + 7, z + 13, Library.getRandomConcrete(), 0, 3);
		world.setBlock(x + 20, y + 7, z + 13, Library.getRandomConcrete(), 0, 3);
		world.setBlock(x + 21, y + 7, z + 13, Library.getRandomConcrete(), 0, 3);
		world.setBlock(x + 5, y + 7, z + 14, dSteel, 0, 3);
		world.setBlock(x + 6, y + 7, z + 14, dSteel, 0, 3);
		world.setBlock(x + 18, y + 7, z + 14, Library.getRandomConcrete(), 0, 3);
		world.setBlock(x + 19, y + 7, z + 14, Library.getRandomConcrete(), 0, 3);
		world.setBlock(x + 20, y + 7, z + 14, Library.getRandomConcrete(), 0, 3);
		world.setBlock(x + 5, y + 7, z + 15, dSteel, 0, 3);
		world.setBlock(x + 6, y + 7, z + 15, dSteel, 0, 3);
		world.setBlock(x + 5, y + 7, z + 16, dSteel, 0, 3);
		world.setBlock(x + 6, y + 7, z + 16, dSteel, 0, 3);
		world.setBlock(x + 7, y + 7, z + 17, Block4, 0, 3);
		world.setBlock(x + 19, y + 7, z + 17, Block4, 0, 3);
		world.setBlock(x + 5, y + 7, z + 23, Block3, s5, 3);
		world.setBlock(x + 7, y + 7, z + 29, Block4, 0, 3);
		world.setBlock(x + 19, y + 7, z + 29, Block4, 0, 3);
		world.setBlock(x + 5, y + 8, z + 8, ModBlocks.fence_metal, 0, 3);
		world.setBlock(x + 6, y + 8, z + 8, ModBlocks.fence_metal, 0, 3);
		world.setBlock(x + 7, y + 8, z + 8, ModBlocks.fence_metal, 0, 3);
		world.setBlock(x + 5, y + 8, z + 9, ModBlocks.fence_metal, 0, 3);
		world.setBlock(x + 5, y + 8, z + 10, ModBlocks.fence_metal, 0, 3);
		world.setBlock(x + 18, y + 8, z + 10, Library.getRandomConcrete(), 0, 3);
		world.setBlock(x + 19, y + 8, z + 10, Library.getRandomConcrete(), 0, 3);
		world.setBlock(x + 20, y + 8, z + 10, Library.getRandomConcrete(), 0, 3);
		world.setBlock(x + 5, y + 8, z + 11, ModBlocks.fence_metal, 0, 3);
		world.setBlock(x + 17, y + 8, z + 11, Library.getRandomConcrete(), 0, 3);
		world.setBlock(x + 18, y + 8, z + 11, Library.getRandomConcrete(), 0, 3);
		world.setBlock(x + 19, y + 8, z + 11, Library.getRandomConcrete(), 0, 3);
		world.setBlock(x + 20, y + 8, z + 11, Library.getRandomConcrete(), 0, 3);
		world.setBlock(x + 21, y + 8, z + 11, Library.getRandomConcrete(), 0, 3);
		world.setBlock(x + 5, y + 8, z + 12, ModBlocks.fence_metal, 0, 3);
		world.setBlock(x + 17, y + 8, z + 12, Library.getRandomConcrete(), 0, 3);
		world.setBlock(x + 18, y + 8, z + 12, Library.getRandomConcrete(), 0, 3);
		world.setBlock(x + 19, y + 8, z + 12, Library.getRandomConcrete(), 0, 3);
		world.setBlock(x + 20, y + 8, z + 12, Library.getRandomConcrete(), 0, 3);
		world.setBlock(x + 21, y + 8, z + 12, Library.getRandomConcrete(), 0, 3);
		world.setBlock(x + 5, y + 8, z + 13, ModBlocks.fence_metal, 0, 3);
		world.setBlock(x + 17, y + 8, z + 13, Library.getRandomConcrete(), 0, 3);
		world.setBlock(x + 18, y + 8, z + 13, Library.getRandomConcrete(), 0, 3);
		world.setBlock(x + 19, y + 8, z + 13, Library.getRandomConcrete(), 0, 3);
		world.setBlock(x + 20, y + 8, z + 13, Library.getRandomConcrete(), 0, 3);
		world.setBlock(x + 21, y + 8, z + 13, Library.getRandomConcrete(), 0, 3);
		world.setBlock(x + 5, y + 8, z + 14, ModBlocks.fence_metal, 0, 3);
		world.setBlock(x + 18, y + 8, z + 14, Library.getRandomConcrete(), 0, 3);
		world.setBlock(x + 19, y + 8, z + 14, Library.getRandomConcrete(), 0, 3);
		world.setBlock(x + 20, y + 8, z + 14, Library.getRandomConcrete(), 0, 3);
		world.setBlock(x + 5, y + 8, z + 15, ModBlocks.fence_metal, 0, 3);
		world.setBlock(x + 5, y + 8, z + 16, ModBlocks.fence_metal, 0, 3);
		world.setBlock(x + 5, y + 8, z + 17, dSteel, 0, 3);
		world.setBlock(x + 6, y + 8, z + 17, dSteel, 0, 3);
		world.setBlock(x + 7, y + 8, z + 17, Block4, 0, 3);
		world.setBlock(x + 19, y + 8, z + 17, Block4, 0, 3);
		world.setBlock(x + 5, y + 8, z + 18, dSteel, 0, 3);
		world.setBlock(x + 6, y + 8, z + 18, dSteel, 0, 3);
		world.setBlock(x + 5, y + 8, z + 23, Block3, s5, 3);
		world.setBlock(x + 7, y + 8, z + 29, Block4, 0, 3);
		world.setBlock(x + 19, y + 8, z + 29, Block4, 0, 3);
		world.setBlock(x + 18, y + 9, z + 10, Library.getRandomConcrete(), 0, 3);
		world.setBlock(x + 19, y + 9, z + 10, Library.getRandomConcrete(), 0, 3);
		world.setBlock(x + 20, y + 9, z + 10, Library.getRandomConcrete(), 0, 3);
		world.setBlock(x + 17, y + 9, z + 11, Library.getRandomConcrete(), 0, 3);
		world.setBlock(x + 18, y + 9, z + 11, Library.getRandomConcrete(), 0, 3);
		world.setBlock(x + 19, y + 9, z + 11, Library.getRandomConcrete(), 0, 3);
		world.setBlock(x + 20, y + 9, z + 11, Library.getRandomConcrete(), 0, 3);
		world.setBlock(x + 21, y + 9, z + 11, Library.getRandomConcrete(), 0, 3);
		world.setBlock(x + 17, y + 9, z + 12, Library.getRandomConcrete(), 0, 3);
		world.setBlock(x + 18, y + 9, z + 12, Library.getRandomConcrete(), 0, 3);
		world.setBlock(x + 19, y + 9, z + 12, Library.getRandomConcrete(), 0, 3);
		world.setBlock(x + 20, y + 9, z + 12, Library.getRandomConcrete(), 0, 3);
		world.setBlock(x + 21, y + 9, z + 12, Library.getRandomConcrete(), 0, 3);
		world.setBlock(x + 17, y + 9, z + 13, Library.getRandomConcrete(), 0, 3);
		world.setBlock(x + 18, y + 9, z + 13, Library.getRandomConcrete(), 0, 3);
		world.setBlock(x + 19, y + 9, z + 13, Library.getRandomConcrete(), 0, 3);
		world.setBlock(x + 20, y + 9, z + 13, Library.getRandomConcrete(), 0, 3);
		world.setBlock(x + 21, y + 9, z + 13, Library.getRandomConcrete(), 0, 3);
		world.setBlock(x + 18, y + 9, z + 14, Library.getRandomConcrete(), 0, 3);
		world.setBlock(x + 19, y + 9, z + 14, Library.getRandomConcrete(), 0, 3);
		world.setBlock(x + 20, y + 9, z + 14, Library.getRandomConcrete(), 0, 3);
		world.setBlock(x + 5, y + 9, z + 16, ModBlocks.fence_metal, 0, 3);
		world.setBlock(x + 5, y + 9, z + 17, ModBlocks.fence_metal, 0, 3);
		world.setBlock(x + 7, y + 9, z + 17, Block4, 0, 3);
		world.setBlock(x + 19, y + 9, z + 17, Block4, 0, 3);
		world.setBlock(x + 5, y + 9, z + 18, ModBlocks.fence_metal, 0, 3);
		world.setBlock(x + 5, y + 9, z + 19, dSteel, 0, 3);
		world.setBlock(x + 6, y + 9, z + 19, dSteel, 0, 3);
		world.setBlock(x + 5, y + 9, z + 20, dSteel, 0, 3);
		world.setBlock(x + 6, y + 9, z + 20, dSteel, 0, 3);
		world.setBlock(x + 5, y + 9, z + 23, Block3, s5, 3);
		world.setBlock(x + 7, y + 9, z + 29, Block4, 0, 3);
		world.setBlock(x + 19, y + 9, z + 29, Block4, 0, 3);
		world.setBlock(x + 18, y + 10, z + 10, Library.getRandomConcrete(), 0, 3);
		world.setBlock(x + 19, y + 10, z + 10, Library.getRandomConcrete(), 0, 3);
		world.setBlock(x + 20, y + 10, z + 10, Library.getRandomConcrete(), 0, 3);
		world.setBlock(x + 17, y + 10, z + 11, Library.getRandomConcrete(), 0, 3);
		world.setBlock(x + 18, y + 10, z + 11, Library.getRandomConcrete(), 0, 3);
		world.setBlock(x + 19, y + 10, z + 11, Library.getRandomConcrete(), 0, 3);
		world.setBlock(x + 20, y + 10, z + 11, Library.getRandomConcrete(), 0, 3);
		world.setBlock(x + 21, y + 10, z + 11, Library.getRandomConcrete(), 0, 3);
		world.setBlock(x + 17, y + 10, z + 12, Library.getRandomConcrete(), 0, 3);
		world.setBlock(x + 18, y + 10, z + 12, Library.getRandomConcrete(), 0, 3);
		world.setBlock(x + 19, y + 10, z + 12, Library.getRandomConcrete(), 0, 3);
		world.setBlock(x + 20, y + 10, z + 12, Library.getRandomConcrete(), 0, 3);
		world.setBlock(x + 21, y + 10, z + 12, Library.getRandomConcrete(), 0, 3);
		world.setBlock(x + 17, y + 10, z + 13, Library.getRandomConcrete(), 0, 3);
		world.setBlock(x + 18, y + 10, z + 13, Library.getRandomConcrete(), 0, 3);
		world.setBlock(x + 19, y + 10, z + 13, Library.getRandomConcrete(), 0, 3);
		world.setBlock(x + 20, y + 10, z + 13, Library.getRandomConcrete(), 0, 3);
		world.setBlock(x + 21, y + 10, z + 13, Library.getRandomConcrete(), 0, 3);
		world.setBlock(x + 18, y + 10, z + 14, Library.getRandomConcrete(), 0, 3);
		world.setBlock(x + 19, y + 10, z + 14, Library.getRandomConcrete(), 0, 3);
		world.setBlock(x + 20, y + 10, z + 14, Library.getRandomConcrete(), 0, 3);
		world.setBlock(x + 7, y + 10, z + 17, Block4, 0, 3);
		world.setBlock(x + 19, y + 10, z + 17, Block4, 0, 3);
		world.setBlock(x + 5, y + 10, z + 18, ModBlocks.fence_metal, 0, 3);
		world.setBlock(x + 5, y + 10, z + 19, ModBlocks.fence_metal, 0, 3);
		world.setBlock(x + 5, y + 10, z + 20, ModBlocks.fence_metal, 0, 3);
		world.setBlock(x + 5, y + 10, z + 21, dSteel, 0, 3);
		world.setBlock(x + 6, y + 10, z + 21, dSteel, 0, 3);
		world.setBlock(x + 5, y + 10, z + 22, dSteel, 0, 3);
		world.setBlock(x + 6, y + 10, z + 22, dSteel, 0, 3);
		world.setBlock(x + 5, y + 10, z + 23, Block3, s5, 3);
		world.setBlock(x + 7, y + 10, z + 29, Block4, 0, 3);
		world.setBlock(x + 19, y + 10, z + 29, Block4, 0, 3);
		world.setBlock(x + 18, y + 11, z + 10, Library.getRandomConcrete(), 0, 3);
		world.setBlock(x + 19, y + 11, z + 10, Library.getRandomConcrete(), 0, 3);
		world.setBlock(x + 20, y + 11, z + 10, Library.getRandomConcrete(), 0, 3);
		world.setBlock(x + 17, y + 11, z + 11, Library.getRandomConcrete(), 0, 3);
		world.setBlock(x + 18, y + 11, z + 11, Library.getRandomConcrete(), 0, 3);
		world.setBlock(x + 19, y + 11, z + 11, Library.getRandomConcrete(), 0, 3);
		world.setBlock(x + 20, y + 11, z + 11, Library.getRandomConcrete(), 0, 3);
		world.setBlock(x + 21, y + 11, z + 11, Library.getRandomConcrete(), 0, 3);
		world.setBlock(x + 17, y + 11, z + 12, Library.getRandomConcrete(), 0, 3);
		world.setBlock(x + 18, y + 11, z + 12, Library.getRandomConcrete(), 0, 3);
		world.setBlock(x + 19, y + 11, z + 12, Library.getRandomConcrete(), 0, 3);
		world.setBlock(x + 20, y + 11, z + 12, Library.getRandomConcrete(), 0, 3);
		world.setBlock(x + 21, y + 11, z + 12, Library.getRandomConcrete(), 0, 3);
		world.setBlock(x + 17, y + 11, z + 13, Library.getRandomConcrete(), 0, 3);
		world.setBlock(x + 18, y + 11, z + 13, Library.getRandomConcrete(), 0, 3);
		world.setBlock(x + 19, y + 11, z + 13, Library.getRandomConcrete(), 0, 3);
		world.setBlock(x + 20, y + 11, z + 13, Library.getRandomConcrete(), 0, 3);
		world.setBlock(x + 21, y + 11, z + 13, Library.getRandomConcrete(), 0, 3);
		world.setBlock(x + 18, y + 11, z + 14, Library.getRandomConcrete(), 0, 3);
		world.setBlock(x + 19, y + 11, z + 14, Library.getRandomConcrete(), 0, 3);
		world.setBlock(x + 20, y + 11, z + 14, Library.getRandomConcrete(), 0, 3);
		world.setBlock(x + 7, y + 11, z + 17, Block4, 0, 3);
		world.setBlock(x + 19, y + 11, z + 17, Block4, 0, 3);
		world.setBlock(x + 5, y + 11, z + 20, ModBlocks.fence_metal, 0, 3);
		world.setBlock(x + 5, y + 11, z + 21, ModBlocks.fence_metal, 0, 3);
		world.setBlock(x + 5, y + 11, z + 22, ModBlocks.fence_metal, 0, 3);
		world.setBlock(x + 5, y + 11, z + 23, dSteel, 0, 3);
		world.setBlock(x + 6, y + 11, z + 23, dSteel, 0, 3);
		world.setBlock(x + 5, y + 11, z + 24, dSteel, 0, 3);
		world.setBlock(x + 6, y + 11, z + 24, dSteel, 0, 3);
		world.setBlock(x + 7, y + 11, z + 29, Block4, 0, 3);
		world.setBlock(x + 19, y + 11, z + 29, Block4, 0, 3);
		world.setBlock(x + 18, y + 12, z + 10, Library.getRandomConcrete(), 0, 3);
		world.setBlock(x + 19, y + 12, z + 10, Library.getRandomConcrete(), 0, 3);
		world.setBlock(x + 20, y + 12, z + 10, Library.getRandomConcrete(), 0, 3);
		world.setBlock(x + 17, y + 12, z + 11, Library.getRandomConcrete(), 0, 3);
		world.setBlock(x + 18, y + 12, z + 11, Library.getRandomConcrete(), 0, 3);
		world.setBlock(x + 19, y + 12, z + 11, Library.getRandomConcrete(), 0, 3);
		world.setBlock(x + 20, y + 12, z + 11, Library.getRandomConcrete(), 0, 3);
		world.setBlock(x + 21, y + 12, z + 11, Library.getRandomConcrete(), 0, 3);
		world.setBlock(x + 17, y + 12, z + 12, Library.getRandomConcrete(), 0, 3);
		world.setBlock(x + 18, y + 12, z + 12, Library.getRandomConcrete(), 0, 3);
		world.setBlock(x + 19, y + 12, z + 12, Library.getRandomConcrete(), 0, 3);
		world.setBlock(x + 20, y + 12, z + 12, Library.getRandomConcrete(), 0, 3);
		world.setBlock(x + 21, y + 12, z + 12, Library.getRandomConcrete(), 0, 3);
		world.setBlock(x + 17, y + 12, z + 13, Library.getRandomConcrete(), 0, 3);
		world.setBlock(x + 18, y + 12, z + 13, Library.getRandomConcrete(), 0, 3);
		world.setBlock(x + 19, y + 12, z + 13, Library.getRandomConcrete(), 0, 3);
		world.setBlock(x + 20, y + 12, z + 13, Library.getRandomConcrete(), 0, 3);
		world.setBlock(x + 21, y + 12, z + 13, Library.getRandomConcrete(), 0, 3);
		world.setBlock(x + 18, y + 12, z + 14, Library.getRandomConcrete(), 0, 3);
		world.setBlock(x + 19, y + 12, z + 14, Library.getRandomConcrete(), 0, 3);
		world.setBlock(x + 20, y + 12, z + 14, Library.getRandomConcrete(), 0, 3);
		world.setBlock(x + 7, y + 12, z + 17, Block4, 0, 3);
		world.setBlock(x + 19, y + 12, z + 17, Block4, 0, 3);
		world.setBlock(x + 5, y + 12, z + 22, ModBlocks.fence_metal, 0, 3);
		world.setBlock(x + 5, y + 12, z + 23, ModBlocks.fence_metal, 0, 3);
		world.setBlock(x + 5, y + 12, z + 24, ModBlocks.fence_metal, 0, 3);
		world.setBlock(x + 5, y + 12, z + 25, dSteel, 0, 3);
		world.setBlock(x + 6, y + 12, z + 25, dSteel, 0, 3);
		world.setBlock(x + 5, y + 12, z + 26, dSteel, 0, 3);
		world.setBlock(x + 6, y + 12, z + 26, dSteel, 0, 3);
		world.setBlock(x + 7, y + 12, z + 29, Block4, 0, 3);
		world.setBlock(x + 19, y + 12, z + 29, Block4, 0, 3);
		world.setBlock(x + 18, y + 13, z + 10, Library.getRandomConcrete(), 0, 3);
		world.setBlock(x + 19, y + 13, z + 10, Library.getRandomConcrete(), 0, 3);
		world.setBlock(x + 20, y + 13, z + 10, Library.getRandomConcrete(), 0, 3);
		world.setBlock(x + 17, y + 13, z + 11, Library.getRandomConcrete(), 0, 3);
		world.setBlock(x + 18, y + 13, z + 11, Library.getRandomConcrete(), 0, 3);
		world.setBlock(x + 19, y + 13, z + 11, Library.getRandomConcrete(), 0, 3);
		world.setBlock(x + 20, y + 13, z + 11, Library.getRandomConcrete(), 0, 3);
		world.setBlock(x + 21, y + 13, z + 11, Library.getRandomConcrete(), 0, 3);
		world.setBlock(x + 17, y + 13, z + 12, Library.getRandomConcrete(), 0, 3);
		world.setBlock(x + 18, y + 13, z + 12, Library.getRandomConcrete(), 0, 3);
		world.setBlock(x + 19, y + 13, z + 12, Library.getRandomConcrete(), 0, 3);
		world.setBlock(x + 20, y + 13, z + 12, Library.getRandomConcrete(), 0, 3);
		world.setBlock(x + 21, y + 13, z + 12, Library.getRandomConcrete(), 0, 3);
		world.setBlock(x + 17, y + 13, z + 13, Library.getRandomConcrete(), 0, 3);
		world.setBlock(x + 18, y + 13, z + 13, Library.getRandomConcrete(), 0, 3);
		world.setBlock(x + 19, y + 13, z + 13, Library.getRandomConcrete(), 0, 3);
		world.setBlock(x + 20, y + 13, z + 13, Library.getRandomConcrete(), 0, 3);
		world.setBlock(x + 21, y + 13, z + 13, Library.getRandomConcrete(), 0, 3);
		world.setBlock(x + 18, y + 13, z + 14, Library.getRandomConcrete(), 0, 3);
		world.setBlock(x + 19, y + 13, z + 14, Library.getRandomConcrete(), 0, 3);
		world.setBlock(x + 20, y + 13, z + 14, Library.getRandomConcrete(), 0, 3);
		world.setBlock(x + 7, y + 13, z + 17, Block5, 0, 3);
		world.setBlock(x + 19, y + 13, z + 17, Block5, 0, 3);
		world.setBlock(x + 7, y + 13, z + 18, Block5, 0, 3);
		world.setBlock(x + 8, y + 13, z + 18, Block5, 0, 3);
		world.setBlock(x + 9, y + 13, z + 18, Block5, 0, 3);
		world.setBlock(x + 10, y + 13, z + 18, Block5, 0, 3);
		world.setBlock(x + 11, y + 13, z + 18, Block5, 0, 3);
		world.setBlock(x + 12, y + 13, z + 18, Block5, 0, 3);
		world.setBlock(x + 13, y + 13, z + 18, Block5, 0, 3);
		world.setBlock(x + 14, y + 13, z + 18, Block5, 0, 3);
		world.setBlock(x + 15, y + 13, z + 18, Block5, 0, 3);
		world.setBlock(x + 16, y + 13, z + 18, Block5, 0, 3);
		world.setBlock(x + 17, y + 13, z + 18, Block5, 0, 3);
		world.setBlock(x + 18, y + 13, z + 18, Block5, 0, 3);
		world.setBlock(x + 19, y + 13, z + 18, Block5, 0, 3);
		world.setBlock(x + 7, y + 13, z + 19, Block5, 0, 3);
		world.setBlock(x + 8, y + 13, z + 19, Blocks.stone_slab, 8, 3);
		world.setBlock(x + 9, y + 13, z + 19, Blocks.stone_slab, 8, 3);
		world.setBlock(x + 10, y + 13, z + 19, Blocks.stone_slab, 8, 3);
		world.setBlock(x + 11, y + 13, z + 19, Blocks.stone_slab, 8, 3);
		world.setBlock(x + 12, y + 13, z + 19, Blocks.stone_slab, 8, 3);
		world.setBlock(x + 13, y + 13, z + 19, Block5, 0, 3);
		world.setBlock(x + 14, y + 13, z + 19, Blocks.stone_slab, 8, 3);
		world.setBlock(x + 15, y + 13, z + 19, Blocks.stone_slab, 8, 3);
		world.setBlock(x + 16, y + 13, z + 19, Blocks.stone_slab, 8, 3);
		world.setBlock(x + 17, y + 13, z + 19, Blocks.stone_slab, 8, 3);
		world.setBlock(x + 18, y + 13, z + 19, Blocks.stone_slab, 8, 3);
		world.setBlock(x + 19, y + 13, z + 19, Block5, 0, 3);
		world.setBlock(x + 7, y + 13, z + 20, Block5, 0, 3);
		world.setBlock(x + 8, y + 13, z + 20, Blocks.stone_slab, 8, 3);
		world.setBlock(x + 9, y + 13, z + 20, Blocks.stone_slab, 8, 3);
		world.setBlock(x + 10, y + 13, z + 20, Blocks.stone_slab, 8, 3);
		world.setBlock(x + 11, y + 13, z + 20, Blocks.stone_slab, 8, 3);
		world.setBlock(x + 12, y + 13, z + 20, Blocks.stone_slab, 8, 3);
		world.setBlock(x + 13, y + 13, z + 20, Block5, 0, 3);
		world.setBlock(x + 14, y + 13, z + 20, Blocks.stone_slab, 8, 3);
		world.setBlock(x + 15, y + 13, z + 20, Blocks.stone_slab, 8, 3);
		world.setBlock(x + 16, y + 13, z + 20, Blocks.stone_slab, 8, 3);
		world.setBlock(x + 17, y + 13, z + 20, Blocks.stone_slab, 8, 3);
		world.setBlock(x + 18, y + 13, z + 20, Blocks.stone_slab, 8, 3);
		world.setBlock(x + 19, y + 13, z + 20, Block5, 0, 3);
		world.setBlock(x + 20, y + 13, z + 20, dSteel, 0, 3);
		world.setBlock(x + 21, y + 13, z + 20, dSteel, 0, 3);
		world.setBlock(x + 7, y + 13, z + 21, Block5, 0, 3);
		world.setBlock(x + 8, y + 13, z + 21, Blocks.stone_slab, 8, 3);
		world.setBlock(x + 9, y + 13, z + 21, Blocks.stone_slab, 8, 3);
		world.setBlock(x + 10, y + 13, z + 21, Blocks.stone_slab, 8, 3);
		world.setBlock(x + 11, y + 13, z + 21, Blocks.stone_slab, 8, 3);
		world.setBlock(x + 12, y + 13, z + 21, Blocks.stone_slab, 8, 3);
		world.setBlock(x + 13, y + 13, z + 21, Block5, 0, 3);
		world.setBlock(x + 14, y + 13, z + 21, Blocks.stone_slab, 8, 3);
		world.setBlock(x + 15, y + 13, z + 21, Blocks.stone_slab, 8, 3);
		world.setBlock(x + 16, y + 13, z + 21, Blocks.stone_slab, 8, 3);
		world.setBlock(x + 17, y + 13, z + 21, Blocks.stone_slab, 8, 3);
		world.setBlock(x + 18, y + 13, z + 21, Blocks.stone_slab, 8, 3);
		world.setBlock(x + 19, y + 13, z + 21, Block5, 0, 3);
		world.setBlock(x + 20, y + 13, z + 21, dSteel, 0, 3);
		world.setBlock(x + 21, y + 13, z + 21, dSteel, 0, 3);
		world.setBlock(x + 7, y + 13, z + 22, Block5, 0, 3);
		world.setBlock(x + 8, y + 13, z + 22, Blocks.stone_slab, 8, 3);
		world.setBlock(x + 9, y + 13, z + 22, Blocks.stone_slab, 8, 3);
		world.setBlock(x + 10, y + 13, z + 22, Blocks.stone_slab, 8, 3);
		world.setBlock(x + 11, y + 13, z + 22, Blocks.stone_slab, 8, 3);
		world.setBlock(x + 12, y + 13, z + 22, Blocks.stone_slab, 8, 3);
		world.setBlock(x + 13, y + 13, z + 22, Block5, 0, 3);
		world.setBlock(x + 14, y + 13, z + 22, Blocks.stone_slab, 8, 3);
		world.setBlock(x + 15, y + 13, z + 22, Blocks.stone_slab, 8, 3);
		world.setBlock(x + 16, y + 13, z + 22, Blocks.stone_slab, 8, 3);
		world.setBlock(x + 17, y + 13, z + 22, Blocks.stone_slab, 8, 3);
		world.setBlock(x + 18, y + 13, z + 22, Blocks.stone_slab, 8, 3);
		world.setBlock(x + 19, y + 13, z + 22, Block5, 0, 3);
		world.setBlock(x + 20, y + 13, z + 22, dSteel, 0, 3);
		world.setBlock(x + 21, y + 13, z + 22, dSteel, 0, 3);
		world.setBlock(x + 7, y + 13, z + 23, Block5, 0, 3);
		world.setBlock(x + 8, y + 13, z + 23, Block5, 0, 3);
		world.setBlock(x + 9, y + 13, z + 23, Block5, 0, 3);
		world.setBlock(x + 10, y + 13, z + 23, Block5, 0, 3);
		world.setBlock(x + 11, y + 13, z + 23, Block5, 0, 3);
		world.setBlock(x + 12, y + 13, z + 23, Block5, 0, 3);
		world.setBlock(x + 13, y + 13, z + 23, Block5, 0, 3);
		world.setBlock(x + 14, y + 13, z + 23, Block5, 0, 3);
		world.setBlock(x + 15, y + 13, z + 23, Block5, 0, 3);
		world.setBlock(x + 16, y + 13, z + 23, Block5, 0, 3);
		world.setBlock(x + 17, y + 13, z + 23, Block5, 0, 3);
		world.setBlock(x + 18, y + 13, z + 23, Block5, 0, 3);
		world.setBlock(x + 19, y + 13, z + 23, Block5, 0, 3);
		world.setBlock(x + 5, y + 13, z + 24, ModBlocks.fence_metal, 0, 3);
		world.setBlock(x + 7, y + 13, z + 24, Block5, 0, 3);
		world.setBlock(x + 8, y + 13, z + 24, Blocks.stone_slab, 8, 3);
		world.setBlock(x + 9, y + 13, z + 24, Blocks.stone_slab, 8, 3);
		world.setBlock(x + 10, y + 13, z + 24, Blocks.stone_slab, 8, 3);
		world.setBlock(x + 11, y + 13, z + 24, Blocks.stone_slab, 8, 3);
		world.setBlock(x + 12, y + 13, z + 24, Blocks.stone_slab, 8, 3);
		world.setBlock(x + 13, y + 13, z + 24, Block5, 0, 3);
		world.setBlock(x + 14, y + 13, z + 24, Blocks.stone_slab, 8, 3);
		world.setBlock(x + 15, y + 13, z + 24, Blocks.stone_slab, 8, 3);
		world.setBlock(x + 16, y + 13, z + 24, Blocks.stone_slab, 8, 3);
		world.setBlock(x + 17, y + 13, z + 24, Blocks.stone_slab, 8, 3);
		world.setBlock(x + 18, y + 13, z + 24, Blocks.stone_slab, 8, 3);
		world.setBlock(x + 19, y + 13, z + 24, Block5, 0, 3);
		world.setBlock(x + 5, y + 13, z + 25, ModBlocks.fence_metal, 0, 3);
		world.setBlock(x + 7, y + 13, z + 25, Block5, 0, 3);
		world.setBlock(x + 8, y + 13, z + 25, Blocks.stone_slab, 8, 3);
		world.setBlock(x + 9, y + 13, z + 25, Blocks.stone_slab, 8, 3);
		world.setBlock(x + 10, y + 13, z + 25, Blocks.stone_slab, 8, 3);
		world.setBlock(x + 11, y + 13, z + 25, Blocks.stone_slab, 8, 3);
		world.setBlock(x + 12, y + 13, z + 25, Blocks.stone_slab, 8, 3);
		world.setBlock(x + 13, y + 13, z + 25, Block5, 0, 3);
		world.setBlock(x + 14, y + 13, z + 25, Blocks.stone_slab, 8, 3);
		world.setBlock(x + 15, y + 13, z + 25, Blocks.stone_slab, 8, 3);
		world.setBlock(x + 16, y + 13, z + 25, Blocks.stone_slab, 8, 3);
		world.setBlock(x + 17, y + 13, z + 25, Blocks.stone_slab, 8, 3);
		world.setBlock(x + 18, y + 13, z + 25, Blocks.stone_slab, 8, 3);
		world.setBlock(x + 19, y + 13, z + 25, Block5, 0, 3);
		world.setBlock(x + 5, y + 13, z + 26, ModBlocks.fence_metal, 0, 3);
		world.setBlock(x + 7, y + 13, z + 26, Block5, 0, 3);
		world.setBlock(x + 8, y + 13, z + 26, Blocks.stone_slab, 8, 3);
		world.setBlock(x + 9, y + 13, z + 26, Blocks.stone_slab, 8, 3);
		world.setBlock(x + 10, y + 13, z + 26, Blocks.stone_slab, 8, 3);
		world.setBlock(x + 11, y + 13, z + 26, Blocks.stone_slab, 8, 3);
		world.setBlock(x + 12, y + 13, z + 26, Blocks.stone_slab, 8, 3);
		world.setBlock(x + 13, y + 13, z + 26, Block5, 0, 3);
		world.setBlock(x + 14, y + 13, z + 26, Blocks.stone_slab, 8, 3);
		world.setBlock(x + 15, y + 13, z + 26, Blocks.stone_slab, 8, 3);
		world.setBlock(x + 16, y + 13, z + 26, Blocks.stone_slab, 8, 3);
		world.setBlock(x + 17, y + 13, z + 26, Blocks.stone_slab, 8, 3);
		world.setBlock(x + 18, y + 13, z + 26, Blocks.stone_slab, 8, 3);
		world.setBlock(x + 19, y + 13, z + 26, Block5, 0, 3);
		world.setBlock(x + 5, y + 13, z + 27, dSteel, 0, 3);
		world.setBlock(x + 6, y + 13, z + 27, dSteel, 0, 3);
		world.setBlock(x + 7, y + 13, z + 27, Block5, 0, 3);
		world.setBlock(x + 8, y + 13, z + 27, Blocks.stone_slab, 8, 3);
		world.setBlock(x + 9, y + 13, z + 27, Blocks.stone_slab, 8, 3);
		world.setBlock(x + 10, y + 13, z + 27, Blocks.stone_slab, 8, 3);
		world.setBlock(x + 11, y + 13, z + 27, Blocks.stone_slab, 8, 3);
		world.setBlock(x + 12, y + 13, z + 27, Blocks.stone_slab, 8, 3);
		world.setBlock(x + 13, y + 13, z + 27, Block5, 0, 3);
		world.setBlock(x + 14, y + 13, z + 27, Blocks.stone_slab, 8, 3);
		world.setBlock(x + 15, y + 13, z + 27, Blocks.stone_slab, 8, 3);
		world.setBlock(x + 16, y + 13, z + 27, Blocks.stone_slab, 8, 3);
		world.setBlock(x + 17, y + 13, z + 27, Blocks.stone_slab, 8, 3);
		world.setBlock(x + 18, y + 13, z + 27, Blocks.stone_slab, 8, 3);
		world.setBlock(x + 19, y + 13, z + 27, Block5, 0, 3);
		world.setBlock(x + 5, y + 13, z + 28, dSteel, 0, 3);
		world.setBlock(x + 6, y + 13, z + 28, dSteel, 0, 3);
		world.setBlock(x + 7, y + 13, z + 28, Block5, 0, 3);
		world.setBlock(x + 8, y + 13, z + 28, Block5, 0, 3);
		world.setBlock(x + 9, y + 13, z + 28, Block5, 0, 3);
		world.setBlock(x + 10, y + 13, z + 28, Block5, 0, 3);
		world.setBlock(x + 11, y + 13, z + 28, Block5, 0, 3);
		world.setBlock(x + 12, y + 13, z + 28, Block5, 0, 3);
		world.setBlock(x + 13, y + 13, z + 28, Block5, 0, 3);
		world.setBlock(x + 14, y + 13, z + 28, Block5, 0, 3);
		world.setBlock(x + 15, y + 13, z + 28, Block5, 0, 3);
		world.setBlock(x + 16, y + 13, z + 28, Block5, 0, 3);
		world.setBlock(x + 17, y + 13, z + 28, Block5, 0, 3);
		world.setBlock(x + 18, y + 13, z + 28, Block5, 0, 3);
		world.setBlock(x + 19, y + 13, z + 28, Block5, 0, 3);
		world.setBlock(x + 7, y + 13, z + 29, Block5, 0, 3);
		world.setBlock(x + 19, y + 13, z + 29, Block5, 0, 3);
		world.setBlock(x + 18, y + 14, z + 10, Library.getRandomConcrete(), 0, 3);
		world.setBlock(x + 19, y + 14, z + 10, Library.getRandomConcrete(), 0, 3);
		world.setBlock(x + 20, y + 14, z + 10, Library.getRandomConcrete(), 0, 3);
		world.setBlock(x + 17, y + 14, z + 11, Library.getRandomConcrete(), 0, 3);
		world.setBlock(x + 18, y + 14, z + 11, Library.getRandomConcrete(), 0, 3);
		world.setBlock(x + 19, y + 14, z + 11, Library.getRandomConcrete(), 0, 3);
		world.setBlock(x + 20, y + 14, z + 11, Library.getRandomConcrete(), 0, 3);
		world.setBlock(x + 21, y + 14, z + 11, Library.getRandomConcrete(), 0, 3);
		world.setBlock(x + 17, y + 14, z + 12, Library.getRandomConcrete(), 0, 3);
		world.setBlock(x + 18, y + 14, z + 12, Library.getRandomConcrete(), 0, 3);
		world.setBlock(x + 19, y + 14, z + 12, Library.getRandomConcrete(), 0, 3);
		world.setBlock(x + 20, y + 14, z + 12, Library.getRandomConcrete(), 0, 3);
		world.setBlock(x + 21, y + 14, z + 12, Library.getRandomConcrete(), 0, 3);
		world.setBlock(x + 17, y + 14, z + 13, Library.getRandomConcrete(), 0, 3);
		world.setBlock(x + 18, y + 14, z + 13, Library.getRandomConcrete(), 0, 3);
		world.setBlock(x + 19, y + 14, z + 13, Library.getRandomConcrete(), 0, 3);
		world.setBlock(x + 20, y + 14, z + 13, Library.getRandomConcrete(), 0, 3);
		world.setBlock(x + 21, y + 14, z + 13, Library.getRandomConcrete(), 0, 3);
		world.setBlock(x + 18, y + 14, z + 14, Library.getRandomConcrete(), 0, 3);
		world.setBlock(x + 19, y + 14, z + 14, Library.getRandomConcrete(), 0, 3);
		world.setBlock(x + 20, y + 14, z + 14, Library.getRandomConcrete(), 0, 3);
		world.setBlock(x + 7, y + 14, z + 18, dSteel, 0, 3);
		world.setBlock(x + 8, y + 14, z + 18, dSteel, 0, 3);
		world.setBlock(x + 9, y + 14, z + 18, dSteel, 0, 3);
		world.setBlock(x + 10, y + 14, z + 18, dSteel, 0, 3);
		world.setBlock(x + 11, y + 14, z + 18, dSteel, 0, 3);
		world.setBlock(x + 12, y + 14, z + 18, dSteel, 0, 3);
		world.setBlock(x + 13, y + 14, z + 18, dSteel, 0, 3);
		world.setBlock(x + 14, y + 14, z + 18, dSteel, 0, 3);
		world.setBlock(x + 15, y + 14, z + 18, dSteel, 0, 3);
		world.setBlock(x + 16, y + 14, z + 18, dSteel, 0, 3);
		world.setBlock(x + 17, y + 14, z + 18, dSteel, 0, 3);
		world.setBlock(x + 18, y + 14, z + 18, dSteel, 0, 3);
		world.setBlock(x + 19, y + 14, z + 18, dSteel, 0, 3);
		world.setBlock(x + 7, y + 14, z + 19, dSteel, 0, 3);
		world.setBlock(x + 10, y + 14, z + 19, Blocks.chest, 3, 3);
		world.setBlockMetadataWithNotify(x + 10, y + 14, z + 19, 3, 3);
        WeightedRandomChestContent.generateChestContents(rand, ItemPool.getPool(ItemPoolsLegacy.POOL_GENERIC), (TileEntityChest)world.getTileEntity(x + 10, y + 14, z + 19), 8);
		world.setBlock(x + 19, y + 14, z + 19, dSteel, 0, 3);
		world.setBlock(x + 20, y + 14, z + 19, dSteel, 0, 3);
		world.setBlock(x + 21, y + 14, z + 19, dSteel, 0, 3);
		world.setBlock(x + 7, y + 14, z + 20, dSteel, 0, 3);
		world.setBlock(x + 21, y + 14, z + 20, ModBlocks.fence_metal, 0, 3);
		world.setBlock(x + 7, y + 14, z + 21, dSteel, 0, 3);
		world.setBlock(x + 21, y + 14, z + 21, ModBlocks.fence_metal, 0, 3);
		world.setBlock(x + 7, y + 14, z + 22, dSteel, 0, 3);
		world.setBlock(x + 13, y + 14, z + 22, dSteel, 0, 3);
		world.setBlock(x + 14, y + 14, z + 22, dSteel, 0, 3);
		world.setBlock(x + 19, y + 14, z + 22, dSteel, 0, 3);
		world.setBlock(x + 20, y + 14, z + 22, ModBlocks.fence_metal, 0, 3);
		world.setBlock(x + 21, y + 14, z + 22, ModBlocks.fence_metal, 0, 3);
		world.setBlock(x + 7, y + 14, z + 23, ModBlocks.fence_metal, 0, 3);
		world.setBlock(x + 13, y + 14, z + 23, dSteel, 0, 3);
		world.setBlock(x + 14, y + 14, z + 23, dSteel, 0, 3);
		world.setBlock(x + 19, y + 14, z + 23, dSteel, 0, 3);
		world.setBlock(x + 7, y + 14, z + 24, ModBlocks.fence_metal, 0, 3);
		world.setBlock(x + 13, y + 14, z + 24, dSteel, 0, 3);
		world.setBlock(x + 14, y + 14, z + 24, dSteel, 0, 3);
		world.setBlock(x + 19, y + 14, z + 24, dSteel, 0, 3);
		world.setBlock(x + 19, y + 14, z + 25, dSteel, 0, 3);
		world.setBlock(x + 5, y + 14, z + 26, ModBlocks.fence_metal, 0, 3);
		world.setBlock(x + 19, y + 14, z + 26, dSteel, 0, 3);
		world.setBlock(x + 5, y + 14, z + 27, ModBlocks.fence_metal, 0, 3);
		world.setBlock(x + 7, y + 14, z + 27, dSteel, 0, 3);
		world.setBlock(x + 16, y + 14, z + 27, Blocks.chest, 2, 3);
		world.setBlockMetadataWithNotify(x + 16, y + 14, z + 27, 3, 3);
        WeightedRandomChestContent.generateChestContents(rand, ItemPool.getPool(ItemPoolsLegacy.POOL_ANTENNA), (TileEntityChest)world.getTileEntity(x + 16, y + 14, z + 27), 8);
		world.setBlock(x + 19, y + 14, z + 27, dSteel, 0, 3);
		world.setBlock(x + 5, y + 14, z + 28, ModBlocks.fence_metal, 0, 3);
		world.setBlock(x + 6, y + 14, z + 28, ModBlocks.fence_metal, 0, 3);
		world.setBlock(x + 7, y + 14, z + 28, dSteel, 0, 3);
		world.setBlock(x + 8, y + 14, z + 28, dSteel, 0, 3);
		world.setBlock(x + 9, y + 14, z + 28, dSteel, 0, 3);
		world.setBlock(x + 10, y + 14, z + 28, dSteel, 0, 3);
		world.setBlock(x + 11, y + 14, z + 28, dSteel, 0, 3);
		world.setBlock(x + 12, y + 14, z + 28, dSteel, 0, 3);
		world.setBlock(x + 13, y + 14, z + 28, dSteel, 0, 3);
		world.setBlock(x + 14, y + 14, z + 28, dSteel, 0, 3);
		world.setBlock(x + 15, y + 14, z + 28, dSteel, 0, 3);
		world.setBlock(x + 16, y + 14, z + 28, dSteel, 0, 3);
		world.setBlock(x + 17, y + 14, z + 28, dSteel, 0, 3);
		world.setBlock(x + 18, y + 14, z + 28, dSteel, 0, 3);
		world.setBlock(x + 19, y + 14, z + 28, dSteel, 0, 3);
		world.setBlock(x + 18, y + 15, z + 10, Library.getRandomConcrete(), 0, 3);
		world.setBlock(x + 19, y + 15, z + 10, Library.getRandomConcrete(), 0, 3);
		world.setBlock(x + 20, y + 15, z + 10, Library.getRandomConcrete(), 0, 3);
		world.setBlock(x + 17, y + 15, z + 11, Library.getRandomConcrete(), 0, 3);
		world.setBlock(x + 18, y + 15, z + 11, Library.getRandomConcrete(), 0, 3);
		world.setBlock(x + 19, y + 15, z + 11, Library.getRandomConcrete(), 0, 3);
		world.setBlock(x + 20, y + 15, z + 11, Library.getRandomConcrete(), 0, 3);
		world.setBlock(x + 21, y + 15, z + 11, Library.getRandomConcrete(), 0, 3);
		world.setBlock(x + 17, y + 15, z + 12, Library.getRandomConcrete(), 0, 3);
		world.setBlock(x + 18, y + 15, z + 12, Library.getRandomConcrete(), 0, 3);
		world.setBlock(x + 19, y + 15, z + 12, Library.getRandomConcrete(), 0, 3);
		world.setBlock(x + 20, y + 15, z + 12, Library.getRandomConcrete(), 0, 3);
		world.setBlock(x + 21, y + 15, z + 12, Library.getRandomConcrete(), 0, 3);
		world.setBlock(x + 17, y + 15, z + 13, Library.getRandomConcrete(), 0, 3);
		world.setBlock(x + 18, y + 15, z + 13, Library.getRandomConcrete(), 0, 3);
		world.setBlock(x + 19, y + 15, z + 13, Library.getRandomConcrete(), 0, 3);
		world.setBlock(x + 20, y + 15, z + 13, Library.getRandomConcrete(), 0, 3);
		world.setBlock(x + 21, y + 15, z + 13, Library.getRandomConcrete(), 0, 3);
		world.setBlock(x + 18, y + 15, z + 14, Library.getRandomConcrete(), 0, 3);
		world.setBlock(x + 19, y + 15, z + 14, Library.getRandomConcrete(), 0, 3);
		world.setBlock(x + 20, y + 15, z + 14, Library.getRandomConcrete(), 0, 3);
		world.setBlock(x + 7, y + 15, z + 18, dSteel, 0, 3);
		world.setBlock(x + 8, y + 15, z + 18, dSteel, 0, 3);
		world.setBlock(x + 9, y + 15, z + 18, Block4, 0, 3);
		world.setBlock(x + 10, y + 15, z + 18, Block4, 0, 3);
		world.setBlock(x + 11, y + 15, z + 18, Block4, 0, 3);
		world.setBlock(x + 12, y + 15, z + 18, Block4, 0, 3);
		world.setBlock(x + 13, y + 15, z + 18, Block4, 0, 3);
		world.setBlock(x + 14, y + 15, z + 18, Block4, 0, 3);
		world.setBlock(x + 15, y + 15, z + 18, Block4, 0, 3);
		world.setBlock(x + 16, y + 15, z + 18, Block4, 0, 3);
		world.setBlock(x + 17, y + 15, z + 18, Block4, 0, 3);
		world.setBlock(x + 18, y + 15, z + 18, dSteel, 0, 3);
		world.setBlock(x + 19, y + 15, z + 18, dSteel, 0, 3);
		world.setBlock(x + 20, y + 15, z + 18, dSteel, 0, 3);
		world.setBlock(x + 21, y + 15, z + 18, dSteel, 0, 3);
		world.setBlock(x + 7, y + 15, z + 19, dSteel, 0, 3);
		world.setBlock(x + 19, y + 15, z + 19, dSteel, 0, 3);
		world.setBlock(x + 21, y + 15, z + 19, ModBlocks.fence_metal, 0, 3);
		world.setBlock(x + 7, y + 15, z + 20, dSteel, 0, 3);
		world.setBlock(x + 21, y + 15, z + 20, ModBlocks.fence_metal, 0, 3);
		world.setBlock(x + 7, y + 15, z + 21, dSteel, 0, 3);
		world.setBlock(x + 7, y + 15, z + 22, dSteel, 0, 3);
		world.setBlock(x + 14, y + 15, z + 22, dTape, 4, 3);
		world.setBlock(x + 19, y + 15, z + 22, dSteel, 0, 3);
		world.setBlock(x + 7, y + 15, z + 23, ModBlocks.fence_metal, 0, 3);
		world.setBlock(x + 14, y + 15, z + 23, dTape, 4, 3);
		world.setBlock(x + 19, y + 15, z + 23, dSteel, 0, 3);
		world.setBlock(x + 7, y + 15, z + 24, ModBlocks.fence_metal, 0, 3);
		world.setBlock(x + 14, y + 15, z + 24, Block3, s5, 3);
		world.setBlock(x + 19, y + 15, z + 24, dSteel, 0, 3);
		world.setBlock(x + 19, y + 15, z + 25, dSteel, 0, 3);
		world.setBlock(x + 19, y + 15, z + 26, dSteel, 0, 3);
		world.setBlock(x + 7, y + 15, z + 27, dSteel, 0, 3);
		world.setBlock(x + 19, y + 15, z + 27, dSteel, 0, 3);
		world.setBlock(x + 7, y + 15, z + 28, dSteel, 0, 3);
		world.setBlock(x + 8, y + 15, z + 28, dSteel, 0, 3);
		world.setBlock(x + 9, y + 15, z + 28, Block4, 0, 3);
		world.setBlock(x + 10, y + 15, z + 28, Block4, 0, 3);
		world.setBlock(x + 11, y + 15, z + 28, Block4, 0, 3);
		world.setBlock(x + 12, y + 15, z + 28, Block4, 0, 3);
		world.setBlock(x + 13, y + 15, z + 28, Block4, 0, 3);
		world.setBlock(x + 14, y + 15, z + 28, Block4, 0, 3);
		world.setBlock(x + 15, y + 15, z + 28, Block4, 0, 3);
		world.setBlock(x + 16, y + 15, z + 28, Block4, 0, 3);
		world.setBlock(x + 17, y + 15, z + 28, Block4, 0, 3);
		world.setBlock(x + 18, y + 15, z + 28, dSteel, 0, 3);
		world.setBlock(x + 19, y + 15, z + 28, dSteel, 0, 3);
		world.setBlock(x + 18, y + 16, z + 10, Library.getRandomConcrete(), 0, 3);
		world.setBlock(x + 19, y + 16, z + 10, Library.getRandomConcrete(), 0, 3);
		world.setBlock(x + 20, y + 16, z + 10, Library.getRandomConcrete(), 0, 3);
		world.setBlock(x + 17, y + 16, z + 11, Library.getRandomConcrete(), 0, 3);
		world.setBlock(x + 18, y + 16, z + 11, Library.getRandomConcrete(), 0, 3);
		world.setBlock(x + 19, y + 16, z + 11, Library.getRandomConcrete(), 0, 3);
		world.setBlock(x + 20, y + 16, z + 11, Library.getRandomConcrete(), 0, 3);
		world.setBlock(x + 21, y + 16, z + 11, Library.getRandomConcrete(), 0, 3);
		world.setBlock(x + 17, y + 16, z + 12, Library.getRandomConcrete(), 0, 3);
		world.setBlock(x + 18, y + 16, z + 12, Library.getRandomConcrete(), 0, 3);
		world.setBlock(x + 19, y + 16, z + 12, Library.getRandomConcrete(), 0, 3);
		world.setBlock(x + 20, y + 16, z + 12, Library.getRandomConcrete(), 0, 3);
		world.setBlock(x + 21, y + 16, z + 12, Library.getRandomConcrete(), 0, 3);
		world.setBlock(x + 17, y + 16, z + 13, Library.getRandomConcrete(), 0, 3);
		world.setBlock(x + 18, y + 16, z + 13, Library.getRandomConcrete(), 0, 3);
		world.setBlock(x + 19, y + 16, z + 13, Library.getRandomConcrete(), 0, 3);
		world.setBlock(x + 20, y + 16, z + 13, Library.getRandomConcrete(), 0, 3);
		world.setBlock(x + 21, y + 16, z + 13, Library.getRandomConcrete(), 0, 3);
		world.setBlock(x + 18, y + 16, z + 14, Library.getRandomConcrete(), 0, 3);
		world.setBlock(x + 19, y + 16, z + 14, Library.getRandomConcrete(), 0, 3);
		world.setBlock(x + 20, y + 16, z + 14, Library.getRandomConcrete(), 0, 3);
		world.setBlock(x + 19, y + 16, z + 17, dSteel, 0, 3);
		world.setBlock(x + 20, y + 16, z + 17, dSteel, 0, 3);
		world.setBlock(x + 21, y + 16, z + 17, dSteel, 0, 3);
		world.setBlock(x + 7, y + 16, z + 18, dSteel, 0, 3);
		world.setBlock(x + 8, y + 16, z + 18, dSteel, 0, 3);
		world.setBlock(x + 9, y + 16, z + 18, dSteel, 0, 3);
		world.setBlock(x + 10, y + 16, z + 18, dSteel, 0, 3);
		world.setBlock(x + 11, y + 16, z + 18, dSteel, 0, 3);
		world.setBlock(x + 12, y + 16, z + 18, dSteel, 0, 3);
		world.setBlock(x + 13, y + 16, z + 18, dSteel, 0, 3);
		world.setBlock(x + 14, y + 16, z + 18, dSteel, 0, 3);
		world.setBlock(x + 15, y + 16, z + 18, dSteel, 0, 3);
		world.setBlock(x + 16, y + 16, z + 18, dSteel, 0, 3);
		world.setBlock(x + 17, y + 16, z + 18, dSteel, 0, 3);
		world.setBlock(x + 18, y + 16, z + 18, dSteel, 0, 3);
		world.setBlock(x + 19, y + 16, z + 18, dSteel, 0, 3);
		world.setBlock(x + 21, y + 16, z + 18, ModBlocks.fence_metal, 0, 3);
		world.setBlock(x + 7, y + 16, z + 19, dSteel, 0, 3);
		world.setBlock(x + 19, y + 16, z + 19, dSteel, 0, 3);
		world.setBlock(x + 21, y + 16, z + 19, ModBlocks.fence_metal, 0, 3);
		world.setBlock(x + 7, y + 16, z + 20, dSteel, 0, 3);
		world.setBlock(x + 19, y + 16, z + 20, dSteel, 0, 3);
		world.setBlock(x + 7, y + 16, z + 21, dSteel, 0, 3);
		world.setBlock(x + 19, y + 16, z + 21, dSteel, 0, 3);
		world.setBlock(x + 7, y + 16, z + 22, dSteel, 0, 3);
		world.setBlock(x + 19, y + 16, z + 22, dSteel, 0, 3);
		world.setBlock(x + 7, y + 16, z + 23, ModBlocks.fence_metal, 0, 3);
		world.setBlock(x + 19, y + 16, z + 23, dSteel, 0, 3);
		world.setBlock(x + 7, y + 16, z + 24, ModBlocks.fence_metal, 0, 3);
		world.setBlock(x + 14, y + 16, z + 24, Block3, s5, 3);
		world.setBlock(x + 19, y + 16, z + 24, dSteel, 0, 3);
		world.setBlock(x + 19, y + 16, z + 25, dSteel, 0, 3);
		world.setBlock(x + 19, y + 16, z + 26, dSteel, 0, 3);
		world.setBlock(x + 7, y + 16, z + 27, dSteel, 0, 3);
		world.setBlock(x + 19, y + 16, z + 27, dSteel, 0, 3);
		world.setBlock(x + 7, y + 16, z + 28, dSteel, 0, 3);
		world.setBlock(x + 8, y + 16, z + 28, dSteel, 0, 3);
		world.setBlock(x + 9, y + 16, z + 28, dSteel, 0, 3);
		world.setBlock(x + 10, y + 16, z + 28, dSteel, 0, 3);
		world.setBlock(x + 11, y + 16, z + 28, dSteel, 0, 3);
		world.setBlock(x + 12, y + 16, z + 28, dSteel, 0, 3);
		world.setBlock(x + 13, y + 16, z + 28, dSteel, 0, 3);
		world.setBlock(x + 14, y + 16, z + 28, dSteel, 0, 3);
		world.setBlock(x + 15, y + 16, z + 28, dSteel, 0, 3);
		world.setBlock(x + 16, y + 16, z + 28, dSteel, 0, 3);
		world.setBlock(x + 17, y + 16, z + 28, dSteel, 0, 3);
		world.setBlock(x + 18, y + 16, z + 28, dSteel, 0, 3);
		world.setBlock(x + 19, y + 16, z + 28, dSteel, 0, 3);
		world.setBlock(x + 16, y + 17, z + 8, dSteel, 0, 3);
		world.setBlock(x + 17, y + 17, z + 8, dSteel, 0, 3);
		world.setBlock(x + 18, y + 17, z + 8, dSteel, 0, 3);
		world.setBlock(x + 19, y + 17, z + 8, dSteel, 0, 3);
		world.setBlock(x + 20, y + 17, z + 8, dSteel, 0, 3);
		world.setBlock(x + 21, y + 17, z + 8, dSteel, 0, 3);
		world.setBlock(x + 22, y + 17, z + 8, dSteel, 0, 3);
		world.setBlock(x + 15, y + 17, z + 9, dSteel, 0, 3);
		world.setBlock(x + 16, y + 17, z + 9, dSteel, 0, 3);
		world.setBlock(x + 17, y + 17, z + 9, dSteel, 0, 3);
		world.setBlock(x + 18, y + 17, z + 9, dSteel, 0, 3);
		world.setBlock(x + 19, y + 17, z + 9, dSteel, 0, 3);
		world.setBlock(x + 20, y + 17, z + 9, dSteel, 0, 3);
		world.setBlock(x + 21, y + 17, z + 9, dSteel, 0, 3);
		world.setBlock(x + 22, y + 17, z + 9, dSteel, 0, 3);
		world.setBlock(x + 23, y + 17, z + 9, dSteel, 0, 3);
		world.setBlock(x + 15, y + 17, z + 10, dSteel, 0, 3);
		world.setBlock(x + 16, y + 17, z + 10, dSteel, 0, 3);
		world.setBlock(x + 17, y + 17, z + 10, dSteel, 0, 3);
		world.setBlock(x + 18, y + 17, z + 10, Library.getRandomConcrete(), 0, 3);
		world.setBlock(x + 19, y + 17, z + 10, Library.getRandomConcrete(), 0, 3);
		world.setBlock(x + 20, y + 17, z + 10, Library.getRandomConcrete(), 0, 3);
		world.setBlock(x + 21, y + 17, z + 10, dSteel, 0, 3);
		world.setBlock(x + 22, y + 17, z + 10, dSteel, 0, 3);
		world.setBlock(x + 23, y + 17, z + 10, dSteel, 0, 3);
		world.setBlock(x + 15, y + 17, z + 11, dSteel, 0, 3);
		world.setBlock(x + 16, y + 17, z + 11, dSteel, 0, 3);
		world.setBlock(x + 17, y + 17, z + 11, Library.getRandomConcrete(), 0, 3);
		world.setBlock(x + 18, y + 17, z + 11, Library.getRandomConcrete(), 0, 3);
		world.setBlock(x + 19, y + 17, z + 11, Library.getRandomConcrete(), 0, 3);
		world.setBlock(x + 20, y + 17, z + 11, Library.getRandomConcrete(), 0, 3);
		world.setBlock(x + 21, y + 17, z + 11, Library.getRandomConcrete(), 0, 3);
		world.setBlock(x + 22, y + 17, z + 11, dSteel, 0, 3);
		world.setBlock(x + 23, y + 17, z + 11, dSteel, 0, 3);
		world.setBlock(x + 15, y + 17, z + 12, dSteel, 0, 3);
		world.setBlock(x + 16, y + 17, z + 12, dSteel, 0, 3);
		world.setBlock(x + 17, y + 17, z + 12, Library.getRandomConcrete(), 0, 3);
		world.setBlock(x + 18, y + 17, z + 12, Library.getRandomConcrete(), 0, 3);
		world.setBlock(x + 19, y + 17, z + 12, Library.getRandomConcrete(), 0, 3);
		world.setBlock(x + 20, y + 17, z + 12, Library.getRandomConcrete(), 0, 3);
		world.setBlock(x + 21, y + 17, z + 12, Library.getRandomConcrete(), 0, 3);
		world.setBlock(x + 22, y + 17, z + 12, dSteel, 0, 3);
		world.setBlock(x + 23, y + 17, z + 12, dSteel, 0, 3);
		world.setBlock(x + 15, y + 17, z + 13, dSteel, 0, 3);
		world.setBlock(x + 16, y + 17, z + 13, dSteel, 0, 3);
		world.setBlock(x + 17, y + 17, z + 13, Library.getRandomConcrete(), 0, 3);
		world.setBlock(x + 18, y + 17, z + 13, Library.getRandomConcrete(), 0, 3);
		world.setBlock(x + 19, y + 17, z + 13, Library.getRandomConcrete(), 0, 3);
		world.setBlock(x + 20, y + 17, z + 13, Library.getRandomConcrete(), 0, 3);
		world.setBlock(x + 21, y + 17, z + 13, Library.getRandomConcrete(), 0, 3);
		world.setBlock(x + 22, y + 17, z + 13, dSteel, 0, 3);
		world.setBlock(x + 23, y + 17, z + 13, dSteel, 0, 3);
		world.setBlock(x + 15, y + 17, z + 14, dSteel, 0, 3);
		world.setBlock(x + 16, y + 17, z + 14, dSteel, 0, 3);
		world.setBlock(x + 17, y + 17, z + 14, dSteel, 0, 3);
		world.setBlock(x + 18, y + 17, z + 14, Library.getRandomConcrete(), 0, 3);
		world.setBlock(x + 19, y + 17, z + 14, Library.getRandomConcrete(), 0, 3);
		world.setBlock(x + 20, y + 17, z + 14, Library.getRandomConcrete(), 0, 3);
		world.setBlock(x + 21, y + 17, z + 14, dSteel, 0, 3);
		world.setBlock(x + 22, y + 17, z + 14, dSteel, 0, 3);
		world.setBlock(x + 23, y + 17, z + 14, dSteel, 0, 3);
		world.setBlock(x + 15, y + 17, z + 15, dSteel, 0, 3);
		world.setBlock(x + 16, y + 17, z + 15, dSteel, 0, 3);
		world.setBlock(x + 17, y + 17, z + 15, dSteel, 0, 3);
		world.setBlock(x + 18, y + 17, z + 15, dSteel, 0, 3);
		world.setBlock(x + 19, y + 17, z + 15, dSteel, 0, 3);
		world.setBlock(x + 20, y + 17, z + 15, dSteel, 0, 3);
		world.setBlock(x + 21, y + 17, z + 15, dSteel, 0, 3);
		world.setBlock(x + 22, y + 17, z + 15, dSteel, 0, 3);
		world.setBlock(x + 23, y + 17, z + 15, dSteel, 0, 3);
		world.setBlock(x + 16, y + 17, z + 16, dSteel, 0, 3);
		world.setBlock(x + 17, y + 17, z + 16, dSteel, 0, 3);
		world.setBlock(x + 18, y + 17, z + 16, dSteel, 0, 3);
		world.setBlock(x + 19, y + 17, z + 16, dSteel, 0, 3);
		world.setBlock(x + 20, y + 17, z + 16, dSteel, 0, 3);
		world.setBlock(x + 21, y + 17, z + 16, dSteel, 0, 3);
		world.setBlock(x + 22, y + 17, z + 16, dSteel, 0, 3);
		world.setBlock(x + 19, y + 17, z + 17, ModBlocks.fence_metal, 0, 3);
		world.setBlock(x + 21, y + 17, z + 17, ModBlocks.fence_metal, 0, 3);
		world.setBlock(x + 19, y + 17, z + 18, ModBlocks.fence_metal, 0, 3);
		world.setBlock(x + 21, y + 17, z + 18, ModBlocks.fence_metal, 0, 3);
		world.setBlock(x + 7, y + 17, z + 19, dSteel, 0, 3);
		world.setBlock(x + 8, y + 17, z + 19, dSteel, 0, 3);
		world.setBlock(x + 9, y + 17, z + 19, dSteel, 0, 3);
		world.setBlock(x + 10, y + 17, z + 19, dSteel, 0, 3);
		world.setBlock(x + 11, y + 17, z + 19, dSteel, 0, 3);
		world.setBlock(x + 12, y + 17, z + 19, dSteel, 0, 3);
		world.setBlock(x + 13, y + 17, z + 19, dSteel, 0, 3);
		world.setBlock(x + 14, y + 17, z + 19, dSteel, 0, 3);
		world.setBlock(x + 15, y + 17, z + 19, dSteel, 0, 3);
		world.setBlock(x + 16, y + 17, z + 19, dSteel, 0, 3);
		world.setBlock(x + 17, y + 17, z + 19, dSteel, 0, 3);
		world.setBlock(x + 18, y + 17, z + 19, dSteel, 0, 3);
		world.setBlock(x + 19, y + 17, z + 19, dSteel, 0, 3);
		world.setBlock(x + 7, y + 17, z + 20, dSteel, 0, 3);
		world.setBlock(x + 8, y + 17, z + 20, dSteel, 0, 3);
		world.setBlock(x + 9, y + 17, z + 20, dSteel, 0, 3);
		world.setBlock(x + 10, y + 17, z + 20, dSteel, 0, 3);
		world.setBlock(x + 11, y + 17, z + 20, dSteel, 0, 3);
		world.setBlock(x + 12, y + 17, z + 20, dSteel, 0, 3);
		world.setBlock(x + 13, y + 17, z + 20, dSteel, 0, 3);
		world.setBlock(x + 14, y + 17, z + 20, dSteel, 0, 3);
		world.setBlock(x + 15, y + 17, z + 20, dSteel, 0, 3);
		world.setBlock(x + 16, y + 17, z + 20, dSteel, 0, 3);
		world.setBlock(x + 17, y + 17, z + 20, dSteel, 0, 3);
		world.setBlock(x + 18, y + 17, z + 20, dSteel, 0, 3);
		world.setBlock(x + 19, y + 17, z + 20, dSteel, 0, 3);
		world.setBlock(x + 7, y + 17, z + 21, dSteel, 0, 3);
		world.setBlock(x + 8, y + 17, z + 21, dSteel, 0, 3);
		world.setBlock(x + 9, y + 17, z + 21, dSteel, 0, 3);
		world.setBlock(x + 10, y + 17, z + 21, dSteel, 0, 3);
		world.setBlock(x + 11, y + 17, z + 21, dSteel, 0, 3);
		world.setBlock(x + 12, y + 17, z + 21, dSteel, 0, 3);
		world.setBlock(x + 13, y + 17, z + 21, dSteel, 0, 3);
		world.setBlock(x + 14, y + 17, z + 21, dSteel, 0, 3);
		world.setBlock(x + 15, y + 17, z + 21, dSteel, 0, 3);
		world.setBlock(x + 16, y + 17, z + 21, dSteel, 0, 3);
		world.setBlock(x + 17, y + 17, z + 21, dSteel, 0, 3);
		world.setBlock(x + 18, y + 17, z + 21, dSteel, 0, 3);
		world.setBlock(x + 19, y + 17, z + 21, dSteel, 0, 3);
		world.setBlock(x + 7, y + 17, z + 22, dSteel, 0, 3);
		world.setBlock(x + 8, y + 17, z + 22, dSteel, 0, 3);
		world.setBlock(x + 9, y + 17, z + 22, dSteel, 0, 3);
		world.setBlock(x + 10, y + 17, z + 22, dSteel, 0, 3);
		world.setBlock(x + 11, y + 17, z + 22, dSteel, 0, 3);
		world.setBlock(x + 12, y + 17, z + 22, dSteel, 0, 3);
		world.setBlock(x + 13, y + 17, z + 22, dSteel, 0, 3);
		world.setBlock(x + 14, y + 17, z + 22, dSteel, 0, 3);
		world.setBlock(x + 15, y + 17, z + 22, dSteel, 0, 3);
		world.setBlock(x + 16, y + 17, z + 22, dSteel, 0, 3);
		world.setBlock(x + 17, y + 17, z + 22, dSteel, 0, 3);
		world.setBlock(x + 18, y + 17, z + 22, dSteel, 0, 3);
		world.setBlock(x + 19, y + 17, z + 22, dSteel, 0, 3);
		world.setBlock(x + 7, y + 17, z + 23, dSteel, 0, 3);
		world.setBlock(x + 8, y + 17, z + 23, dSteel, 0, 3);
		world.setBlock(x + 9, y + 17, z + 23, dSteel, 0, 3);
		world.setBlock(x + 10, y + 17, z + 23, dSteel, 0, 3);
		world.setBlock(x + 11, y + 17, z + 23, dSteel, 0, 3);
		world.setBlock(x + 12, y + 17, z + 23, dSteel, 0, 3);
		world.setBlock(x + 13, y + 17, z + 23, dSteel, 0, 3);
		world.setBlock(x + 14, y + 17, z + 23, dSteel, 0, 3);
		world.setBlock(x + 15, y + 17, z + 23, dSteel, 0, 3);
		world.setBlock(x + 16, y + 17, z + 23, dSteel, 0, 3);
		world.setBlock(x + 17, y + 17, z + 23, dSteel, 0, 3);
		world.setBlock(x + 18, y + 17, z + 23, dSteel, 0, 3);
		world.setBlock(x + 19, y + 17, z + 23, dSteel, 0, 3);
		world.setBlock(x + 7, y + 17, z + 24, dSteel, 0, 3);
		world.setBlock(x + 8, y + 17, z + 24, dSteel, 0, 3);
		world.setBlock(x + 9, y + 17, z + 24, dSteel, 0, 3);
		world.setBlock(x + 10, y + 17, z + 24, dSteel, 0, 3);
		world.setBlock(x + 11, y + 17, z + 24, dSteel, 0, 3);
		world.setBlock(x + 12, y + 17, z + 24, dSteel, 0, 3);
		world.setBlock(x + 13, y + 17, z + 24, dSteel, 0, 3);
		world.setBlock(x + 14, y + 17, z + 24, dSteel, 0, 3);
		world.setBlock(x + 15, y + 17, z + 24, dSteel, 0, 3);
		world.setBlock(x + 16, y + 17, z + 24, dSteel, 0, 3);
		world.setBlock(x + 17, y + 17, z + 24, dSteel, 0, 3);
		world.setBlock(x + 18, y + 17, z + 24, dSteel, 0, 3);
		world.setBlock(x + 19, y + 17, z + 24, dSteel, 0, 3);
		world.setBlock(x + 7, y + 17, z + 25, dSteel, 0, 3);
		world.setBlock(x + 8, y + 17, z + 25, dSteel, 0, 3);
		world.setBlock(x + 9, y + 17, z + 25, dSteel, 0, 3);
		world.setBlock(x + 10, y + 17, z + 25, dSteel, 0, 3);
		world.setBlock(x + 11, y + 17, z + 25, dSteel, 0, 3);
		world.setBlock(x + 12, y + 17, z + 25, dSteel, 0, 3);
		world.setBlock(x + 13, y + 17, z + 25, dSteel, 0, 3);
		world.setBlock(x + 14, y + 17, z + 25, dSteel, 0, 3);
		world.setBlock(x + 15, y + 17, z + 25, dSteel, 0, 3);
		world.setBlock(x + 16, y + 17, z + 25, dSteel, 0, 3);
		world.setBlock(x + 17, y + 17, z + 25, dSteel, 0, 3);
		world.setBlock(x + 18, y + 17, z + 25, dSteel, 0, 3);
		world.setBlock(x + 19, y + 17, z + 25, dSteel, 0, 3);
		world.setBlock(x + 7, y + 17, z + 26, dSteel, 0, 3);
		world.setBlock(x + 8, y + 17, z + 26, dSteel, 0, 3);
		world.setBlock(x + 9, y + 17, z + 26, dSteel, 0, 3);
		world.setBlock(x + 10, y + 17, z + 26, dSteel, 0, 3);
		world.setBlock(x + 11, y + 17, z + 26, dSteel, 0, 3);
		world.setBlock(x + 12, y + 17, z + 26, dSteel, 0, 3);
		world.setBlock(x + 13, y + 17, z + 26, dSteel, 0, 3);
		world.setBlock(x + 14, y + 17, z + 26, dSteel, 0, 3);
		world.setBlock(x + 15, y + 17, z + 26, dSteel, 0, 3);
		world.setBlock(x + 16, y + 17, z + 26, dSteel, 0, 3);
		world.setBlock(x + 17, y + 17, z + 26, dSteel, 0, 3);
		world.setBlock(x + 18, y + 17, z + 26, dSteel, 0, 3);
		world.setBlock(x + 19, y + 17, z + 26, dSteel, 0, 3);
		world.setBlock(x + 7, y + 17, z + 27, dSteel, 0, 3);
		world.setBlock(x + 8, y + 17, z + 27, dSteel, 0, 3);
		world.setBlock(x + 9, y + 17, z + 27, dSteel, 0, 3);
		world.setBlock(x + 10, y + 17, z + 27, dSteel, 0, 3);
		world.setBlock(x + 11, y + 17, z + 27, dSteel, 0, 3);
		world.setBlock(x + 12, y + 17, z + 27, dSteel, 0, 3);
		world.setBlock(x + 13, y + 17, z + 27, dSteel, 0, 3);
		world.setBlock(x + 14, y + 17, z + 27, dSteel, 0, 3);
		world.setBlock(x + 15, y + 17, z + 27, dSteel, 0, 3);
		world.setBlock(x + 16, y + 17, z + 27, dSteel, 0, 3);
		world.setBlock(x + 17, y + 17, z + 27, dSteel, 0, 3);
		world.setBlock(x + 18, y + 17, z + 27, dSteel, 0, 3);
		world.setBlock(x + 19, y + 17, z + 27, dSteel, 0, 3);
		world.setBlock(x + 16, y + 18, z + 8, ModBlocks.fence_metal, 0, 3);
		world.setBlock(x + 17, y + 18, z + 8, ModBlocks.fence_metal, 0, 3);
		world.setBlock(x + 18, y + 18, z + 8, ModBlocks.fence_metal, 0, 3);
		world.setBlock(x + 19, y + 18, z + 8, ModBlocks.fence_metal, 0, 3);
		world.setBlock(x + 20, y + 18, z + 8, ModBlocks.fence_metal, 0, 3);
		world.setBlock(x + 21, y + 18, z + 8, ModBlocks.fence_metal, 0, 3);
		world.setBlock(x + 22, y + 18, z + 8, ModBlocks.fence_metal, 0, 3);
		world.setBlock(x + 15, y + 18, z + 9, ModBlocks.fence_metal, 0, 3);
		world.setBlock(x + 16, y + 18, z + 9, ModBlocks.fence_metal, 0, 3);
		world.setBlock(x + 22, y + 18, z + 9, ModBlocks.fence_metal, 0, 3);
		world.setBlock(x + 23, y + 18, z + 9, ModBlocks.fence_metal, 0, 3);
		world.setBlock(x + 15, y + 18, z + 10, ModBlocks.fence_metal, 0, 3);
		world.setBlock(x + 18, y + 18, z + 10, Library.getRandomConcrete(), 0, 3);
		world.setBlock(x + 19, y + 18, z + 10, Library.getRandomConcrete(), 0, 3);
		world.setBlock(x + 20, y + 18, z + 10, Library.getRandomConcrete(), 0, 3);
		world.setBlock(x + 23, y + 18, z + 10, ModBlocks.fence_metal, 0, 3);
		world.setBlock(x + 15, y + 18, z + 11, ModBlocks.fence_metal, 0, 3);
		world.setBlock(x + 17, y + 18, z + 11, Library.getRandomConcrete(), 0, 3);
		world.setBlock(x + 18, y + 18, z + 11, Library.getRandomConcrete(), 0, 3);
		world.setBlock(x + 19, y + 18, z + 11, Library.getRandomConcrete(), 0, 3);
		world.setBlock(x + 20, y + 18, z + 11, Library.getRandomConcrete(), 0, 3);
		world.setBlock(x + 21, y + 18, z + 11, Library.getRandomConcrete(), 0, 3);
		world.setBlock(x + 23, y + 18, z + 11, ModBlocks.fence_metal, 0, 3);
		world.setBlock(x + 15, y + 18, z + 12, ModBlocks.fence_metal, 0, 3);
		world.setBlock(x + 17, y + 18, z + 12, Library.getRandomConcrete(), 0, 3);
		world.setBlock(x + 18, y + 18, z + 12, Library.getRandomConcrete(), 0, 3);
		world.setBlock(x + 19, y + 18, z + 12, Library.getRandomConcrete(), 0, 3);
		world.setBlock(x + 20, y + 18, z + 12, Library.getRandomConcrete(), 0, 3);
		world.setBlock(x + 21, y + 18, z + 12, Library.getRandomConcrete(), 0, 3);
		world.setBlock(x + 23, y + 18, z + 12, ModBlocks.fence_metal, 0, 3);
		world.setBlock(x + 15, y + 18, z + 13, ModBlocks.fence_metal, 0, 3);
		world.setBlock(x + 17, y + 18, z + 13, Library.getRandomConcrete(), 0, 3);
		world.setBlock(x + 18, y + 18, z + 13, Library.getRandomConcrete(), 0, 3);
		world.setBlock(x + 19, y + 18, z + 13, Library.getRandomConcrete(), 0, 3);
		world.setBlock(x + 20, y + 18, z + 13, Library.getRandomConcrete(), 0, 3);
		world.setBlock(x + 21, y + 18, z + 13, Library.getRandomConcrete(), 0, 3);
		world.setBlock(x + 23, y + 18, z + 13, ModBlocks.fence_metal, 0, 3);
		world.setBlock(x + 15, y + 18, z + 14, ModBlocks.fence_metal, 0, 3);
		world.setBlock(x + 18, y + 18, z + 14, Library.getRandomConcrete(), 0, 3);
		world.setBlock(x + 19, y + 18, z + 14, Library.getRandomConcrete(), 0, 3);
		world.setBlock(x + 20, y + 18, z + 14, Library.getRandomConcrete(), 0, 3);
		world.setBlock(x + 23, y + 18, z + 14, ModBlocks.fence_metal, 0, 3);
		world.setBlock(x + 15, y + 18, z + 15, ModBlocks.fence_metal, 0, 3);
		world.setBlock(x + 16, y + 18, z + 15, ModBlocks.fence_metal, 0, 3);
		world.setBlock(x + 22, y + 18, z + 15, ModBlocks.fence_metal, 0, 3);
		world.setBlock(x + 23, y + 18, z + 15, ModBlocks.fence_metal, 0, 3);
		world.setBlock(x + 16, y + 18, z + 16, ModBlocks.fence_metal, 0, 3);
		world.setBlock(x + 17, y + 18, z + 16, ModBlocks.fence_metal, 0, 3);
		world.setBlock(x + 18, y + 18, z + 16, ModBlocks.fence_metal, 0, 3);
		world.setBlock(x + 19, y + 18, z + 16, ModBlocks.fence_metal, 0, 3);
		world.setBlock(x + 21, y + 18, z + 16, ModBlocks.fence_metal, 0, 3);
		world.setBlock(x + 22, y + 18, z + 16, ModBlocks.fence_metal, 0, 3);
		world.setBlock(x + 19, y + 18, z + 17, ModBlocks.fence_metal, 0, 3);
		world.setBlock(x + 21, y + 18, z + 17, ModBlocks.fence_metal, 0, 3);
		world.setBlock(x + 18, y + 19, z + 10, Library.getRandomConcrete(), 0, 3);
		world.setBlock(x + 19, y + 19, z + 10, Library.getRandomConcrete(), 0, 3);
		world.setBlock(x + 20, y + 19, z + 10, Library.getRandomConcrete(), 0, 3);
		world.setBlock(x + 17, y + 19, z + 11, Library.getRandomConcrete(), 0, 3);
		world.setBlock(x + 18, y + 19, z + 11, Library.getRandomConcrete(), 0, 3);
		world.setBlock(x + 19, y + 19, z + 11, Library.getRandomConcrete(), 0, 3);
		world.setBlock(x + 20, y + 19, z + 11, Library.getRandomConcrete(), 0, 3);
		world.setBlock(x + 21, y + 19, z + 11, Library.getRandomConcrete(), 0, 3);
		world.setBlock(x + 17, y + 19, z + 12, Library.getRandomConcrete(), 0, 3);
		world.setBlock(x + 18, y + 19, z + 12, Library.getRandomConcrete(), 0, 3);
		world.setBlock(x + 19, y + 19, z + 12, Blocks.chest, 4, 3);
		world.setBlockMetadataWithNotify(x + 19, y + 19, z + 12, 4, 3);
        WeightedRandomChestContent.generateChestContents(rand, ItemPool.getPool(ItemPoolsLegacy.POOL_EXPENSIVE), (TileEntityChest)world.getTileEntity(x + 19, y + 19, z + 12), 12);
		world.setBlock(x + 20, y + 19, z + 12, Library.getRandomConcrete(), 0, 3);
		world.setBlock(x + 21, y + 19, z + 12, Library.getRandomConcrete(), 0, 3);
		world.setBlock(x + 17, y + 19, z + 13, Library.getRandomConcrete(), 0, 3);
		world.setBlock(x + 18, y + 19, z + 13, Library.getRandomConcrete(), 0, 3);
		world.setBlock(x + 19, y + 19, z + 13, Library.getRandomConcrete(), 0, 3);
		world.setBlock(x + 20, y + 19, z + 13, Library.getRandomConcrete(), 0, 3);
		world.setBlock(x + 21, y + 19, z + 13, Library.getRandomConcrete(), 0, 3);
		world.setBlock(x + 18, y + 19, z + 14, Library.getRandomConcrete(), 0, 3);
		world.setBlock(x + 19, y + 19, z + 14, Library.getRandomConcrete(), 0, 3);
		world.setBlock(x + 20, y + 19, z + 14, Library.getRandomConcrete(), 0, 3);
		world.setBlock(x + 18, y + 20, z + 10, dSteel, 0, 3);
		world.setBlock(x + 19, y + 20, z + 10, dSteel, 0, 3);
		world.setBlock(x + 20, y + 20, z + 10, dSteel, 0, 3);
		world.setBlock(x + 17, y + 20, z + 11, dSteel, 0, 3);
		world.setBlock(x + 18, y + 20, z + 11, dSteel, 0, 3);
		world.setBlock(x + 19, y + 20, z + 11, dSteel, 0, 3);
		world.setBlock(x + 20, y + 20, z + 11, dSteel, 0, 3);
		world.setBlock(x + 21, y + 20, z + 11, dSteel, 0, 3);
		world.setBlock(x + 17, y + 20, z + 12, dSteel, 0, 3);
		world.setBlock(x + 18, y + 20, z + 12, dSteel, 0, 3);
		world.setBlock(x + 19, y + 20, z + 12, dSteel, 0, 3);
		world.setBlock(x + 20, y + 20, z + 12, dSteel, 0, 3);
		world.setBlock(x + 21, y + 20, z + 12, Block5, 0, 3);
		world.setBlock(x + 22, y + 20, z + 12, Block5, 0, 3);
		world.setBlock(x + 23, y + 20, z + 12, Block5, 0, 3);
		world.setBlock(x + 17, y + 20, z + 13, dSteel, 0, 3);
		world.setBlock(x + 18, y + 20, z + 13, dSteel, 0, 3);
		world.setBlock(x + 19, y + 20, z + 13, dSteel, 0, 3);
		world.setBlock(x + 20, y + 20, z + 13, dSteel, 0, 3);
		world.setBlock(x + 21, y + 20, z + 13, dSteel, 0, 3);
		world.setBlock(x + 18, y + 20, z + 14, dSteel, 0, 3);
		world.setBlock(x + 19, y + 20, z + 14, dSteel, 0, 3);
		world.setBlock(x + 20, y + 20, z + 14, dSteel, 0, 3);
		world.setBlock(x + 18, y + 21, z + 10, dSteel, 0, 3);
		world.setBlock(x + 19, y + 21, z + 10, dSteel, 0, 3);
		world.setBlock(x + 20, y + 21, z + 10, dSteel, 0, 3);
		world.setBlock(x + 18, y + 21, z + 11, dSteel, 0, 3);
		world.setBlock(x + 19, y + 21, z + 11, dSteel, 0, 3);
		world.setBlock(x + 20, y + 21, z + 11, dSteel, 0, 3);
		world.setBlock(x + 22, y + 21, z + 11, Block4, 0, 3);
		world.setBlock(x + 21, y + 21, z + 12, Block5, 0, 3);
		world.setBlock(x + 22, y + 21, z + 12, Block4, 0, 3);
		world.setBlock(x + 23, y + 21, z + 12, Block5, 0, 3);
		world.setBlock(x + 24, y + 21, z + 12, Block5, 0, 3);
		world.setBlock(x + 18, y + 21, z + 13, dSteel, 0, 3);
		world.setBlock(x + 19, y + 21, z + 13, dSteel, 0, 3);
		world.setBlock(x + 20, y + 21, z + 13, dSteel, 0, 3);
		world.setBlock(x + 22, y + 21, z + 13, Block4, 0, 3);
		world.setBlock(x + 18, y + 21, z + 14, dSteel, 0, 3);
		world.setBlock(x + 19, y + 21, z + 14, dSteel, 0, 3);
		world.setBlock(x + 20, y + 21, z + 14, dSteel, 0, 3);
		world.setBlock(x + 15, y + 22, z + 9, dSteel, 0, 3);
		world.setBlock(x + 18, y + 22, z + 10, dSteel, 0, 3);
		world.setBlock(x + 19, y + 22, z + 10, dSteel, 0, 3);
		world.setBlock(x + 20, y + 22, z + 10, dSteel, 0, 3);
		world.setBlock(x + 21, y + 22, z + 11, Block4, 0, 3);
		world.setBlock(x + 22, y + 22, z + 11, Block4, 0, 3);
		world.setBlock(x + 23, y + 22, z + 11, Block4, 0, 3);
		world.setBlock(x + 21, y + 22, z + 12, Block4, 0, 3);
		world.setBlock(x + 22, y + 22, z + 12, Block4, 0, 3);
		world.setBlock(x + 23, y + 22, z + 12, Block4, 0, 3);
		world.setBlock(x + 24, y + 22, z + 12, Block5, 0, 3);
		world.setBlock(x + 21, y + 22, z + 13, Block4, 0, 3);
		world.setBlock(x + 22, y + 22, z + 13, Block4, 0, 3);
		world.setBlock(x + 23, y + 22, z + 13, Block4, 0, 3);
		world.setBlock(x + 18, y + 22, z + 14, dSteel, 0, 3);
		world.setBlock(x + 19, y + 22, z + 14, dSteel, 0, 3);
		world.setBlock(x + 20, y + 22, z + 14, dSteel, 0, 3);
		world.setBlock(x + 15, y + 22, z + 15, dSteel, 0, 3);
		world.setBlock(x + 14, y + 23, z + 9, dSteel, 0, 3);
		world.setBlock(x + 15, y + 23, z + 9, dSteel, 0, 3);
		world.setBlock(x + 16, y + 23, z + 9, dSteel, 0, 3);
		world.setBlock(x + 15, y + 23, z + 10, dSteel, 0, 3);
		world.setBlock(x + 18, y + 23, z + 10, dSteel, 0, 3);
		world.setBlock(x + 19, y + 23, z + 10, dSteel, 0, 3);
		world.setBlock(x + 20, y + 23, z + 10, dSteel, 0, 3);
		world.setBlock(x + 15, y + 23, z + 11, dSteel, 0, 3);
		world.setBlock(x + 20, y + 23, z + 11, Block4, 0, 3);
		world.setBlock(x + 21, y + 23, z + 11, Block4, 0, 3);
		world.setBlock(x + 22, y + 23, z + 11, Block4, 0, 3);
		world.setBlock(x + 15, y + 23, z + 12, dSteel, 0, 3);
		world.setBlock(x + 20, y + 23, z + 12, Block4, 0, 3);
		world.setBlock(x + 21, y + 23, z + 12, Block4, 0, 3);
		world.setBlock(x + 22, y + 23, z + 12, Block4, 0, 3);
		world.setBlock(x + 23, y + 23, z + 12, Block5, 0, 3);
		world.setBlock(x + 24, y + 23, z + 12, Block5, 0, 3);
		world.setBlock(x + 15, y + 23, z + 13, dSteel, 0, 3);
		world.setBlock(x + 20, y + 23, z + 13, Block4, 0, 3);
		world.setBlock(x + 21, y + 23, z + 13, Block4, 0, 3);
		world.setBlock(x + 22, y + 23, z + 13, Block4, 0, 3);
		world.setBlock(x + 15, y + 23, z + 14, dSteel, 0, 3);
		world.setBlock(x + 18, y + 23, z + 14, dSteel, 0, 3);
		world.setBlock(x + 19, y + 23, z + 14, dSteel, 0, 3);
