//Schematic to java Structure by jajo_11 | inspired by "MITHION'S .SCHEMATIC TO JAVA CONVERTINGTOOL"

package com.hbm.world.dungeon;

import java.util.Random;

import com.hbm.blocks.BlockDummyable;
import com.hbm.blocks.ModBlocks;
import com.hbm.blocks.bomb.LaunchPad;
import com.hbm.config.GeneralConfig;
import com.hbm.itempool.ItemPool;
import com.hbm.itempool.ItemPoolsComponent;
import com.hbm.itempool.ItemPoolsLegacy;
import com.hbm.lib.Library;
import net.minecraft.block.Block;
import net.minecraft.block.material.Material;
import net.minecraft.init.Blocks;
import net.minecraft.tileentity.TileEntityChest;
import net.minecraft.util.WeightedRandomChestContent;
import net.minecraft.world.World;
import net.minecraft.world.gen.feature.WorldGenerator;
import net.minecraftforge.common.util.ForgeDirection;

public class Silo extends WorldGenerator
{
	Block Block2 = ModBlocks.launch_pad;
	Block Block3 = ModBlocks.reinforced_light;
	Block Block4 = ModBlocks.tape_recorder;
	Block Block5 = ModBlocks.reinforced_glass;
	Block Block6 = ModBlocks.deco_steel;
	
	protected Block[] GetValidSpawnBlocks()
	{
		return new Block[]
		{
			Blocks.grass,
			Blocks.dirt,
			Blocks.stone,
			Blocks.sand,
			Blocks.sandstone,
		};
	}

	public boolean LocationIsValidSpawn(World world, int x, int y, int z)
 {

		Block checkBlock = world.getBlock(x, y - 1, z);
		Block blockAbove = world.getBlock(x, y , z);
		Block blockBelow = world.getBlock(x, y - 2, z);

		for (Block i : GetValidSpawnBlocks())
		{
			if (blockAbove != Blocks.air)
			{
				return false;
			}
			if (checkBlock == i)
			{
				return true;
			}
			else if (checkBlock == Blocks.snow_layer && blockBelow == i)
			{
				return true;
			}
			else if (checkBlock.getMaterial() == Material.plants && blockBelow == i)
			{
				return true;
			}
		}
		return false;
	}

	@Override
	public boolean generate(World world, Random rand, int x, int y, int z)
	{
		int i = rand.nextInt(1);

		if(i == 0)
		{
		    generate_r0(world, rand, x, y, z);
		}

       return true;

	}

	public boolean generate_r0(World world, Random rand, int x, int y, int z)
	{
		if(!LocationIsValidSpawn(world, x + 10, y, z + 10))
		{
			return false;
		}

		world.setBlock(x + 7, y + -21, z + 1, Library.getRandomConcrete(), 0, 3);
		world.setBlock(x + 8, y + -21, z + 1, Library.getRandomConcrete(), 0, 3);
		world.setBlock(x + 9, y + -21, z + 1, Library.getRandomConcrete(), 0, 3);
		world.setBlock(x + 10, y + -21, z + 1, Library.getRandomConcrete(), 0, 3);
		world.setBlock(x + 11, y + -21, z + 1, Library.getRandomConcrete(), 0, 3);
		world.setBlock(x + 7, y + -21, z + 2, Library.getRandomConcrete(), 0, 3);
		world.setBlock(x + 8, y + -21, z + 2, Library.getRandomConcrete(), 0, 3);
		world.setBlock(x + 9, y + -21, z + 2, Library.getRandomConcrete(), 0, 3);
		world.setBlock(x + 10, y + -21, z + 2, Library.getRandomConcrete(), 0, 3);
		world.setBlock(x + 11, y + -21, z + 2, Library.getRandomConcrete(), 0, 3);
		world.setBlock(x + 7, y + -21, z + 3, Library.getRandomConcrete(), 0, 3);
		world.setBlock(x + 8, y + -21, z + 3, Library.getRandomConcrete(), 0, 3);
		world.setBlock(x + 9, y + -21, z + 3, Library.getRandomConcrete(), 0, 3);
		world.setBlock(x + 10, y + -21, z + 3, Library.getRandomConcrete(), 0, 3);
		world.setBlock(x + 11, y + -21, z + 3, Library.getRandomConcrete(), 0, 3);
		world.setBlock(x + 7, y + -21, z + 4, Library.getRandomConcrete(), 0, 3);
		world.setBlock(x + 8, y + -21, z + 4, Library.getRandomConcrete(), 0, 3);
		world.setBlock(x + 9, y + -21, z + 4, Library.getRandomConcrete(), 0, 3);
		world.setBlock(x + 10, y + -21, z + 4, Library.getRandomConcrete(), 0, 3);
		world.setBlock(x + 11, y + -21, z + 4, Library.getRandomConcrete(), 0, 3);
		world.setBlock(x + 12, y + -21, z + 4, Library.getRandomConcrete(), 0, 3);
		world.setBlock(x + 13, y + -21, z + 4, Library.getRandomConcrete(), 0, 3);
		world.setBlock(x + 14, y + -21, z + 4, Library.getRandomConcrete(), 0, 3);
		world.setBlock(x + 15, y + -21, z + 4, Library.getRandomConcrete(), 0, 3);
		world.setBlock(x + 7, y + -21, z + 5, Library.getRandomConcrete(), 0, 3);
		world.setBlock(x + 8, y + -21, z + 5, Library.getRandomConcrete(), 0, 3);
		world.setBlock(x + 9, y + -21, z + 5, Library.getRandomConcrete(), 0, 3);
		world.setBlock(x + 10, y + -21, z + 5, Library.getRandomConcrete(), 0, 3);
		world.setBlock(x + 11, y + -21, z + 5, Library.getRandomConcrete(), 0, 3);
		world.setBlock(x + 12, y + -21, z + 5, Library.getRandomConcrete(), 0, 3);
		world.setBlock(x + 13, y + -21, z + 5, Library.getRandomConcrete(), 0, 3);
		world.setBlock(x + 14, y + -21, z + 5, Library.getRandomConcrete(), 0, 3);
		world.setBlock(x + 15, y + -21, z + 5, Library.getRandomConcrete(), 0, 3);
		world.setBlock(x + 7, y + -21, z + 6, Library.getRandomConcrete(), 0, 3);
		world.setBlock(x + 8, y + -21, z + 6, Library.getRandomConcrete(), 0, 3);
		world.setBlock(x + 9, y + -21, z + 6, Library.getRandomConcrete(), 0, 3);
		world.setBlock(x + 10, y + -21, z + 6, Library.getRandomConcrete(), 0, 3);
		world.setBlock(x + 11, y + -21, z + 6, Library.getRandomConcrete(), 0, 3);
		world.setBlock(x + 12, y + -21, z + 6, Library.getRandomConcrete(), 0, 3);
		world.setBlock(x + 13, y + -21, z + 6, Library.getRandomConcrete(), 0, 3);
		world.setBlock(x + 14, y + -21, z + 6, Library.getRandomConcrete(), 0, 3);
		world.setBlock(x + 15, y + -21, z + 6, Library.getRandomConcrete(), 0, 3);
		world.setBlock(x + 6, y + -21, z + 7, Library.getRandomConcrete(), 0, 3);
		world.setBlock(x + 7, y + -21, z + 7, Library.getRandomConcrete(), 0, 3);
		world.setBlock(x + 8, y + -21, z + 7, Library.getRandomConcrete(), 0, 3);
		world.setBlock(x + 9, y + -21, z + 7, Library.getRandomConcrete(), 0, 3);
		world.setBlock(x + 10, y + -21, z + 7, Library.getRandomConcrete(), 0, 3);
		world.setBlock(x + 11, y + -21, z + 7, Library.getRandomConcrete(), 0, 3);
		world.setBlock(x + 12, y + -21, z + 7, Library.getRandomConcrete(), 0, 3);
		world.setBlock(x + 0, y + -21, z + 8, Library.getRandomConcrete(), 0, 3);
		world.setBlock(x + 1, y + -21, z + 8, Library.getRandomConcrete(), 0, 3);
		world.setBlock(x + 2, y + -21, z + 8, Library.getRandomConcrete(), 0, 3);
		world.setBlock(x + 3, y + -21, z + 8, Library.getRandomConcrete(), 0, 3);
		world.setBlock(x + 4, y + -21, z + 8, Library.getRandomConcrete(), 0, 3);
		world.setBlock(x + 5, y + -21, z + 8, Library.getRandomConcrete(), 0, 3);
		world.setBlock(x + 6, y + -21, z + 8, Library.getRandomConcrete(), 0, 3);
		world.setBlock(x + 7, y + -21, z + 8, Library.getRandomConcrete(), 0, 3);
		world.setBlock(x + 8, y + -21, z + 8, Library.getRandomConcrete(), 0, 3);
		world.setBlock(x + 9, y + -21, z + 8, Library.getRandomConcrete(), 0, 3);
		world.setBlock(x + 10, y + -21, z + 8, Library.getRandomConcrete(), 0, 3);
		world.setBlock(x + 11, y + -21, z + 8, Library.getRandomConcrete(), 0, 3);
		world.setBlock(x + 12, y + -21, z + 8, Library.getRandomConcrete(), 0, 3);
		world.setBlock(x + 13, y + -21, z + 8, Library.getRandomConcrete(), 0, 3);
		world.setBlock(x + 14, y + -21, z + 8, Library.getRandomConcrete(), 0, 3);
		world.setBlock(x + 15, y + -21, z + 8, Library.getRandomConcrete(), 0, 3);
		world.setBlock(x + 16, y + -21, z + 8, Library.getRandomConcrete(), 0, 3);
		world.setBlock(x + 17, y + -21, z + 8, Library.getRandomConcrete(), 0, 3);
		world.setBlock(x + 18, y + -21, z + 8, Library.getRandomConcrete(), 0, 3);
		world.setBlock(x + 19, y + -21, z + 8, Library.getRandomConcrete(), 0, 3);
		world.setBlock(x + 20, y + -21, z + 8, Library.getRandomConcrete(), 0, 3);
		world.setBlock(x + 0, y + -21, z + 9, Library.getRandomConcrete(), 0, 3);
		world.setBlock(x + 1, y + -21, z + 9, Library.getRandomConcrete(), 0, 3);
		world.setBlock(x + 2, y + -21, z + 9, Library.getRandomConcrete(), 0, 3);
		world.setBlock(x + 3, y + -21, z + 9, Library.getRandomConcrete(), 0, 3);
		world.setBlock(x + 4, y + -21, z + 9, Library.getRandomConcrete(), 0, 3);
		world.setBlock(x + 5, y + -21, z + 9, Library.getRandomConcrete(), 0, 3);
		world.setBlock(x + 6, y + -21, z + 9, Library.getRandomConcrete(), 0, 3);
		world.setBlock(x + 7, y + -21, z + 9, Library.getRandomConcrete(), 0, 3);
		world.setBlock(x + 8, y + -21, z + 9, Library.getRandomConcrete(), 0, 3);
		world.setBlock(x + 9, y + -21, z + 9, Library.getRandomConcrete(), 0, 3);
		world.setBlock(x + 10, y + -21, z + 9, Library.getRandomConcrete(), 0, 3);
		world.setBlock(x + 11, y + -21, z + 9, Library.getRandomConcrete(), 0, 3);
		world.setBlock(x + 12, y + -21, z + 9, Library.getRandomConcrete(), 0, 3);
		world.setBlock(x + 13, y + -21, z + 9, Library.getRandomConcrete(), 0, 3);
		world.setBlock(x + 14, y + -21, z + 9, Library.getRandomConcrete(), 0, 3);
		world.setBlock(x + 15, y + -21, z + 9, Library.getRandomConcrete(), 0, 3);
		world.setBlock(x + 16, y + -21, z + 9, Library.getRandomConcrete(), 0, 3);
		world.setBlock(x + 17, y + -21, z + 9, Library.getRandomConcrete(), 0, 3);
		world.setBlock(x + 18, y + -21, z + 9, Library.getRandomConcrete(), 0, 3);
		world.setBlock(x + 19, y + -21, z + 9, Library.getRandomConcrete(), 0, 3);
		world.setBlock(x + 20, y + -21, z + 9, Library.getRandomConcrete(), 0, 3);
		world.setBlock(x + 0, y + -21, z + 10, Library.getRandomConcrete(), 0, 3);
		world.setBlock(x + 1, y + -21, z + 10, Library.getRandomConcrete(), 0, 3);
		world.setBlock(x + 2, y + -21, z + 10, Library.getRandomConcrete(), 0, 3);
		world.setBlock(x + 3, y + -21, z + 10, Library.getRandomConcrete(), 0, 3);
		world.setBlock(x + 4, y + -21, z + 10, Library.getRandomConcrete(), 0, 3);
		world.setBlock(x + 5, y + -21, z + 10, Library.getRandomConcrete(), 0, 3);
		world.setBlock(x + 6, y + -21, z + 10, Library.getRandomConcrete(), 0, 3);
		world.setBlock(x + 7, y + -21, z + 10, Library.getRandomConcrete(), 0, 3);
		world.setBlock(x + 8, y + -21, z + 10, Library.getRandomConcrete(), 0, 3);
		world.setBlock(x + 9, y + -21, z + 10, Library.getRandomConcrete(), 0, 3);
		world.setBlock(x + 10, y + -21, z + 10, Library.getRandomConcrete(), 0, 3);
		world.setBlock(x + 11, y + -21, z + 10, Library.getRandomConcrete(), 0, 3);
		world.setBlock(x + 12, y + -21, z + 10, Library.getRandomConcrete(), 0, 3);
		world.setBlock(x + 13, y + -21, z + 10, Library.getRandomConcrete(), 0, 3);
		world.setBlock(x + 14, y + -21, z + 10, Library.getRandomConcrete(), 0, 3);
		world.setBlock(x + 15, y + -21, z + 10, Library.getRandomConcrete(), 0, 3);
		world.setBlock(x + 16, y + -21, z + 10, Library.getRandomConcrete(), 0, 3);
		world.setBlock(x + 17, y + -21, z + 10, Library.getRandomConcrete(), 0, 3);
		world.setBlock(x + 18, y + -21, z + 10, Library.getRandomConcrete(), 0, 3);
		world.setBlock(x + 19, y + -21, z + 10, Library.getRandomConcrete(), 0, 3);
		world.setBlock(x + 20, y + -21, z + 10, Library.getRandomConcrete(), 0, 3);
		world.setBlock(x + 0, y + -21, z + 11, Library.getRandomConcrete(), 0, 3);
		world.setBlock(x + 1, y + -21, z + 11, Library.getRandomConcrete(), 0, 3);
		world.setBlock(x + 2, y + -21, z + 11, Library.getRandomConcrete(), 0, 3);
		world.setBlock(x + 3, y + -21, z + 11, Library.getRandomConcrete(), 0, 3);
		world.setBlock(x + 4, y + -21, z + 11, Library.getRandomConcrete(), 0, 3);
		world.setBlock(x + 5, y + -21, z + 11, Library.getRandomConcrete(), 0, 3);
		world.setBlock(x + 6, y + -21, z + 11, Library.getRandomConcrete(), 0, 3);
		world.setBlock(x + 7, y + -21, z + 11, Library.getRandomConcrete(), 0, 3);
		world.setBlock(x + 8, y + -21, z + 11, Library.getRandomConcrete(), 0, 3);
		world.setBlock(x + 9, y + -21, z + 11, Library.getRandomConcrete(), 0, 3);
		world.setBlock(x + 10, y + -21, z + 11, Library.getRandomConcrete(), 0, 3);
		world.setBlock(x + 11, y + -21, z + 11, Library.getRandomConcrete(), 0, 3);
		world.setBlock(x + 12, y + -21, z + 11, Library.getRandomConcrete(), 0, 3);
		world.setBlock(x + 13, y + -21, z + 11, Library.getRandomConcrete(), 0, 3);
		world.setBlock(x + 14, y + -21, z + 11, Library.getRandomConcrete(), 0, 3);
		world.setBlock(x + 15, y + -21, z + 11, Library.getRandomConcrete(), 0, 3);
		world.setBlock(x + 16, y + -21, z + 11, Library.getRandomConcrete(), 0, 3);
		world.setBlock(x + 17, y + -21, z + 11, Library.getRandomConcrete(), 0, 3);
		world.setBlock(x + 18, y + -21, z + 11, Library.getRandomConcrete(), 0, 3);
		world.setBlock(x + 19, y + -21, z + 11, Library.getRandomConcrete(), 0, 3);
		world.setBlock(x + 20, y + -21, z + 11, Library.getRandomConcrete(), 0, 3);
		world.setBlock(x + 0, y + -21, z + 12, Library.getRandomConcrete(), 0, 3);
		world.setBlock(x + 1, y + -21, z + 12, Library.getRandomConcrete(), 0, 3);
		world.setBlock(x + 2, y + -21, z + 12, Library.getRandomConcrete(), 0, 3);
		world.setBlock(x + 3, y + -21, z + 12, Library.getRandomConcrete(), 0, 3);
		world.setBlock(x + 4, y + -21, z + 12, Library.getRandomConcrete(), 0, 3);
		world.setBlock(x + 5, y + -21, z + 12, Library.getRandomConcrete(), 0, 3);
		world.setBlock(x + 6, y + -21, z + 12, Library.getRandomConcrete(), 0, 3);
		world.setBlock(x + 7, y + -21, z + 12, Library.getRandomConcrete(), 0, 3);
		world.setBlock(x + 8, y + -21, z + 12, Library.getRandomConcrete(), 0, 3);
		world.setBlock(x + 9, y + -21, z + 12, Library.getRandomConcrete(), 0, 3);
		world.setBlock(x + 10, y + -21, z + 12, Library.getRandomConcrete(), 0, 3);
		world.setBlock(x + 11, y + -21, z + 12, Library.getRandomConcrete(), 0, 3);
		world.setBlock(x + 12, y + -21, z + 12, Library.getRandomConcrete(), 0, 3);
		world.setBlock(x + 13, y + -21, z + 12, Library.getRandomConcrete(), 0, 3);
		world.setBlock(x + 14, y + -21, z + 12, Library.getRandomConcrete(), 0, 3);
		world.setBlock(x + 15, y + -21, z + 12, Library.getRandomConcrete(), 0, 3);
		world.setBlock(x + 16, y + -21, z + 12, Library.getRandomConcrete(), 0, 3);
		world.setBlock(x + 17, y + -21, z + 12, Library.getRandomConcrete(), 0, 3);
		world.setBlock(x + 18, y + -21, z + 12, Library.getRandomConcrete(), 0, 3);
		world.setBlock(x + 19, y + -21, z + 12, Library.getRandomConcrete(), 0, 3);
		world.setBlock(x + 20, y + -21, z + 12, Library.getRandomConcrete(), 0, 3);
		world.setBlock(x + 6, y + -21, z + 13, Library.getRandomConcrete(), 0, 3);
		world.setBlock(x + 7, y + -21, z + 13, Library.getRandomConcrete(), 0, 3);
		world.setBlock(x + 8, y + -21, z + 13, Library.getRandomConcrete(), 0, 3);
		world.setBlock(x + 9, y + -21, z + 13, Library.getRandomConcrete(), 0, 3);
		world.setBlock(x + 10, y + -21, z + 13, Library.getRandomConcrete(), 0, 3);
		world.setBlock(x + 11, y + -21, z + 13, Library.getRandomConcrete(), 0, 3);
		world.setBlock(x + 12, y + -21, z + 13, Library.getRandomConcrete(), 0, 3);
		world.setBlock(x + 7, y + -21, z + 14, Library.getRandomConcrete(), 0, 3);
		world.setBlock(x + 8, y + -21, z + 14, Library.getRandomConcrete(), 0, 3);
		world.setBlock(x + 9, y + -21, z + 14, Library.getRandomConcrete(), 0, 3);
		world.setBlock(x + 10, y + -21, z + 14, Library.getRandomConcrete(), 0, 3);
		world.setBlock(x + 11, y + -21, z + 14, Library.getRandomConcrete(), 0, 3);
		world.setBlock(x + 7, y + -21, z + 15, Library.getRandomConcrete(), 0, 3);
		world.setBlock(x + 8, y + -21, z + 15, Library.getRandomConcrete(), 0, 3);
		world.setBlock(x + 9, y + -21, z + 15, Library.getRandomConcrete(), 0, 3);
		world.setBlock(x + 10, y + -21, z + 15, Library.getRandomConcrete(), 0, 3);
		world.setBlock(x + 11, y + -21, z + 15, Library.getRandomConcrete(), 0, 3);
		world.setBlock(x + 7, y + -21, z + 16, Library.getRandomConcrete(), 0, 3);
		world.setBlock(x + 8, y + -21, z + 16, Library.getRandomConcrete(), 0, 3);
		world.setBlock(x + 9, y + -21, z + 16, Library.getRandomConcrete(), 0, 3);
		world.setBlock(x + 10, y + -21, z + 16, Library.getRandomConcrete(), 0, 3);
		world.setBlock(x + 11, y + -21, z + 16, Library.getRandomConcrete(), 0, 3);
		world.setBlock(x + 7, y + -21, z + 17, Library.getRandomConcrete(), 0, 3);
		world.setBlock(x + 8, y + -21, z + 17, Library.getRandomConcrete(), 0, 3);
		world.setBlock(x + 9, y + -21, z + 17, Library.getRandomConcrete(), 0, 3);
		world.setBlock(x + 10, y + -21, z + 17, Library.getRandomConcrete(), 0, 3);
		world.setBlock(x + 11, y + -21, z + 17, Library.getRandomConcrete(), 0, 3);
		world.setBlock(x + 7, y + -21, z + 18, Library.getRandomConcrete(), 0, 3);
		world.setBlock(x + 8, y + -21, z + 18, Library.getRandomConcrete(), 0, 3);
		world.setBlock(x + 9, y + -21, z + 18, Library.getRandomConcrete(), 0, 3);
		world.setBlock(x + 10, y + -21, z + 18, Library.getRandomConcrete(), 0, 3);
		world.setBlock(x + 11, y + -21, z + 18, Library.getRandomConcrete(), 0, 3);
		world.setBlock(x + 7, y + -21, z + 19, Library.getRandomConcrete(), 0, 3);
		world.setBlock(x + 8, y + -21, z + 19, Library.getRandomConcrete(), 0, 3);
		world.setBlock(x + 9, y + -21, z + 19, Library.getRandomConcrete(), 0, 3);
		world.setBlock(x + 10, y + -21, z + 19, Library.getRandomConcrete(), 0, 3);
		world.setBlock(x + 11, y + -21, z + 19, Library.getRandomConcrete(), 0, 3);
		world.setBlock(x + 7, y + -20, z + 1, Library.getRandomConcrete(), 0, 3);
		world.setBlock(x + 8, y + -20, z + 1, Library.getRandomConcrete(), 0, 3);
		world.setBlock(x + 9, y + -20, z + 1, Library.getRandomConcrete(), 0, 3);
		world.setBlock(x + 10, y + -20, z + 1, Library.getRandomConcrete(), 0, 3);
		world.setBlock(x + 11, y + -20, z + 1, Library.getRandomConcrete(), 0, 3);
		world.setBlock(x + 7, y + -20, z + 2, Library.getRandomConcrete(), 0, 3);
		world.setBlock(x + 8, y + -20, z + 2, Blocks.air, 0, 3);
		world.setBlock(x + 9, y + -20, z + 2, Blocks.air, 0, 3);
		world.setBlock(x + 10, y + -20, z + 2, Blocks.air, 0, 3);
		world.setBlock(x + 11, y + -20, z + 2, Library.getRandomConcrete(), 0, 3);
		world.setBlock(x + 7, y + -20, z + 3, Library.getRandomConcrete(), 0, 3);
		world.setBlock(x + 8, y + -20, z + 3, Blocks.air, 0, 3);
		world.setBlock(x + 9, y + -20, z + 3, Blocks.air, 0, 3);
		world.setBlock(x + 10, y + -20, z + 3, Blocks.air, 0, 3);
		world.setBlock(x + 11, y + -20, z + 3, Library.getRandomConcrete(), 0, 3);
		world.setBlock(x + 7, y + -20, z + 4, Library.getRandomConcrete(), 0, 3);
		world.setBlock(x + 8, y + -20, z + 4, Blocks.air, 0, 3);
		world.setBlock(x + 9, y + -20, z + 4, Blocks.air, 0, 3);
		world.setBlock(x + 10, y + -20, z + 4, Blocks.air, 0, 3);
		world.setBlock(x + 11, y + -20, z + 4, Library.getRandomConcrete(), 0, 3);
		world.setBlock(x + 12, y + -20, z + 4, Library.getRandomConcrete(), 0, 3);
		world.setBlock(x + 13, y + -20, z + 4, Library.getRandomConcrete(), 0, 3);
		world.setBlock(x + 14, y + -20, z + 4, Library.getRandomConcrete(), 0, 3);
		world.setBlock(x + 15, y + -20, z + 4, Library.getRandomConcrete(), 0, 3);
		world.setBlock(x + 7, y + -20, z + 5, Library.getRandomConcrete(), 0, 3);
		world.setBlock(x + 8, y + -20, z + 5, Blocks.air, 0, 3);
		world.setBlock(x + 9, y + -20, z + 5, Blocks.air, 0, 3);
		world.setBlock(x + 10, y + -20, z + 5, Blocks.air, 0, 3);
		world.setBlock(x + 11, y + -20, z + 5, Library.getRandomConcrete(), 0, 3);
		world.setBlock(x + 12, y + -20, z + 5, Blocks.redstone_wire, 0, 3);
		world.setBlock(x + 14, y + -20, z + 5, Library.getRandomConcrete(), 0, 3);
		world.setBlock(x + 15, y + -20, z + 5, Library.getRandomConcrete(), 0, 3);
		world.setBlock(x + 7, y + -20, z + 6, Library.getRandomConcrete(), 0, 3);
		world.setBlock(x + 8, y + -20, z + 6, Blocks.iron_bars, 0, 3);
		world.setBlock(x + 9, y + -20, z + 6, Blocks.iron_bars, 0, 3);
		world.setBlock(x + 10, y + -20, z + 6, Blocks.iron_bars, 0, 3);
		world.setBlock(x + 11, y + -20, z + 6, Library.getRandomConcrete(), 0, 3);
		world.setBlock(x + 12, y + -20, z + 6, Blocks.unpowered_repeater, 2, 3);
		world.setBlock(x + 13, y + -20, z + 6, Library.getRandomConcrete(), 0, 3);
		world.setBlock(x + 14, y + -20, z + 6, Library.getRandomConcrete(), 0, 3);
		world.setBlock(x + 15, y + -20, z + 6, Library.getRandomConcrete(), 0, 3);
		world.setBlock(x + 6, y + -20, z + 7, Library.getRandomConcrete(), 0, 3);
		world.setBlock(x + 7, y + -20, z + 7, Library.getRandomConcrete(), 0, 3);
		world.setBlock(x + 9, y + -20, z + 7, Blocks.air, 0, 3);
		world.setBlock(x + 11, y + -20, z + 7, Library.getRandomConcrete(), 0, 3);
		world.setBlock(x + 12, y + -20, z + 7, Library.getRandomConcrete(), 0, 3);
		world.setBlock(x + 0, y + -20, z + 8, Library.getRandomConcrete(), 0, 3);
		world.setBlock(x + 1, y + -20, z + 8, Library.getRandomConcrete(), 0, 3);
		world.setBlock(x + 2, y + -20, z + 8, Library.getRandomConcrete(), 0, 3);
		world.setBlock(x + 3, y + -20, z + 8, Library.getRandomConcrete(), 0, 3);
		world.setBlock(x + 4, y + -20, z + 8, Library.getRandomConcrete(), 0, 3);
		world.setBlock(x + 5, y + -20, z + 8, Library.getRandomConcrete(), 0, 3);
		world.setBlock(x + 6, y + -20, z + 8, Library.getRandomConcrete(), 0, 3);
		world.setBlock(x + 7, y + -20, z + 8, Blocks.air, 0, 3);
		world.setBlock(x + 8, y + -20, z + 8, Blocks.air, 0, 3);
		world.setBlock(x + 9, y + -20, z + 8, Blocks.air, 0, 3);
		world.setBlock(x + 10, y + -20, z + 8, Blocks.air, 0, 3);
		world.setBlock(x + 11, y + -20, z + 8, Blocks.air, 0, 3);
		world.setBlock(x + 12, y + -20, z + 8, Blocks.unpowered_repeater, 2, 3);
		world.setBlock(x + 13, y + -20, z + 8, Library.getRandomConcrete(), 0, 3);
		world.setBlock(x + 14, y + -20, z + 8, Library.getRandomConcrete(), 0, 3);
		world.setBlock(x + 15, y + -20, z + 8, Library.getRandomConcrete(), 0, 3);
		world.setBlock(x + 16, y + -20, z + 8, Library.getRandomConcrete(), 0, 3);
		world.setBlock(x + 17, y + -20, z + 8, Library.getRandomConcrete(), 0, 3);
		world.setBlock(x + 18, y + -20, z + 8, Library.getRandomConcrete(), 0, 3);
		world.setBlock(x + 19, y + -20, z + 8, Library.getRandomConcrete(), 0, 3);
		world.setBlock(x + 20, y + -20, z + 8, Library.getRandomConcrete(), 0, 3);
		world.setBlock(x + 0, y + -20, z + 9, Library.getRandomConcrete(), 0, 3);
		world.setBlock(x + 1, y + -20, z + 9, Blocks.air, 0, 3);
		world.setBlock(x + 2, y + -20, z + 9, Blocks.air, 0, 3);
		world.setBlock(x + 3, y + -20, z + 9, Blocks.air, 0, 3);
		world.setBlock(x + 4, y + -20, z + 9, Blocks.air, 0, 3);
		world.setBlock(x + 5, y + -20, z + 9, Blocks.iron_bars, 0, 3);
		world.setBlock(x + 6, y + -20, z + 9, Blocks.air, 0, 3);
		world.setBlock(x + 7, y + -20, z + 9, Blocks.air, 0, 3);
		world.setBlock(x + 8, y + -20, z + 9, Blocks.air, 0, 3);
		world.setBlock(x + 9, y + -20, z + 9, Blocks.air, 0, 3);
		world.setBlock(x + 10, y + -20, z + 9, Blocks.air, 0, 3);
		world.setBlock(x + 11, y + -20, z + 9, Blocks.air, 0, 3);
		world.setBlock(x + 12, y + -20, z + 9, Blocks.redstone_wire, 0, 3);
		world.setBlock(x + 13, y + -20, z + 9, Blocks.iron_bars, 0, 3);
		world.setBlock(x + 14, y + -20, z + 9, Blocks.air, 0, 3);
		world.setBlock(x + 15, y + -20, z + 9, Blocks.air, 0, 3);
		world.setBlock(x + 16, y + -20, z + 9, Blocks.air, 0, 3);
		world.setBlock(x + 17, y + -20, z + 9, Blocks.air, 0, 3);
		world.setBlock(x + 18, y + -20, z + 9, Library.getRandomConcrete(), 0, 3);
		world.setBlock(x + 19, y + -20, z + 9, Library.getRandomConcrete(), 0, 3);
		world.setBlock(x + 20, y + -20, z + 9, Library.getRandomConcrete(), 0, 3);
		world.setBlock(x + 0, y + -20, z + 10, Library.getRandomConcrete(), 0, 3);
		world.setBlock(x + 1, y + -20, z + 10, Blocks.air, 0, 3);
		world.setBlock(x + 2, y + -20, z + 10, Blocks.air, 0, 3);
		world.setBlock(x + 3, y + -20, z + 10, Blocks.air, 0, 3);
		world.setBlock(x + 4, y + -20, z + 10, Blocks.air, 0, 3);
		world.setBlock(x + 5, y + -20, z + 10, Blocks.iron_bars, 0, 3);
		world.setBlock(x + 6, y + -20, z + 10, Blocks.air, 0, 3);
		world.setBlock(x + 7, y + -20, z + 10, Blocks.air, 0, 3);
		world.setBlock(x + 8, y + -20, z + 10, Blocks.air, 0, 3);
		world.setBlock(x + 11, y + -20, z + 10, Blocks.redstone_wire, 0, 3);
		world.setBlock(x + 12, y + -20, z + 10, Blocks.redstone_wire, 0, 3);
		world.setBlock(x + 13, y + -20, z + 10, Blocks.iron_bars, 0, 3);
		world.setBlock(x + 14, y + -20, z + 10, Blocks.air, 0, 3);
		world.setBlock(x + 15, y + -20, z + 10, Blocks.air, 0, 3);
		world.setBlock(x + 16, y + -20, z + 10, Blocks.air, 0, 3);
		world.setBlock(x + 17, y + -20, z + 10, Blocks.air, 0, 3);
		world.setBlock(x + 18, y + -20, z + 10, Library.getRandomConcrete(), 0, 3);
		world.setBlock(x + 19, y + -20, z + 10, Blocks.chest, 5, 3);
		world.setBlockMetadataWithNotify(x + 19, y + -20, z + 10, 5, 3);
		if(world.getBlock(x + 19, y + -20, z + 10) == Blocks.chest)
		{
			WeightedRandomChestContent.generateChestContents(rand, ItemPool.getPool(ItemPoolsLegacy.POOL_EXPENSIVE), (TileEntityChest)world.getTileEntity(x + 19, y + -20, z + 10), rand.nextInt(2)+ 6);
		}
        world.setBlock(x + 20, y + -20, z + 10, Library.getRandomConcrete(), 0, 3);
		world.setBlock(x + 0, y + -20, z + 11, Library.getRandomConcrete(), 0, 3);
		world.setBlock(x + 1, y + -20, z + 11, Blocks.air, 0, 3);
		world.setBlock(x + 2, y + -20, z + 11, Blocks.air, 0, 3);
		world.setBlock(x + 3, y + -20, z + 11, Blocks.air, 0, 3);
		world.setBlock(x + 4, y + -20, z + 11, Blocks.air, 0, 3);
		world.setBlock(x + 5, y + -20, z + 11, Blocks.iron_bars, 0, 3);
		world.setBlock(x + 6, y + -20, z + 11, Blocks.air, 0, 3);
		world.setBlock(x + 7, y + -20, z + 11, Blocks.air, 0, 3);
		world.setBlock(x + 8, y + -20, z + 11, Blocks.air, 0, 3);
		world.setBlock(x + 9, y + -20, z + 11, Blocks.air, 0, 3);
		world.setBlock(x + 10, y + -20, z + 11, Blocks.air, 0, 3);
		world.setBlock(x + 11, y + -20, z + 11, Blocks.air, 0, 3);
		world.setBlock(x + 12, y + -20, z + 11, Blocks.air, 0, 3);
		world.setBlock(x + 13, y + -20, z + 11, Blocks.iron_bars, 0, 3);
		world.setBlock(x + 14, y + -20, z + 11, Blocks.air, 0, 3);
		world.setBlock(x + 15, y + -20, z + 11, Blocks.air, 0, 3);
		world.setBlock(x + 16, y + -20, z + 11, Blocks.air, 0, 3);
		world.setBlock(x + 17, y + -20, z + 11, Blocks.air, 0, 3);
		world.setBlock(x + 18, y + -20, z + 11, Library.getRandomConcrete(), 0, 3);
		world.setBlock(x + 19, y + -20, z + 11, Library.getRandomConcrete(), 0, 3);
		world.setBlock(x + 20, y + -20, z + 11, Library.getRandomConcrete(), 0, 3);
		world.setBlock(x + 0, y + -20, z + 12, Library.getRandomConcrete(), 0, 3);
		world.setBlock(x + 1, y + -20, z + 12, Library.getRandomConcrete(), 0, 3);
		world.setBlock(x + 2, y + -20, z + 12, Library.getRandomConcrete(), 0, 3);
		world.setBlock(x + 3, y + -20, z + 12, Library.getRandomConcrete(), 0, 3);
		world.setBlock(x + 4, y + -20, z + 12, Library.getRandomConcrete(), 0, 3);
		world.setBlock(x + 5, y + -20, z + 12, Library.getRandomConcrete(), 0, 3);
		world.setBlock(x + 6, y + -20, z + 12, Library.getRandomConcrete(), 0, 3);
		world.setBlock(x + 7, y + -20, z + 12, Blocks.air, 0, 3);
		world.setBlock(x + 8, y + -20, z + 12, Blocks.air, 0, 3);
		world.setBlock(x + 9, y + -20, z + 12, Blocks.air, 0, 3);
		world.setBlock(x + 10, y + -20, z + 12, Blocks.air, 0, 3);
		world.setBlock(x + 11, y + -20, z + 12, Blocks.air, 0, 3);
		world.setBlock(x + 12, y + -20, z + 12, Library.getRandomConcrete(), 0, 3);
		world.setBlock(x + 13, y + -20, z + 12, Library.getRandomConcrete(), 0, 3);
		world.setBlock(x + 14, y + -20, z + 12, Library.getRandomConcrete(), 0, 3);
		world.setBlock(x + 15, y + -20, z + 12, Library.getRandomConcrete(), 0, 3);
		world.setBlock(x + 16, y + -20, z + 12, Library.getRandomConcrete(), 0, 3);
		world.setBlock(x + 17, y + -20, z + 12, Library.getRandomConcrete(), 0, 3);
		world.setBlock(x + 18, y + -20, z + 12, Library.getRandomConcrete(), 0, 3);
		world.setBlock(x + 19, y + -20, z + 12, Library.getRandomConcrete(), 0, 3);
		world.setBlock(x + 20, y + -20, z + 12, Library.getRandomConcrete(), 0, 3);
		world.setBlock(x + 6, y + -20, z + 13, Library.getRandomConcrete(), 0, 3);
		world.setBlock(x + 7, y + -20, z + 13, Library.getRandomConcrete(), 0, 3);
		world.setBlock(x + 8, y + -20, z + 13, Blocks.air, 0, 3);
		world.setBlock(x + 9, y + -20, z + 13, Blocks.air, 0, 3);
		world.setBlock(x + 10, y + -20, z + 13, Blocks.air, 0, 3);
		world.setBlock(x + 11, y + -20, z + 13, Library.getRandomConcrete(), 0, 3);
		world.setBlock(x + 12, y + -20, z + 13, Library.getRandomConcrete(), 0, 3);
		world.setBlock(x + 7, y + -20, z + 14, Library.getRandomConcrete(), 0, 3);
		world.setBlock(x + 8, y + -20, z + 14, Blocks.iron_bars, 0, 3);
		world.setBlock(x + 9, y + -20, z + 14, Blocks.iron_bars, 0, 3);
		world.setBlock(x + 10, y + -20, z + 14, Blocks.iron_bars, 0, 3);
		world.setBlock(x + 11, y + -20, z + 14, Library.getRandomConcrete(), 0, 3);
		world.setBlock(x + 7, y + -20, z + 15, Library.getRandomConcrete(), 0, 3);
		world.setBlock(x + 8, y + -20, z + 15, Blocks.air, 0, 3);
		world.setBlock(x + 9, y + -20, z + 15, Blocks.air, 0, 3);
		world.setBlock(x + 10, y + -20, z + 15, Blocks.air, 0, 3);
		world.setBlock(x + 11, y + -20, z + 15, Library.getRandomConcrete(), 0, 3);
		world.setBlock(x + 7, y + -20, z + 16, Library.getRandomConcrete(), 0, 3);
		world.setBlock(x + 8, y + -20, z + 16, Blocks.air, 0, 3);
		world.setBlock(x + 9, y + -20, z + 16, Blocks.air, 0, 3);
		world.setBlock(x + 10, y + -20, z + 16, Blocks.air, 0, 3);
		world.setBlock(x + 11, y + -20, z + 16, Library.getRandomConcrete(), 0, 3);
		world.setBlock(x + 7, y + -20, z + 17, Library.getRandomConcrete(), 0, 3);
		world.setBlock(x + 8, y + -20, z + 17, Blocks.air, 0, 3);
		world.setBlock(x + 9, y + -20, z + 17, Blocks.air, 0, 3);
		world.setBlock(x + 10, y + -20, z + 17, Blocks.air, 0, 3);
		world.setBlock(x + 11, y + -20, z + 17, Library.getRandomConcrete(), 0, 3);
		world.setBlock(x + 7, y + -20, z + 18, Library.getRandomConcrete(), 0, 3);
		world.setBlock(x + 8, y + -20, z + 18, Blocks.air, 0, 3);
		world.setBlock(x + 9, y + -20, z + 18, Blocks.air, 0, 3);
		world.setBlock(x + 10, y + -20, z + 18, Blocks.air, 0, 3);
		world.setBlock(x + 11, y + -20, z + 18, Library.getRandomConcrete(), 0, 3);
		world.setBlock(x + 7, y + -20, z + 19, Library.getRandomConcrete(), 0, 3);
		world.setBlock(x + 8, y + -20, z + 19, Library.getRandomConcrete(), 0, 3);
		world.setBlock(x + 9, y + -20, z + 19, Library.getRandomConcrete(), 0, 3);
		world.setBlock(x + 10, y + -20, z + 19, Library.getRandomConcrete(), 0, 3);
		world.setBlock(x + 11, y + -20, z + 19, Library.getRandomConcrete(), 0, 3);
		world.setBlock(x + 7, y + -19, z + 1, Library.getRandomConcrete(), 0, 3);
		world.setBlock(x + 8, y + -19, z + 1, Library.getRandomConcrete(), 0, 3);
		world.setBlock(x + 9, y + -19, z + 1, Library.getRandomConcrete(), 0, 3);
		world.setBlock(x + 10, y + -19, z + 1, Library.getRandomConcrete(), 0, 3);
		world.setBlock(x + 11, y + -19, z + 1, Library.getRandomConcrete(), 0, 3);
		world.setBlock(x + 7, y + -19, z + 2, Library.getRandomConcrete(), 0, 3);
		world.setBlock(x + 8, y + -19, z + 2, Blocks.air, 0, 3);
		world.setBlock(x + 9, y + -19, z + 2, Blocks.air, 0, 3);
		world.setBlock(x + 10, y + -19, z + 2, Blocks.air, 0, 3);
		world.setBlock(x + 11, y + -19, z + 2, Library.getRandomConcrete(), 0, 3);
		world.setBlock(x + 7, y + -19, z + 3, Library.getRandomConcrete(), 0, 3);
		world.setBlock(x + 8, y + -19, z + 3, Blocks.air, 0, 3);
		world.setBlock(x + 9, y + -19, z + 3, Blocks.air, 0, 3);
		world.setBlock(x + 10, y + -19, z + 3, Blocks.air, 0, 3);
		world.setBlock(x + 11, y + -19, z + 3, Library.getRandomConcrete(), 0, 3);
		world.setBlock(x + 7, y + -19, z + 4, Library.getRandomConcrete(), 0, 3);
		world.setBlock(x + 8, y + -19, z + 4, Blocks.air, 0, 3);
		world.setBlock(x + 9, y + -19, z + 4, Blocks.air, 0, 3);
		world.setBlock(x + 10, y + -19, z + 4, Blocks.air, 0, 3);
		world.setBlock(x + 11, y + -19, z + 4, Library.getRandomConcrete(), 0, 3);
		world.setBlock(x + 12, y + -19, z + 4, Library.getRandomConcrete(), 0, 3);
		world.setBlock(x + 13, y + -19, z + 4, Library.getRandomConcrete(), 0, 3);
		world.setBlock(x + 14, y + -19, z + 4, Library.getRandomConcrete(), 0, 3);
		world.setBlock(x + 15, y + -19, z + 4, Library.getRandomConcrete(), 0, 3);
		world.setBlock(x + 7, y + -19, z + 5, Library.getRandomConcrete(), 0, 3);
		world.setBlock(x + 8, y + -19, z + 5, Blocks.air, 0, 3);
		world.setBlock(x + 9, y + -19, z + 5, Blocks.air, 0, 3);
		world.setBlock(x + 10, y + -19, z + 5, Blocks.air, 0, 3);
		world.setBlock(x + 11, y + -19, z + 5, Library.getRandomConcrete(), 0, 3);
		world.setBlock(x + 12, y + -19, z + 5, Library.getRandomConcrete(), 0, 3);
		world.setBlock(x + 14, y + -19, z + 5, Blocks.redstone_wire, 15, 3);
		world.setBlock(x + 15, y + -19, z + 5, Library.getRandomConcrete(), 0, 3);
		world.setBlock(x + 7, y + -19, z + 6, Library.getRandomConcrete(), 0, 3);
		world.setBlock(x + 8, y + -19, z + 6, Blocks.iron_bars, 0, 3);
		world.setBlock(x + 9, y + -19, z + 6, Blocks.iron_bars, 0, 3);
		world.setBlock(x + 10, y + -19, z + 6, Blocks.iron_bars, 0, 3);
		world.setBlock(x + 11, y + -19, z + 6, Library.getRandomConcrete(), 0, 3);
		world.setBlock(x + 12, y + -19, z + 6, Library.getRandomConcrete(), 0, 3);
		world.setBlock(x + 13, y + -19, z + 6, Library.getRandomConcrete(), 0, 3);
		world.setBlock(x + 14, y + -19, z + 6, Library.getRandomConcrete(), 0, 3);
		world.setBlock(x + 15, y + -19, z + 6, Library.getRandomConcrete(), 0, 3);
		world.setBlock(x + 6, y + -19, z + 7, Library.getRandomConcrete(), 0, 3);
		world.setBlock(x + 7, y + -19, z + 7, Library.getRandomConcrete(), 0, 3);
		world.setBlock(x + 9, y + -19, z + 7, Blocks.air, 0, 3);
		world.setBlock(x + 11, y + -19, z + 7, Library.getRandomConcrete(), 0, 3);
		world.setBlock(x + 12, y + -19, z + 7, Library.getRandomConcrete(), 0, 3);
		world.setBlock(x + 0, y + -19, z + 8, Library.getRandomConcrete(), 0, 3);
		world.setBlock(x + 1, y + -19, z + 8, Library.getRandomConcrete(), 0, 3);
		world.setBlock(x + 2, y + -19, z + 8, Library.getRandomConcrete(), 0, 3);
		world.setBlock(x + 3, y + -19, z + 8, Library.getRandomConcrete(), 0, 3);
		world.setBlock(x + 4, y + -19, z + 8, Library.getRandomConcrete(), 0, 3);
		world.setBlock(x + 5, y + -19, z + 8, Library.getRandomConcrete(), 0, 3);
		world.setBlock(x + 6, y + -19, z + 8, Library.getRandomConcrete(), 0, 3);
		world.setBlock(x + 7, y + -19, z + 8, Blocks.air, 0, 3);
		world.setBlock(x + 8, y + -19, z + 8, Blocks.air, 0, 3);
		world.setBlock(x + 9, y + -19, z + 8, Blocks.air, 0, 3);
		world.setBlock(x + 10, y + -19, z + 8, Blocks.air, 0, 3);
		world.setBlock(x + 11, y + -19, z + 8, Blocks.air, 0, 3);
		world.setBlock(x + 12, y + -19, z + 8, Blocks.air, 0, 3);
		world.setBlock(x + 13, y + -19, z + 8, Library.getRandomConcrete(), 0, 3);
		world.setBlock(x + 14, y + -19, z + 8, Library.getRandomConcrete(), 0, 3);
		world.setBlock(x + 15, y + -19, z + 8, Library.getRandomConcrete(), 0, 3);
		world.setBlock(x + 16, y + -19, z + 8, Library.getRandomConcrete(), 0, 3);
		world.setBlock(x + 17, y + -19, z + 8, Library.getRandomConcrete(), 0, 3);
		world.setBlock(x + 18, y + -19, z + 8, Library.getRandomConcrete(), 0, 3);
		world.setBlock(x + 19, y + -19, z + 8, Library.getRandomConcrete(), 0, 3);
		world.setBlock(x + 20, y + -19, z + 8, Library.getRandomConcrete(), 0, 3);
		world.setBlock(x + 0, y + -19, z + 9, Library.getRandomConcrete(), 0, 3);
		world.setBlock(x + 1, y + -19, z + 9, Blocks.air, 0, 3);
		world.setBlock(x + 2, y + -19, z + 9, Blocks.air, 0, 3);
		world.setBlock(x + 3, y + -19, z + 9, Blocks.air, 0, 3);
		world.setBlock(x + 4, y + -19, z + 9, Blocks.air, 0, 3);
		world.setBlock(x + 5, y + -19, z + 9, Blocks.iron_bars, 0, 3);
		world.setBlock(x + 6, y + -19, z + 9, Blocks.air, 0, 3);
		world.setBlock(x + 7, y + -19, z + 9, Blocks.air, 0, 3);
		world.setBlock(x + 8, y + -19, z + 9, Blocks.air, 0, 3);
		world.setBlock(x + 9, y + -19, z + 9, Blocks.air, 0, 3);
		world.setBlock(x + 10, y + -19, z + 9, Blocks.air, 0, 3);
		world.setBlock(x + 11, y + -19, z + 9, Blocks.air, 0, 3);
		world.setBlock(x + 12, y + -19, z + 9, Blocks.air, 0, 3);
		world.setBlock(x + 13, y + -19, z + 9, Blocks.iron_bars, 0, 3);
		world.setBlock(x + 14, y + -19, z + 9, Blocks.air, 0, 3);
		world.setBlock(x + 15, y + -19, z + 9, Blocks.air, 0, 3);
		world.setBlock(x + 16, y + -19, z + 9, Blocks.air, 0, 3);
		world.setBlock(x + 17, y + -19, z + 9, Blocks.air, 0, 3);
		world.setBlock(x + 18, y + -19, z + 9, Library.getRandomConcrete(), 0, 3);
		world.setBlock(x + 19, y + -19, z + 9, Library.getRandomConcrete(), 0, 3);
		world.setBlock(x + 20, y + -19, z + 9, Library.getRandomConcrete(), 0, 3);
		world.setBlock(x + 0, y + -19, z + 10, Library.getRandomConcrete(), 0, 3);
		world.setBlock(x + 1, y + -19, z + 10, Blocks.air, 0, 3);
		world.setBlock(x + 2, y + -19, z + 10, Blocks.air, 0, 3);
		world.setBlock(x + 3, y + -19, z + 10, Blocks.air, 0, 3);
		world.setBlock(x + 4, y + -19, z + 10, Blocks.air, 0, 3);
		world.setBlock(x + 5, y + -19, z + 10, Blocks.iron_bars, 0, 3);
		world.setBlock(x + 6, y + -19, z + 10, Blocks.air, 0, 3);
		world.setBlock(x + 7, y + -19, z + 10, Blocks.air, 0, 3);
		world.setBlock(x + 8, y + -19, z + 10, Blocks.air, 0, 3);
		world.setBlock(x + 9, y + -19, z + 10, Blocks.air, 0, 3);
		world.setBlock(x + 10, y + -19, z + 10, Blocks.air, 0, 3);
		world.setBlock(x + 11, y + -19, z + 10, Blocks.air, 0, 3);
		world.setBlock(x + 12, y + -19, z + 10, Blocks.air, 0, 3);
		world.setBlock(x + 13, y + -19, z + 10, Blocks.iron_bars, 0, 3);
		world.setBlock(x + 14, y + -19, z + 10, Blocks.air, 0, 3);
		world.setBlock(x + 15, y + -19, z + 10, Blocks.air, 0, 3);
		world.setBlock(x + 16, y + -19, z + 10, Blocks.air, 0, 3);
		world.setBlock(x + 17, y + -19, z + 10, Blocks.air, 0, 3);
		world.setBlock(x + 18, y + -19, z + 10, Library.getRandomConcrete(), 0, 3);
		world.setBlock(x + 19, y + -19, z + 10, Library.getRandomConcrete(), 0, 3);
		world.setBlock(x + 20, y + -19, z + 10, Library.getRandomConcrete(), 0, 3);
		world.setBlock(x + 0, y + -19, z + 11, Library.getRandomConcrete(), 0, 3);
		world.setBlock(x + 1, y + -19, z + 11, Blocks.air, 0, 3);
		world.setBlock(x + 2, y + -19, z + 11, Blocks.air, 0, 3);
		world.setBlock(x + 3, y + -19, z + 11, Blocks.air, 0, 3);
		world.setBlock(x + 4, y + -19, z + 11, Blocks.air, 0, 3);
		world.setBlock(x + 5, y + -19, z + 11, Blocks.iron_bars, 0, 3);
		world.setBlock(x + 6, y + -19, z + 11, Blocks.air, 0, 3);
		world.setBlock(x + 7, y + -19, z + 11, Blocks.air, 0, 3);
		world.setBlock(x + 8, y + -19, z + 11, Blocks.air, 0, 3);
		world.setBlock(x + 9, y + -19, z + 11, Blocks.air, 0, 3);
		world.setBlock(x + 10, y + -19, z + 11, Blocks.air, 0, 3);
		world.setBlock(x + 11, y + -19, z + 11, Blocks.air, 0, 3);
		world.setBlock(x + 12, y + -19, z + 11, Blocks.air, 0, 3);
		world.setBlock(x + 13, y + -19, z + 11, Blocks.iron_bars, 0, 3);
		world.setBlock(x + 14, y + -19, z + 11, Blocks.air, 0, 3);
		world.setBlock(x + 15, y + -19, z + 11, Blocks.air, 0, 3);
		world.setBlock(x + 16, y + -19, z + 11, Blocks.air, 0, 3);
		world.setBlock(x + 17, y + -19, z + 11, Blocks.air, 0, 3);
		world.setBlock(x + 18, y + -19, z + 11, Library.getRandomConcrete(), 0, 3);
		world.setBlock(x + 19, y + -19, z + 11, Library.getRandomConcrete(), 0, 3);
		world.setBlock(x + 20, y + -19, z + 11, Library.getRandomConcrete(), 0, 3);
		world.setBlock(x + 0, y + -19, z + 12, Library.getRandomConcrete(), 0, 3);
		world.setBlock(x + 1, y + -19, z + 12, Library.getRandomConcrete(), 0, 3);
		world.setBlock(x + 2, y + -19, z + 12, Library.getRandomConcrete(), 0, 3);
		world.setBlock(x + 3, y + -19, z + 12, Library.getRandomConcrete(), 0, 3);
		world.setBlock(x + 4, y + -19, z + 12, Library.getRandomConcrete(), 0, 3);
		world.setBlock(x + 5, y + -19, z + 12, Library.getRandomConcrete(), 0, 3);
		world.setBlock(x + 6, y + -19, z + 12, Library.getRandomConcrete(), 0, 3);
		world.setBlock(x + 7, y + -19, z + 12, Blocks.air, 0, 3);
		world.setBlock(x + 8, y + -19, z + 12, Blocks.air, 0, 3);
		world.setBlock(x + 9, y + -19, z + 12, Blocks.air, 0, 3);
		world.setBlock(x + 10, y + -19, z + 12, Blocks.air, 0, 3);
		world.setBlock(x + 11, y + -19, z + 12, Blocks.air, 0, 3);
		world.setBlock(x + 12, y + -19, z + 12, Library.getRandomConcrete(), 0, 3);
		world.setBlock(x + 13, y + -19, z + 12, Library.getRandomConcrete(), 0, 3);
		world.setBlock(x + 14, y + -19, z + 12, Library.getRandomConcrete(), 0, 3);
		world.setBlock(x + 15, y + -19, z + 12, Library.getRandomConcrete(), 0, 3);
		world.setBlock(x + 16, y + -19, z + 12, Library.getRandomConcrete(), 0, 3);
		world.setBlock(x + 17, y + -19, z + 12, Library.getRandomConcrete(), 0, 3);
		world.setBlock(x + 18, y + -19, z + 12, Library.getRandomConcrete(), 0, 3);
		world.setBlock(x + 19, y + -19, z + 12, Library.getRandomConcrete(), 0, 3);
		world.setBlock(x + 20, y + -19, z + 12, Library.getRandomConcrete(), 0, 3);
		world.setBlock(x + 6, y + -19, z + 13, Library.getRandomConcrete(), 0, 3);
		world.setBlock(x + 7, y + -19, z + 13, Library.getRandomConcrete(), 0, 3);
		world.setBlock(x + 8, y + -19, z + 13, Blocks.air, 0, 3);
		world.setBlock(x + 9, y + -19, z + 13, Blocks.air, 0, 3);
		world.setBlock(x + 10, y + -19, z + 13, Blocks.air, 0, 3);
		world.setBlock(x + 11, y + -19, z + 13, Library.getRandomConcrete(), 0, 3);
		world.setBlock(x + 12, y + -19, z + 13, Library.getRandomConcrete(), 0, 3);
		world.setBlock(x + 7, y + -19, z + 14, Library.getRandomConcrete(), 0, 3);
		world.setBlock(x + 8, y + -19, z + 14, Blocks.iron_bars, 0, 3);
		world.setBlock(x + 9, y + -19, z + 14, Blocks.iron_bars, 0, 3);
		world.setBlock(x + 10, y + -19, z + 14, Blocks.iron_bars, 0, 3);
		world.setBlock(x + 11, y + -19, z + 14, Library.getRandomConcrete(), 0, 3);
		world.setBlock(x + 7, y + -19, z + 15, Library.getRandomConcrete(), 0, 3);
		world.setBlock(x + 8, y + -19, z + 15, Blocks.air, 0, 3);
		world.setBlock(x + 9, y + -19, z + 15, Blocks.air, 0, 3);
		world.setBlock(x + 10, y + -19, z + 15, Blocks.air, 0, 3);
		world.setBlock(x + 11, y + -19, z + 15, Library.getRandomConcrete(), 0, 3);
		world.setBlock(x + 7, y + -19, z + 16, Library.getRandomConcrete(), 0, 3);
		world.setBlock(x + 8, y + -19, z + 16, Blocks.air, 0, 3);
		world.setBlock(x + 9, y + -19, z + 16, Blocks.air, 0, 3);
		world.setBlock(x + 10, y + -19, z + 16, Blocks.air, 0, 3);
		world.setBlock(x + 11, y + -19, z + 16, Library.getRandomConcrete(), 0, 3);
		world.setBlock(x + 7, y + -19, z + 17, Library.getRandomConcrete(), 0, 3);
		world.setBlock(x + 8, y + -19, z + 17, Blocks.air, 0, 3);
		world.setBlock(x + 9, y + -19, z + 17, Blocks.air, 0, 3);
		world.setBlock(x + 10, y + -19, z + 17, Blocks.air, 0, 3);
		world.setBlock(x + 11, y + -19, z + 17, Library.getRandomConcrete(), 0, 3);
		world.setBlock(x + 7, y + -19, z + 18, Library.getRandomConcrete(), 0, 3);
		world.setBlock(x + 8, y + -19, z + 18, Blocks.air, 0, 3);
		world.setBlock(x + 9, y + -19, z + 18, Blocks.air, 0, 3);
		world.setBlock(x + 10, y + -19, z + 18, Blocks.air, 0, 3);
		world.setBlock(x + 11, y + -19, z + 18, Library.getRandomConcrete(), 0, 3);
		world.setBlock(x + 7, y + -19, z + 19, Library.getRandomConcrete(), 0, 3);
		world.setBlock(x + 8, y + -19, z + 19, Library.getRandomConcrete(), 0, 3);
		world.setBlock(x + 9, y + -19, z + 19, Library.getRandomConcrete(), 0, 3);
		world.setBlock(x + 10, y + -19, z + 19, Library.getRandomConcrete(), 0, 3);
		world.setBlock(x + 11, y + -19, z + 19, Library.getRandomConcrete(), 0, 3);
		world.setBlock(x + 7, y + -18, z + 1, Library.getRandomConcrete(), 0, 3);
		world.setBlock(x + 8, y + -18, z + 1, Library.getRandomConcrete(), 0, 3);
		world.setBlock(x + 9, y + -18, z + 1, Library.getRandomConcrete(), 0, 3);
		world.setBlock(x + 10, y + -18, z + 1, Library.getRandomConcrete(), 0, 3);
		world.setBlock(x + 11, y + -18, z + 1, Library.getRandomConcrete(), 0, 3);
		world.setBlock(x + 7, y + -18, z + 2, Library.getRandomConcrete(), 0, 3);
		world.setBlock(x + 8, y + -18, z + 2, Library.getRandomConcrete(), 0, 3);
		world.setBlock(x + 9, y + -18, z + 2, Library.getRandomConcrete(), 0, 3);
		world.setBlock(x + 10, y + -18, z + 2, Library.getRandomConcrete(), 0, 3);
		world.setBlock(x + 11, y + -18, z + 2, Library.getRandomConcrete(), 0, 3);
		world.setBlock(x + 7, y + -18, z + 3, Library.getRandomConcrete(), 0, 3);
		world.setBlock(x + 8, y + -18, z + 3, Library.getRandomConcrete(), 0, 3);
		world.setBlock(x + 9, y + -18, z + 3, Library.getRandomConcrete(), 0, 3);
		world.setBlock(x + 10, y + -18, z + 3, Library.getRandomConcrete(), 0, 3);
		world.setBlock(x + 11, y + -18, z + 3, Library.getRandomConcrete(), 0, 3);
		world.setBlock(x + 7, y + -18, z + 4, Library.getRandomConcrete(), 0, 3);
		world.setBlock(x + 8, y + -18, z + 4, Library.getRandomConcrete(), 0, 3);
		world.setBlock(x + 9, y + -18, z + 4, Library.getRandomConcrete(), 0, 3);
		world.setBlock(x + 10, y + -18, z + 4, Library.getRandomConcrete(), 0, 3);
		world.setBlock(x + 11, y + -18, z + 4, Library.getRandomConcrete(), 0, 3);
		world.setBlock(x + 12, y + -18, z + 4, Library.getRandomConcrete(), 0, 3);
		world.setBlock(x + 13, y + -18, z + 4, Library.getRandomConcrete(), 0, 3);
		world.setBlock(x + 14, y + -18, z + 4, Library.getRandomConcrete(), 0, 3);
		world.setBlock(x + 15, y + -18, z + 4, Library.getRandomConcrete(), 0, 3);
		world.setBlock(x + 7, y + -18, z + 5, Library.getRandomConcrete(), 0, 3);
		world.setBlock(x + 8, y + -18, z + 5, Library.getRandomConcrete(), 0, 3);
		world.setBlock(x + 9, y + -18, z + 5, Library.getRandomConcrete(), 0, 3);
		world.setBlock(x + 10, y + -18, z + 5, Library.getRandomConcrete(), 0, 3);
		world.setBlock(x + 11, y + -18, z + 5, Library.getRandomConcrete(), 0, 3);
		world.setBlock(x + 12, y + -18, z + 5, Blocks.redstone_wire, 0, 3);
		world.setBlock(x + 14, y + -18, z + 5, Library.getRandomConcrete(), 0, 3);
		world.setBlock(x + 15, y + -18, z + 5, Library.getRandomConcrete(), 0, 3);
		world.setBlock(x + 7, y + -18, z + 6, Library.getRandomConcrete(), 0, 3);
		world.setBlock(x + 8, y + -18, z + 6, Library.getRandomConcrete(), 0, 3);
		world.setBlock(x + 9, y + -18, z + 6, Library.getRandomConcrete(), 0, 3);
		world.setBlock(x + 10, y + -18, z + 6, Library.getRandomConcrete(), 0, 3);
		world.setBlock(x + 11, y + -18, z + 6, Library.getRandomConcrete(), 0, 3);
		world.setBlock(x + 12, y + -18, z + 6, Library.getRandomConcrete(), 0, 3);
		world.setBlock(x + 13, y + -18, z + 6, Library.getRandomConcrete(), 0, 3);
		world.setBlock(x + 14, y + -18, z + 6, Library.getRandomConcrete(), 0, 3);
		world.setBlock(x + 15, y + -18, z + 6, Library.getRandomConcrete(), 0, 3);
		world.setBlock(x + 6, y + -18, z + 7, Library.getRandomConcrete(), 0, 3);
		world.setBlock(x + 7, y + -18, z + 7, Library.getRandomConcrete(), 0, 3);
		world.setBlock(x + 9, y + -18, z + 7, Blocks.air, 0, 3);
		world.setBlock(x + 11, y + -18, z + 7, Library.getRandomConcrete(), 0, 3);
		world.setBlock(x + 12, y + -18, z + 7, Library.getRandomConcrete(), 0, 3);
		world.setBlock(x + 0, y + -18, z + 8, Library.getRandomConcrete(), 0, 3);
		world.setBlock(x + 1, y + -18, z + 8, Library.getRandomConcrete(), 0, 3);
		world.setBlock(x + 2, y + -18, z + 8, Library.getRandomConcrete(), 0, 3);
		world.setBlock(x + 3, y + -18, z + 8, Library.getRandomConcrete(), 0, 3);
		world.setBlock(x + 4, y + -18, z + 8, Library.getRandomConcrete(), 0, 3);
		world.setBlock(x + 5, y + -18, z + 8, Library.getRandomConcrete(), 0, 3);
		world.setBlock(x + 6, y + -18, z + 8, Library.getRandomConcrete(), 0, 3);
		world.setBlock(x + 7, y + -18, z + 8, Blocks.air, 0, 3);
		world.setBlock(x + 8, y + -18, z + 8, Blocks.air, 0, 3);
		world.setBlock(x + 9, y + -18, z + 8, Blocks.air, 0, 3);
		world.setBlock(x + 10, y + -18, z + 8, Blocks.air, 0, 3);
		world.setBlock(x + 11, y + -18, z + 8, Blocks.air, 0, 3);
		world.setBlock(x + 12, y + -18, z + 8, Library.getRandomConcrete(), 0, 3);
		world.setBlock(x + 13, y + -18, z + 8, Library.getRandomConcrete(), 0, 3);
		world.setBlock(x + 14, y + -18, z + 8, Library.getRandomConcrete(), 0, 3);
		world.setBlock(x + 15, y + -18, z + 8, Library.getRandomConcrete(), 0, 3);
		world.setBlock(x + 16, y + -18, z + 8, Library.getRandomConcrete(), 0, 3);
		world.setBlock(x + 17, y + -18, z + 8, Library.getRandomConcrete(), 0, 3);
		world.setBlock(x + 18, y + -18, z + 8, Library.getRandomConcrete(), 0, 3);
		world.setBlock(x + 19, y + -18, z + 8, Library.getRandomConcrete(), 0, 3);
		world.setBlock(x + 20, y + -18, z + 8, Library.getRandomConcrete(), 0, 3);
		world.setBlock(x + 0, y + -18, z + 9, Library.getRandomConcrete(), 0, 3);
		world.setBlock(x + 1, y + -18, z + 9, Library.getRandomConcrete(), 0, 3);
		world.setBlock(x + 2, y + -18, z + 9, Library.getRandomConcrete(), 0, 3);
		world.setBlock(x + 3, y + -18, z + 9, Library.getRandomConcrete(), 0, 3);
		world.setBlock(x + 4, y + -18, z + 9, Library.getRandomConcrete(), 0, 3);
		world.setBlock(x + 5, y + -18, z + 9, Library.getRandomConcrete(), 0, 3);
		world.setBlock(x + 6, y + -18, z + 9, Blocks.air, 0, 3);
		world.setBlock(x + 7, y + -18, z + 9, Blocks.air, 0, 3);
		world.setBlock(x + 8, y + -18, z + 9, Blocks.air, 0, 3);
		world.setBlock(x + 9, y + -18, z + 9, Blocks.air, 0, 3);
		world.setBlock(x + 10, y + -18, z + 9, Blocks.air, 0, 3);
		world.setBlock(x + 11, y + -18, z + 9, Blocks.air, 0, 3);
		world.setBlock(x + 12, y + -18, z + 9, Blocks.air, 0, 3);
		world.setBlock(x + 13, y + -18, z + 9, Library.getRandomConcrete(), 0, 3);
		world.setBlock(x + 14, y + -18, z + 9, Library.getRandomConcrete(), 0, 3);
		world.setBlock(x + 15, y + -18, z + 9, Library.getRandomConcrete(), 0, 3);
		world.setBlock(x + 16, y + -18, z + 9, Library.getRandomConcrete(), 0, 3);
		world.setBlock(x + 17, y + -18, z + 9, Library.getRandomConcrete(), 0, 3);
		world.setBlock(x + 18, y + -18, z + 9, Library.getRandomConcrete(), 0, 3);
		world.setBlock(x + 19, y + -18, z + 9, Library.getRandomConcrete(), 0, 3);
		world.setBlock(x + 20, y + -18, z + 9, Library.getRandomConcrete(), 0, 3);
		world.setBlock(x + 0, y + -18, z + 10, Library.getRandomConcrete(), 0, 3);
		world.setBlock(x + 1, y + -18, z + 10, Library.getRandomConcrete(), 0, 3);
		world.setBlock(x + 2, y + -18, z + 10, Library.getRandomConcrete(), 0, 3);
		world.setBlock(x + 3, y + -18, z + 10, Library.getRandomConcrete(), 0, 3);
		world.setBlock(x + 4, y + -18, z + 10, Library.getRandomConcrete(), 0, 3);
		world.setBlock(x + 5, y + -18, z + 10, Library.getRandomConcrete(), 0, 3);
		world.setBlock(x + 6, y + -18, z + 10, Blocks.air, 0, 3);
		world.setBlock(x + 7, y + -18, z + 10, Blocks.air, 0, 3);
		world.setBlock(x + 8, y + -18, z + 10, Blocks.air, 0, 3);
		world.setBlock(x + 9, y + -18, z + 10, Blocks.air, 0, 3);
		world.setBlock(x + 10, y + -18, z + 10, Blocks.air, 0, 3);
		world.setBlock(x + 11, y + -18, z + 10, Blocks.air, 0, 3);
		world.setBlock(x + 12, y + -18, z + 10, Blocks.air, 0, 3);
		world.setBlock(x + 13, y + -18, z + 10, Library.getRandomConcrete(), 0, 3);
		world.setBlock(x + 14, y + -18, z + 10, Library.getRandomConcrete(), 0, 3);
		world.setBlock(x + 15, y + -18, z + 10, Library.getRandomConcrete(), 0, 3);
		world.setBlock(x + 16, y + -18, z + 10, Library.getRandomConcrete(), 0, 3);
		world.setBlock(x + 17, y + -18, z + 10, Library.getRandomConcrete(), 0, 3);
		world.setBlock(x + 18, y + -18, z + 10, Library.getRandomConcrete(), 0, 3);
		world.setBlock(x + 19, y + -18, z + 10, Library.getRandomConcrete(), 0, 3);
		world.setBlock(x + 20, y + -18, z + 10, Library.getRandomConcrete(), 0, 3);
		world.setBlock(x + 0, y + -18, z + 11, Library.getRandomConcrete(), 0, 3);
		world.setBlock(x + 1, y + -18, z + 11, Library.getRandomConcrete(), 0, 3);
		world.setBlock(x + 2, y + -18, z + 11, Library.getRandomConcrete(), 0, 3);
		world.setBlock(x + 3, y + -18, z + 11, Library.getRandomConcrete(), 0, 3);
		world.setBlock(x + 4, y + -18, z + 11, Library.getRandomConcrete(), 0, 3);
		world.setBlock(x + 5, y + -18, z + 11, Library.getRandomConcrete(), 0, 3);
		world.setBlock(x + 6, y + -18, z + 11, Blocks.air, 0, 3);
		world.setBlock(x + 7, y + -18, z + 11, Blocks.air, 0, 3);
		world.setBlock(x + 8, y + -18, z + 11, Blocks.air, 0, 3);
		world.setBlock(x + 9, y + -18, z + 11, Blocks.air, 0, 3);
		world.setBlock(x + 10, y + -18, z + 11, Blocks.air, 0, 3);
		world.setBlock(x + 11, y + -18, z + 11, Blocks.air, 0, 3);
		world.setBlock(x + 12, y + -18, z + 11, Blocks.air, 0, 3);
		world.setBlock(x + 13, y + -18, z + 11, Library.getRandomConcrete(), 0, 3);
		world.setBlock(x + 14, y + -18, z + 11, Library.getRandomConcrete(), 0, 3);
		world.setBlock(x + 15, y + -18, z + 11, Library.getRandomConcrete(), 0, 3);
		world.setBlock(x + 16, y + -18, z + 11, Library.getRandomConcrete(), 0, 3);
		world.setBlock(x + 17, y + -18, z + 11, Library.getRandomConcrete(), 0, 3);
		world.setBlock(x + 18, y + -18, z + 11, Library.getRandomConcrete(), 0, 3);
		world.setBlock(x + 19, y + -18, z + 11, Library.getRandomConcrete(), 0, 3);
		world.setBlock(x + 20, y + -18, z + 11, Library.getRandomConcrete(), 0, 3);
		world.setBlock(x + 0, y + -18, z + 12, Library.getRandomConcrete(), 0, 3);
		world.setBlock(x + 1, y + -18, z + 12, Library.getRandomConcrete(), 0, 3);
		world.setBlock(x + 2, y + -18, z + 12, Library.getRandomConcrete(), 0, 3);
		world.setBlock(x + 3, y + -18, z + 12, Library.getRandomConcrete(), 0, 3);
		world.setBlock(x + 4, y + -18, z + 12, Library.getRandomConcrete(), 0, 3);
		world.setBlock(x + 5, y + -18, z + 12, Library.getRandomConcrete(), 0, 3);
		world.setBlock(x + 6, y + -18, z + 12, Library.getRandomConcrete(), 0, 3);
		world.setBlock(x + 7, y + -18, z + 12, Blocks.air, 0, 3);
		world.setBlock(x + 8, y + -18, z + 12, Blocks.air, 0, 3);
		world.setBlock(x + 9, y + -18, z + 12, Blocks.air, 0, 3);
		world.setBlock(x + 10, y + -18, z + 12, Blocks.air, 0, 3);
		world.setBlock(x + 11, y + -18, z + 12, Blocks.air, 0, 3);
		world.setBlock(x + 12, y + -18, z + 12, Library.getRandomConcrete(), 0, 3);
		world.setBlock(x + 13, y + -18, z + 12, Library.getRandomConcrete(), 0, 3);
		world.setBlock(x + 14, y + -18, z + 12, Library.getRandomConcrete(), 0, 3);
		world.setBlock(x + 15, y + -18, z + 12, Library.getRandomConcrete(), 0, 3);
		world.setBlock(x + 16, y + -18, z + 12, Library.getRandomConcrete(), 0, 3);
		world.setBlock(x + 17, y + -18, z + 12, Library.getRandomConcrete(), 0, 3);
		world.setBlock(x + 18, y + -18, z + 12, Library.getRandomConcrete(), 0, 3);
		world.setBlock(x + 19, y + -18, z + 12, Library.getRandomConcrete(), 0, 3);
		world.setBlock(x + 20, y + -18, z + 12, Library.getRandomConcrete(), 0, 3);
		world.setBlock(x + 6, y + -18, z + 13, Library.getRandomConcrete(), 0, 3);
		world.setBlock(x + 7, y + -18, z + 13, Library.getRandomConcrete(), 0, 3);
		world.setBlock(x + 8, y + -18, z + 13, Blocks.air, 0, 3);
		world.setBlock(x + 9, y + -18, z + 13, Blocks.air, 0, 3);
		world.setBlock(x + 10, y + -18, z + 13, Blocks.air, 0, 3);
		world.setBlock(x + 11, y + -18, z + 13, Library.getRandomConcrete(), 0, 3);
		world.setBlock(x + 12, y + -18, z + 13, Library.getRandomConcrete(), 0, 3);
		world.setBlock(x + 7, y + -18, z + 14, Library.getRandomConcrete(), 0, 3);
		world.setBlock(x + 8, y + -18, z + 14, Library.getRandomConcrete(), 0, 3);
		world.setBlock(x + 9, y + -18, z + 14, Library.getRandomConcrete(), 0, 3);
		world.setBlock(x + 10, y + -18, z + 14, Library.getRandomConcrete(), 0, 3);
		world.setBlock(x + 11, y + -18, z + 14, Library.getRandomConcrete(), 0, 3);
		world.setBlock(x + 7, y + -18, z + 15, Library.getRandomConcrete(), 0, 3);
		world.setBlock(x + 8, y + -18, z + 15, Library.getRandomConcrete(), 0, 3);
		world.setBlock(x + 9, y + -18, z + 15, Library.getRandomConcrete(), 0, 3);
		world.setBlock(x + 10, y + -18, z + 15, Library.getRandomConcrete(), 0, 3);
		world.setBlock(x + 11, y + -18, z + 15, Library.getRandomConcrete(), 0, 3);
		world.setBlock(x + 7, y + -18, z + 16, Library.getRandomConcrete(), 0, 3);
		world.setBlock(x + 8, y + -18, z + 16, Library.getRandomConcrete(), 0, 3);
		world.setBlock(x + 9, y + -18, z + 16, Library.getRandomConcrete(), 0, 3);
		world.setBlock(x + 10, y + -18, z + 16, Library.getRandomConcrete(), 0, 3);
		world.setBlock(x + 11, y + -18, z + 16, Library.getRandomConcrete(), 0, 3);
		world.setBlock(x + 7, y + -18, z + 17, Library.getRandomConcrete(), 0, 3);
		world.setBlock(x + 8, y + -18, z + 17, Library.getRandomConcrete(), 0, 3);
		world.setBlock(x + 9, y + -18, z + 17, Library.getRandomConcrete(), 0, 3);
		world.setBlock(x + 10, y + -18, z + 17, Library.getRandomConcrete(), 0, 3);
		world.setBlock(x + 11, y + -18, z + 17, Library.getRandomConcrete(), 0, 3);
		world.setBlock(x + 7, y + -18, z + 18, Library.getRandomConcrete(), 0, 3);
		world.setBlock(x + 8, y + -18, z + 18, Library.getRandomConcrete(), 0, 3);
		world.setBlock(x + 9, y + -18, z + 18, Library.getRandomConcrete(), 0, 3);
		world.setBlock(x + 10, y + -18, z + 18, Library.getRandomConcrete(), 0, 3);
		world.setBlock(x + 11, y + -18, z + 18, Library.getRandomConcrete(), 0, 3);
		world.setBlock(x + 7, y + -18, z + 19, Library.getRandomConcrete(), 0, 3);
		world.setBlock(x + 8, y + -18, z + 19, Library.getRandomConcrete(), 0, 3);
		world.setBlock(x + 9, y + -18, z + 19, Library.getRandomConcrete(), 0, 3);
		world.setBlock(x + 10, y + -18, z + 19, Library.getRandomConcrete(), 0, 3);
		world.setBlock(x + 11, y + -18, z + 19, Library.getRandomConcrete(), 0, 3);
		world.setBlock(x + 7, y + -17, z + 1, Library.getRandomConcrete(), 0, 3);
		world.setBlock(x + 8, y + -17, z + 1, Library.getRandomConcrete(), 0, 3);
		world.setBlock(x + 9, y + -17, z + 1, Library.getRandomConcrete(), 0, 3);
		world.setBlock(x + 10, y + -17, z + 1, Library.getRandomConcrete(), 0, 3);
		world.setBlock(x + 11, y + -17, z + 1, Library.getRandomConcrete(), 0, 3);
		world.setBlock(x + 7, y + -17, z + 2, Library.getRandomConcrete(), 0, 3);
		world.setBlock(x + 8, y + -17, z + 2, Blocks.chest, 3, 3);
		world.setBlockMetadataWithNotify(x + 8, y + -17, z + 2, 3, 3);
		if(world.getBlock(x + 8, y + -17, z + 2) == Blocks.chest)
		{
			WeightedRandomChestContent.generateChestContents(rand, ItemPool.getPool(ItemPoolsComponent.POOL_SILO), (TileEntityChest)world.getTileEntity(x + 8, y + -17, z + 2), rand.nextInt(2)+ 6);
		}
        world.setBlock(x + 10, y + -17, z + 2, Blocks.air, 0, 3);
		world.setBlock(x + 11, y + -17, z + 2, Library.getRandomConcrete(), 0, 3);
		world.setBlock(x + 7, y + -17, z + 3, Library.getRandomConcrete(), 0, 3);
		world.setBlock(x + 8, y + -17, z + 3, Blocks.air, 0, 3);
		world.setBlock(x + 9, y + -17, z + 3, Blocks.air, 0, 3);
		world.setBlock(x + 10, y + -17, z + 3, Blocks.air, 0, 3);
		world.setBlock(x + 11, y + -17, z + 3, Library.getRandomConcrete(), 0, 3);
		world.setBlock(x + 7, y + -17, z + 4, Library.getRandomConcrete(), 0, 3);
		world.setBlock(x + 8, y + -17, z + 4, Blocks.air, 0, 3);
		world.setBlock(x + 9, y + -17, z + 4, Blocks.air, 0, 3);
		world.setBlock(x + 10, y + -17, z + 4, Blocks.air, 0, 3);
		world.setBlock(x + 11, y + -17, z + 4, Library.getRandomConcrete(), 0, 3);
		world.setBlock(x + 12, y + -17, z + 4, Library.getRandomConcrete(), 0, 3);
		world.setBlock(x + 13, y + -17, z + 4, Library.getRandomConcrete(), 0, 3);
		world.setBlock(x + 14, y + -17, z + 4, Library.getRandomConcrete(), 0, 3);
		world.setBlock(x + 15, y + -17, z + 4, Library.getRandomConcrete(), 0, 3);
		world.setBlock(x + 7, y + -17, z + 5, Library.getRandomConcrete(), 0, 3);
		world.setBlock(x + 8, y + -17, z + 5, Blocks.air, 0, 3);
		world.setBlock(x + 9, y + -17, z + 5, Blocks.air, 0, 3);
		world.setBlock(x + 10, y + -17, z + 5, Blocks.air, 0, 3);
		world.setBlock(x + 11, y + -17, z + 5, Library.getRandomConcrete(), 0, 3);
		world.setBlock(x + 12, y + -17, z + 5, Library.getRandomConcrete(), 0, 3);
		world.setBlock(x + 14, y + -17, z + 5, Blocks.redstone_wire, 15, 3);
		world.setBlock(x + 15, y + -17, z + 5, Library.getRandomConcrete(), 0, 3);
		world.setBlock(x + 7, y + -17, z + 6, Library.getRandomConcrete(), 0, 3);
		world.setBlock(x + 8, y + -17, z + 6, Blocks.air, 0, 3);
		world.setBlock(x + 9, y + -17, z + 6, Blocks.air, 0, 3);
		world.setBlock(x + 10, y + -17, z + 6, Blocks.air, 0, 3);
		world.setBlock(x + 11, y + -17, z + 6, Library.getRandomConcrete(), 0, 3);
		world.setBlock(x + 12, y + -17, z + 6, Library.getRandomConcrete(), 0, 3);
		world.setBlock(x + 13, y + -17, z + 6, Library.getRandomConcrete(), 0, 3);
		world.setBlock(x + 14, y + -17, z + 6, Library.getRandomConcrete(), 0, 3);
		world.setBlock(x + 15, y + -17, z + 6, Library.getRandomConcrete(), 0, 3);
		world.setBlock(x + 6, y + -17, z + 7, Library.getRandomConcrete(), 0, 3);
		world.setBlock(x + 7, y + -17, z + 7, Library.getRandomConcrete(), 0, 3);
		world.setBlock(x + 9, y + -17, z + 7, Blocks.air, 0, 3);
		world.setBlock(x + 11, y + -17, z + 7, Library.getRandomConcrete(), 0, 3);
		world.setBlock(x + 12, y + -17, z + 7, Library.getRandomConcrete(), 0, 3);
		world.setBlock(x + 6, y + -17, z + 8, Library.getRandomConcrete(), 0, 3);
		world.setBlock(x + 7, y + -17, z + 8, Blocks.air, 0, 3);
		world.setBlock(x + 8, y + -17, z + 8, Blocks.air, 0, 3);
		world.setBlock(x + 9, y + -17, z + 8, Blocks.air, 0, 3);
		world.setBlock(x + 10, y + -17, z + 8, Blocks.air, 0, 3);
		world.setBlock(x + 11, y + -17, z + 8, Blocks.air, 0, 3);
		world.setBlock(x + 12, y + -17, z + 8, Library.getRandomConcrete(), 0, 3);
		world.setBlock(x + 5, y + -17, z + 9, Library.getRandomConcrete(), 0, 3);
		world.setBlock(x + 6, y + -17, z + 9, Blocks.air, 0, 3);
		world.setBlock(x + 7, y + -17, z + 9, Blocks.air, 0, 3);
		world.setBlock(x + 8, y + -17, z + 9, Blocks.air, 0, 3);
		world.setBlock(x + 9, y + -17, z + 9, Blocks.air, 0, 3);
		world.setBlock(x + 10, y + -17, z + 9, Blocks.air, 0, 3);
		world.setBlock(x + 11, y + -17, z + 9, Blocks.air, 0, 3);
		world.setBlock(x + 12, y + -17, z + 9, Blocks.air, 0, 3);
		world.setBlock(x + 13, y + -17, z + 9, Library.getRandomConcrete(), 0, 3);
		world.setBlock(x + 5, y + -17, z + 10, Library.getRandomConcrete(), 0, 3);
		world.setBlock(x + 6, y + -17, z + 10, Blocks.air, 0, 3);
		world.setBlock(x + 7, y + -17, z + 10, Blocks.air, 0, 3);
		world.setBlock(x + 8, y + -17, z + 10, Blocks.air, 0, 3);
		world.setBlock(x + 9, y + -17, z + 10, Blocks.air, 0, 3);
		world.setBlock(x + 10, y + -17, z + 10, Blocks.air, 0, 3);
		world.setBlock(x + 11, y + -17, z + 10, Blocks.air, 0, 3);
		world.setBlock(x + 12, y + -17, z + 10, Blocks.air, 0, 3);
		world.setBlock(x + 13, y + -17, z + 10, Library.getRandomConcrete(), 0, 3);
		world.setBlock(x + 5, y + -17, z + 11, Library.getRandomConcrete(), 0, 3);
		world.setBlock(x + 6, y + -17, z + 11, Blocks.air, 0, 3);
		world.setBlock(x + 7, y + -17, z + 11, Blocks.air, 0, 3);
		world.setBlock(x + 8, y + -17, z + 11, Blocks.air, 0, 3);
		world.setBlock(x + 9, y + -17, z + 11, Blocks.air, 0, 3);
		world.setBlock(x + 10, y + -17, z + 11, Blocks.air, 0, 3);
		world.setBlock(x + 11, y + -17, z + 11, Blocks.air, 0, 3);
		world.setBlock(x + 12, y + -17, z + 11, Blocks.air, 0, 3);
		world.setBlock(x + 13, y + -17, z + 11, Library.getRandomConcrete(), 0, 3);
		world.setBlock(x + 6, y + -17, z + 12, Library.getRandomConcrete(), 0, 3);
		world.setBlock(x + 7, y + -17, z + 12, Blocks.air, 0, 3);
		world.setBlock(x + 8, y + -17, z + 12, Blocks.air, 0, 3);
		world.setBlock(x + 9, y + -17, z + 12, Blocks.air, 0, 3);
		world.setBlock(x + 10, y + -17, z + 12, Blocks.air, 0, 3);
		world.setBlock(x + 11, y + -17, z + 12, Blocks.air, 0, 3);
		world.setBlock(x + 12, y + -17, z + 12, Library.getRandomConcrete(), 0, 3);
		world.setBlock(x + 6, y + -17, z + 13, Library.getRandomConcrete(), 0, 3);
		world.setBlock(x + 7, y + -17, z + 13, Library.getRandomConcrete(), 0, 3);
		world.setBlock(x + 8, y + -17, z + 13, Blocks.air, 0, 3);
		world.setBlock(x + 9, y + -17, z + 13, Blocks.air, 0, 3);
		world.setBlock(x + 10, y + -17, z + 13, Blocks.air, 0, 3);
		world.setBlock(x + 11, y + -17, z + 13, Library.getRandomConcrete(), 0, 3);
		world.setBlock(x + 12, y + -17, z + 13, Library.getRandomConcrete(), 0, 3);
		world.setBlock(x + 8, y + -17, z + 14, Library.getRandomConcrete(), 0, 3);
		world.setBlock(x + 9, y + -17, z + 14, Library.getRandomConcrete(), 0, 3);
		world.setBlock(x + 10, y + -17, z + 14, Library.getRandomConcrete(), 0, 3);
		world.setBlock(x + 7, y + -16, z + 1, Library.getRandomConcrete(), 0, 3);
		world.setBlock(x + 8, y + -16, z + 1, Library.getRandomConcrete(), 0, 3);
		world.setBlock(x + 9, y + -16, z + 1, Library.getRandomConcrete(), 0, 3);
		world.setBlock(x + 10, y + -16, z + 1, Library.getRandomConcrete(), 0, 3);
		world.setBlock(x + 11, y + -16, z + 1, Library.getRandomConcrete(), 0, 3);
		world.setBlock(x + 7, y + -16, z + 2, Library.getRandomConcrete(), 0, 3);
		world.setBlock(x + 8, y + -16, z + 2, Blocks.air, 0, 3);
		world.setBlock(x + 10, y + -16, z + 2, Blocks.air, 0, 3);
		world.setBlock(x + 11, y + -16, z + 2, Library.getRandomConcrete(), 0, 3);
		world.setBlock(x + 7, y + -16, z + 3, Library.getRandomConcrete(), 0, 3);
		world.setBlock(x + 8, y + -16, z + 3, Blocks.air, 0, 3);
		world.setBlock(x + 9, y + -16, z + 3, Blocks.air, 0, 3);
		world.setBlock(x + 10, y + -16, z + 3, Blocks.air, 0, 3);
		world.setBlock(x + 11, y + -16, z + 3, Library.getRandomConcrete(), 0, 3);
		world.setBlock(x + 7, y + -16, z + 4, Block3, 0, 3);
		world.setBlock(x + 8, y + -16, z + 4, Blocks.air, 0, 3);
		world.setBlock(x + 9, y + -16, z + 4, Blocks.air, 0, 3);
		world.setBlock(x + 10, y + -16, z + 4, Blocks.air, 0, 3);
		world.setBlock(x + 11, y + -16, z + 4, Block3, 0, 3);
		world.setBlock(x + 12, y + -16, z + 4, Library.getRandomConcrete(), 0, 3);
		world.setBlock(x + 13, y + -16, z + 4, Library.getRandomConcrete(), 0, 3);
		world.setBlock(x + 14, y + -16, z + 4, Library.getRandomConcrete(), 0, 3);
		world.setBlock(x + 15, y + -16, z + 4, Library.getRandomConcrete(), 0, 3);
		world.setBlock(x + 7, y + -16, z + 5, Library.getRandomConcrete(), 0, 3);
		world.setBlock(x + 8, y + -16, z + 5, Blocks.air, 0, 3);
		world.setBlock(x + 9, y + -16, z + 5, Blocks.air, 0, 3);
		world.setBlock(x + 10, y + -16, z + 5, Blocks.air, 0, 3);
		world.setBlock(x + 11, y + -16, z + 5, Library.getRandomConcrete(), 0, 3);
		world.setBlock(x + 12, y + -16, z + 5, Blocks.redstone_wire, 0, 3);
		world.setBlock(x + 14, y + -16, z + 5, Library.getRandomConcrete(), 0, 3);
		world.setBlock(x + 15, y + -16, z + 5, Library.getRandomConcrete(), 0, 3);
		world.setBlock(x + 7, y + -16, z + 6, Library.getRandomConcrete(), 0, 3);
		world.setBlock(x + 8, y + -16, z + 6, Blocks.air, 0, 3);
		world.setBlock(x + 9, y + -16, z + 6, Blocks.air, 0, 3);
		world.setBlock(x + 10, y + -16, z + 6, Blocks.air, 0, 3);
		world.setBlock(x + 11, y + -16, z + 6, Library.getRandomConcrete(), 0, 3);
		world.setBlock(x + 12, y + -16, z + 6, Library.getRandomConcrete(), 0, 3);
		world.setBlock(x + 13, y + -16, z + 6, Library.getRandomConcrete(), 0, 3);
		world.setBlock(x + 14, y + -16, z + 6, Library.getRandomConcrete(), 0, 3);
		world.setBlock(x + 15, y + -16, z + 6, Library.getRandomConcrete(), 0, 3);
		world.setBlock(x + 6, y + -16, z + 7, Library.getRandomConcrete(), 0, 3);
		world.setBlock(x + 7, y + -16, z + 7, Library.getRandomConcrete(), 0, 3);
		world.setBlock(x + 8, y + -16, z + 7, Blocks.air, 0, 3);
		world.setBlock(x + 9, y + -16, z + 7, Blocks.air, 0, 3);
		world.setBlock(x + 10, y + -16, z + 7, Blocks.air, 0, 3);
		world.setBlock(x + 11, y + -16, z + 7, Library.getRandomConcrete(), 0, 3);
		world.setBlock(x + 12, y + -16, z + 7, Library.getRandomConcrete(), 0, 3);
		world.setBlock(x + 6, y + -16, z + 8, Library.getRandomConcrete(), 0, 3);
		world.setBlock(x + 7, y + -16, z + 8, Blocks.air, 0, 3);
		world.setBlock(x + 8, y + -16, z + 8, Blocks.air, 0, 3);
		world.setBlock(x + 9, y + -16, z + 8, Blocks.air, 0, 3);
		world.setBlock(x + 10, y + -16, z + 8, Blocks.air, 0, 3);
		world.setBlock(x + 11, y + -16, z + 8, Blocks.air, 0, 3);
		world.setBlock(x + 12, y + -16, z + 8, Library.getRandomConcrete(), 0, 3);
		world.setBlock(x + 5, y + -16, z + 9, Library.getRandomConcrete(), 0, 3);
		world.setBlock(x + 6, y + -16, z + 9, Blocks.air, 0, 3);
		world.setBlock(x + 7, y + -16, z + 9, Blocks.air, 0, 3);
		world.setBlock(x + 8, y + -16, z + 9, Blocks.air, 0, 3);
		world.setBlock(x + 9, y + -16, z + 9, Blocks.air, 0, 3);
		world.setBlock(x + 10, y + -16, z + 9, Blocks.air, 0, 3);
		world.setBlock(x + 11, y + -16, z + 9, Blocks.air, 0, 3);
		world.setBlock(x + 12, y + -16, z + 9, Blocks.air, 0, 3);
		world.setBlock(x + 13, y + -16, z + 9, Library.getRandomConcrete(), 0, 3);
		world.setBlock(x + 5, y + -16, z + 10, Library.getRandomConcrete(), 0, 3);
		world.setBlock(x + 6, y + -16, z + 10, Blocks.air, 0, 3);
		world.setBlock(x + 7, y + -16, z + 10, Blocks.air, 0, 3);
		world.setBlock(x + 8, y + -16, z + 10, Blocks.air, 0, 3);
		world.setBlock(x + 9, y + -16, z + 10, Blocks.air, 0, 3);
		world.setBlock(x + 10, y + -16, z + 10, Blocks.air, 0, 3);
		world.setBlock(x + 11, y + -16, z + 10, Blocks.air, 0, 3);
		world.setBlock(x + 12, y + -16, z + 10, Blocks.air, 0, 3);
		world.setBlock(x + 13, y + -16, z + 10, Library.getRandomConcrete(), 0, 3);
		world.setBlock(x + 5, y + -16, z + 11, Library.getRandomConcrete(), 0, 3);
		world.setBlock(x + 6, y + -16, z + 11, Blocks.air, 0, 3);
		world.setBlock(x + 7, y + -16, z + 11, Blocks.air, 0, 3);
		world.setBlock(x + 8, y + -16, z + 11, Blocks.air, 0, 3);
		world.setBlock(x + 9, y + -16, z + 11, Blocks.air, 0, 3);
		world.setBlock(x + 10, y + -16, z + 11, Blocks.air, 0, 3);
		world.setBlock(x + 11, y + -16, z + 11, Blocks.air, 0, 3);
		world.setBlock(x + 12, y + -16, z + 11, Blocks.air, 0, 3);
		world.setBlock(x + 13, y + -16, z + 11, Library.getRandomConcrete(), 0, 3);
		world.setBlock(x + 6, y + -16, z + 12, Library.getRandomConcrete(), 0, 3);
		world.setBlock(x + 7, y + -16, z + 12, Blocks.air, 0, 3);
		world.setBlock(x + 8, y + -16, z + 12, Blocks.air, 0, 3);
		world.setBlock(x + 9, y + -16, z + 12, Blocks.air, 0, 3);
		world.setBlock(x + 10, y + -16, z + 12, Blocks.air, 0, 3);
		world.setBlock(x + 11, y + -16, z + 12, Blocks.air, 0, 3);
		world.setBlock(x + 12, y + -16, z + 12, Library.getRandomConcrete(), 0, 3);
		world.setBlock(x + 6, y + -16, z + 13, Library.getRandomConcrete(), 0, 3);
		world.setBlock(x + 7, y + -16, z + 13, Library.getRandomConcrete(), 0, 3);
		world.setBlock(x + 8, y + -16, z + 13, Blocks.air, 0, 3);
		world.setBlock(x + 9, y + -16, z + 13, Blocks.air, 0, 3);
		world.setBlock(x + 10, y + -16, z + 13, Blocks.air, 0, 3);
		world.setBlock(x + 11, y + -16, z + 13, Library.getRandomConcrete(), 0, 3);
		world.setBlock(x + 12, y + -16, z + 13, Library.getRandomConcrete(), 0, 3);
		world.setBlock(x + 8, y + -16, z + 14, Library.getRandomConcrete(), 0, 3);
		world.setBlock(x + 9, y + -16, z + 14, Library.getRandomConcrete(), 0, 3);
		world.setBlock(x + 10, y + -16, z + 14, Library.getRandomConcrete(), 0, 3);
		world.setBlock(x + 7, y + -15, z + 1, Library.getRandomConcrete(), 0, 3);
		world.setBlock(x + 8, y + -15, z + 1, Library.getRandomConcrete(), 0, 3);
		world.setBlock(x + 9, y + -15, z + 1, Block3, 0, 3);
		world.setBlock(x + 10, y + -15, z + 1, Library.getRandomConcrete(), 0, 3);
		world.setBlock(x + 11, y + -15, z + 1, Library.getRandomConcrete(), 0, 3);
		world.setBlock(x + 7, y + -15, z + 2, Library.getRandomConcrete(), 0, 3);
		world.setBlock(x + 8, y + -15, z + 2, Blocks.air, 0, 3);
		world.setBlock(x + 10, y + -15, z + 2, Blocks.air, 0, 3);
		world.setBlock(x + 11, y + -15, z + 2, Library.getRandomConcrete(), 0, 3);
		world.setBlock(x + 7, y + -15, z + 3, Library.getRandomConcrete(), 0, 3);
		world.setBlock(x + 8, y + -15, z + 3, Blocks.air, 0, 3);
		world.setBlock(x + 9, y + -15, z + 3, Blocks.air, 0, 3);
		world.setBlock(x + 10, y + -15, z + 3, Blocks.air, 0, 3);
		world.setBlock(x + 11, y + -15, z + 3, Library.getRandomConcrete(), 0, 3);
		world.setBlock(x + 7, y + -15, z + 4, Library.getRandomConcrete(), 0, 3);
		world.setBlock(x + 8, y + -15, z + 4, Blocks.air, 0, 3);
		world.setBlock(x + 9, y + -15, z + 4, Blocks.air, 0, 3);
		world.setBlock(x + 10, y + -15, z + 4, Blocks.air, 0, 3);
		world.setBlock(x + 11, y + -15, z + 4, Library.getRandomConcrete(), 0, 3);
		world.setBlock(x + 12, y + -15, z + 4, Library.getRandomConcrete(), 0, 3);
		world.setBlock(x + 13, y + -15, z + 4, Library.getRandomConcrete(), 0, 3);
		world.setBlock(x + 14, y + -15, z + 4, Library.getRandomConcrete(), 0, 3);
		world.setBlock(x + 15, y + -15, z + 4, Library.getRandomConcrete(), 0, 3);
		world.setBlock(x + 7, y + -15, z + 5, Library.getRandomConcrete(), 0, 3);
		world.setBlock(x + 8, y + -15, z + 5, Blocks.air, 0, 3);
		world.setBlock(x + 9, y + -15, z + 5, Blocks.air, 0, 3);
		world.setBlock(x + 10, y + -15, z + 5, Blocks.air, 0, 3);
		world.setBlock(x + 11, y + -15, z + 5, Library.getRandomConcrete(), 0, 3);
		world.setBlock(x + 12, y + -15, z + 5, Library.getRandomConcrete(), 0, 3);
		world.setBlock(x + 14, y + -15, z + 5, Blocks.redstone_wire, 15, 3);
		world.setBlock(x + 15, y + -15, z + 5, Library.getRandomConcrete(), 0, 3);
		world.setBlock(x + 7, y + -15, z + 6, Library.getRandomConcrete(), 0, 3);
		world.setBlock(x + 8, y + -15, z + 6, Blocks.air, 0, 3);
		world.setBlock(x + 9, y + -15, z + 6, Blocks.air, 0, 3);
		world.setBlock(x + 10, y + -15, z + 6, Blocks.air, 0, 3);
		world.setBlock(x + 11, y + -15, z + 6, Library.getRandomConcrete(), 0, 3);
		world.setBlock(x + 12, y + -15, z + 6, Library.getRandomConcrete(), 0, 3);
		world.setBlock(x + 13, y + -15, z + 6, Library.getRandomConcrete(), 0, 3);
		world.setBlock(x + 14, y + -15, z + 6, Library.getRandomConcrete(), 0, 3);
		world.setBlock(x + 15, y + -15, z + 6, Library.getRandomConcrete(), 0, 3);
		world.setBlock(x + 6, y + -15, z + 7, Library.getRandomConcrete(), 0, 3);
		world.setBlock(x + 7, y + -15, z + 7, Library.getRandomConcrete(), 0, 3);
		world.setBlock(x + 8, y + -15, z + 7, Blocks.air, 0, 3);
		world.setBlock(x + 9, y + -15, z + 7, Blocks.air, 0, 3);
		world.setBlock(x + 10, y + -15, z + 7, Blocks.air, 0, 3);
		world.setBlock(x + 11, y + -15, z + 7, Library.getRandomConcrete(), 0, 3);
		world.setBlock(x + 12, y + -15, z + 7, Library.getRandomConcrete(), 0, 3);
		world.setBlock(x + 6, y + -15, z + 8, Library.getRandomConcrete(), 0, 3);
		world.setBlock(x + 7, y + -15, z + 8, Blocks.air, 0, 3);
		world.setBlock(x + 8, y + -15, z + 8, Blocks.air, 0, 3);
		world.setBlock(x + 9, y + -15, z + 8, Blocks.air, 0, 3);
		world.setBlock(x + 10, y + -15, z + 8, Blocks.air, 0, 3);
		world.setBlock(x + 11, y + -15, z + 8, Blocks.air, 0, 3);
		world.setBlock(x + 12, y + -15, z + 8, Library.getRandomConcrete(), 0, 3);
		world.setBlock(x + 5, y + -15, z + 9, Library.getRandomConcrete(), 0, 3);
		world.setBlock(x + 6, y + -15, z + 9, Blocks.air, 0, 3);
		world.setBlock(x + 7, y + -15, z + 9, Blocks.air, 0, 3);
		world.setBlock(x + 8, y + -15, z + 9, Blocks.air, 0, 3);
		world.setBlock(x + 9, y + -15, z + 9, Blocks.air, 0, 3);
		world.setBlock(x + 10, y + -15, z + 9, Blocks.air, 0, 3);
		world.setBlock(x + 11, y + -15, z + 9, Blocks.air, 0, 3);
		world.setBlock(x + 12, y + -15, z + 9, Blocks.air, 0, 3);
		world.setBlock(x + 13, y + -15, z + 9, Library.getRandomConcrete(), 0, 3);
		world.setBlock(x + 5, y + -15, z + 10, Library.getRandomConcrete(), 0, 3);
		world.setBlock(x + 6, y + -15, z + 10, Blocks.air, 0, 3);
		world.setBlock(x + 7, y + -15, z + 10, Blocks.air, 0, 3);
		world.setBlock(x + 8, y + -15, z + 10, Blocks.air, 0, 3);
		world.setBlock(x + 9, y + -15, z + 10, Blocks.air, 0, 3);
		world.setBlock(x + 10, y + -15, z + 10, Blocks.air, 0, 3);
		world.setBlock(x + 11, y + -15, z + 10, Blocks.air, 0, 3);
		world.setBlock(x + 12, y + -15, z + 10, Blocks.air, 0, 3);
		world.setBlock(x + 13, y + -15, z + 10, Library.getRandomConcrete(), 0, 3);
		world.setBlock(x + 5, y + -15, z + 11, Library.getRandomConcrete(), 0, 3);
		world.setBlock(x + 6, y + -15, z + 11, Blocks.air, 0, 3);
		world.setBlock(x + 7, y + -15, z + 11, Blocks.air, 0, 3);
		world.setBlock(x + 8, y + -15, z + 11, Blocks.air, 0, 3);
		world.setBlock(x + 9, y + -15, z + 11, Blocks.air, 0, 3);
		world.setBlock(x + 10, y + -15, z + 11, Blocks.air, 0, 3);
		world.setBlock(x + 11, y + -15, z + 11, Blocks.air, 0, 3);
		world.setBlock(x + 12, y + -15, z + 11, Blocks.air, 0, 3);
		world.setBlock(x + 13, y + -15, z + 11, Library.getRandomConcrete(), 0, 3);
		world.setBlock(x + 6, y + -15, z + 12, Library.getRandomConcrete(), 0, 3);
		world.setBlock(x + 7, y + -15, z + 12, Blocks.air, 0, 3);
		world.setBlock(x + 8, y + -15, z + 12, Blocks.air, 0, 3);
		world.setBlock(x + 9, y + -15, z + 12, Blocks.air, 0, 3);
		world.setBlock(x + 10, y + -15, z + 12, Blocks.air, 0, 3);
		world.setBlock(x + 11, y + -15, z + 12, Blocks.air, 0, 3);
		world.setBlock(x + 12, y + -15, z + 12, Library.getRandomConcrete(), 0, 3);
		world.setBlock(x + 6, y + -15, z + 13, Library.getRandomConcrete(), 0, 3);
		world.setBlock(x + 7, y + -15, z + 13, Library.getRandomConcrete(), 0, 3);
		world.setBlock(x + 8, y + -15, z + 13, Blocks.air, 0, 3);
		world.setBlock(x + 9, y + -15, z + 13, Blocks.air, 0, 3);
		world.setBlock(x + 10, y + -15, z + 13, Blocks.air, 0, 3);
		world.setBlock(x + 11, y + -15, z + 13, Library.getRandomConcrete(), 0, 3);
		world.setBlock(x + 12, y + -15, z + 13, Library.getRandomConcrete(), 0, 3);
		world.setBlock(x + 8, y + -15, z + 14, Library.getRandomConcrete(), 0, 3);
		world.setBlock(x + 9, y + -15, z + 14, Library.getRandomConcrete(), 0, 3);
		world.setBlock(x + 10, y + -15, z + 14, Library.getRandomConcrete(), 0, 3);
		world.setBlock(x + 7, y + -14, z + 1, Library.getRandomConcrete(), 0, 3);
		world.setBlock(x + 8, y + -14, z + 1, Library.getRandomConcrete(), 0, 3);
		world.setBlock(x + 9, y + -14, z + 1, Library.getRandomConcrete(), 0, 3);
		world.setBlock(x + 10, y + -14, z + 1, Library.getRandomConcrete(), 0, 3);
		world.setBlock(x + 11, y + -14, z + 1, Library.getRandomConcrete(), 0, 3);
		world.setBlock(x + 7, y + -14, z + 2, Library.getRandomConcrete(), 0, 3);
		world.setBlock(x + 8, y + -14, z + 2, Library.getRandomConcrete(), 0, 3);
		world.setBlock(x + 10, y + -14, z + 2, Library.getRandomConcrete(), 0, 3);
		world.setBlock(x + 11, y + -14, z + 2, Library.getRandomConcrete(), 0, 3);
		world.setBlock(x + 7, y + -14, z + 3, Library.getRandomConcrete(), 0, 3);
		world.setBlock(x + 8, y + -14, z + 3, Library.getRandomConcrete(), 0, 3);
		world.setBlock(x + 9, y + -14, z + 3, Library.getRandomConcrete(), 0, 3);
		world.setBlock(x + 10, y + -14, z + 3, Library.getRandomConcrete(), 0, 3);
		world.setBlock(x + 11, y + -14, z + 3, Library.getRandomConcrete(), 0, 3);
		world.setBlock(x + 7, y + -14, z + 4, Library.getRandomConcrete(), 0, 3);
		world.setBlock(x + 8, y + -14, z + 4, Library.getRandomConcrete(), 0, 3);
		world.setBlock(x + 9, y + -14, z + 4, Library.getRandomConcrete(), 0, 3);
		world.setBlock(x + 10, y + -14, z + 4, Library.getRandomConcrete(), 0, 3);
		world.setBlock(x + 11, y + -14, z + 4, Library.getRandomConcrete(), 0, 3);
		world.setBlock(x + 12, y + -14, z + 4, Library.getRandomConcrete(), 0, 3);
		world.setBlock(x + 13, y + -14, z + 4, Library.getRandomConcrete(), 0, 3);
		world.setBlock(x + 14, y + -14, z + 4, Library.getRandomConcrete(), 0, 3);
		world.setBlock(x + 15, y + -14, z + 4, Library.getRandomConcrete(), 0, 3);
		world.setBlock(x + 7, y + -14, z + 5, Library.getRandomConcrete(), 0, 3);
		world.setBlock(x + 8, y + -14, z + 5, Library.getRandomConcrete(), 0, 3);
		world.setBlock(x + 9, y + -14, z + 5, Library.getRandomConcrete(), 0, 3);
		world.setBlock(x + 10, y + -14, z + 5, Library.getRandomConcrete(), 0, 3);
		world.setBlock(x + 11, y + -14, z + 5, Blocks.redstone_wire, 0, 3);
		world.setBlock(x + 12, y + -14, z + 5, Blocks.redstone_wire, 0, 3);
		world.setBlock(x + 13, y + -14, z + 5, Blocks.stone_slab, 8, 3);
		world.setBlock(x + 14, y + -14, z + 5, Library.getRandomConcrete(), 0, 3);
		world.setBlock(x + 15, y + -14, z + 5, Library.getRandomConcrete(), 0, 3);
		world.setBlock(x + 7, y + -14, z + 6, Library.getRandomConcrete(), 0, 3);
		world.setBlock(x + 8, y + -14, z + 6, Library.getRandomConcrete(), 0, 3);
		world.setBlock(x + 9, y + -14, z + 6, Library.getRandomConcrete(), 0, 3);
		world.setBlock(x + 10, y + -14, z + 6, Library.getRandomConcrete(), 0, 3);
		world.setBlock(x + 11, y + -14, z + 6, Library.getRandomConcrete(), 0, 3);
		world.setBlock(x + 12, y + -14, z + 6, Library.getRandomConcrete(), 0, 3);
		world.setBlock(x + 13, y + -14, z + 6, Library.getRandomConcrete(), 0, 3);
		world.setBlock(x + 14, y + -14, z + 6, Library.getRandomConcrete(), 0, 3);
		world.setBlock(x + 15, y + -14, z + 6, Library.getRandomConcrete(), 0, 3);
		world.setBlock(x + 6, y + -14, z + 7, Library.getRandomConcrete(), 0, 3);
		world.setBlock(x + 7, y + -14, z + 7, Library.getRandomConcrete(), 0, 3);
		world.setBlock(x + 8, y + -14, z + 7, Blocks.air, 0, 3);
		world.setBlock(x + 9, y + -14, z + 7, Blocks.air, 0, 3);
		world.setBlock(x + 10, y + -14, z + 7, Blocks.air, 0, 3);
		world.setBlock(x + 11, y + -14, z + 7, Library.getRandomConcrete(), 0, 3);
		world.setBlock(x + 12, y + -14, z + 7, Library.getRandomConcrete(), 0, 3);
		world.setBlock(x + 6, y + -14, z + 8, Library.getRandomConcrete(), 0, 3);
		world.setBlock(x + 7, y + -14, z + 8, Blocks.air, 0, 3);
		world.setBlock(x + 8, y + -14, z + 8, Blocks.air, 0, 3);
		world.setBlock(x + 9, y + -14, z + 8, Blocks.air, 0, 3);
		world.setBlock(x + 10, y + -14, z + 8, Blocks.air, 0, 3);
		world.setBlock(x + 11, y + -14, z + 8, Blocks.air, 0, 3);
		world.setBlock(x + 12, y + -14, z + 8, Library.getRandomConcrete(), 0, 3);
		world.setBlock(x + 5, y + -14, z + 9, Library.getRandomConcrete(), 0, 3);
		world.setBlock(x + 6, y + -14, z + 9, Blocks.air, 0, 3);
		world.setBlock(x + 7, y + -14, z + 9, Blocks.air, 0, 3);
		world.setBlock(x + 8, y + -14, z + 9, Blocks.air, 0, 3);
		world.setBlock(x + 9, y + -14, z + 9, Blocks.air, 0, 3);
		world.setBlock(x + 10, y + -14, z + 9, Blocks.air, 0, 3);
		world.setBlock(x + 11, y + -14, z + 9, Blocks.air, 0, 3);
		world.setBlock(x + 12, y + -14, z + 9, Blocks.air, 0, 3);
		world.setBlock(x + 13, y + -14, z + 9, Library.getRandomConcrete(), 0, 3);
		world.setBlock(x + 5, y + -14, z + 10, Library.getRandomConcrete(), 0, 3);
		world.setBlock(x + 6, y + -14, z + 10, Blocks.air, 0, 3);
		world.setBlock(x + 7, y + -14, z + 10, Blocks.air, 0, 3);
		world.setBlock(x + 8, y + -14, z + 10, Blocks.air, 0, 3);
		world.setBlock(x + 9, y + -14, z + 10, Blocks.air, 0, 3);
		world.setBlock(x + 10, y + -14, z + 10, Blocks.air, 0, 3);
		world.setBlock(x + 11, y + -14, z + 10, Blocks.air, 0, 3);
		world.setBlock(x + 12, y + -14, z + 10, Blocks.air, 0, 3);
		world.setBlock(x + 13, y + -14, z + 10, Library.getRandomConcrete(), 0, 3);
		world.setBlock(x + 5, y + -14, z + 11, Library.getRandomConcrete(), 0, 3);
		world.setBlock(x + 6, y + -14, z + 11, Blocks.air, 0, 3);
		world.setBlock(x + 7, y + -14, z + 11, Blocks.air, 0, 3);
		world.setBlock(x + 8, y + -14, z + 11, Blocks.air, 0, 3);
		world.setBlock(x + 9, y + -14, z + 11, Blocks.air, 0, 3);
		world.setBlock(x + 10, y + -14, z + 11, Blocks.air, 0, 3);
		world.setBlock(x + 11, y + -14, z + 11, Blocks.air, 0, 3);
		world.setBlock(x + 12, y + -14, z + 11, Blocks.air, 0, 3);
		world.setBlock(x + 13, y + -14, z + 11, Library.getRandomConcrete(), 0, 3);
		world.setBlock(x + 6, y + -14, z + 12, Library.getRandomConcrete(), 0, 3);
		world.setBlock(x + 7, y + -14, z + 12, Blocks.air, 0, 3);
		world.setBlock(x + 8, y + -14, z + 12, Blocks.air, 0, 3);
		world.setBlock(x + 9, y + -14, z + 12, Blocks.air, 0, 3);
		world.setBlock(x + 10, y + -14, z + 12, Blocks.air, 0, 3);
		world.setBlock(x + 11, y + -14, z + 12, Blocks.air, 0, 3);
		world.setBlock(x + 12, y + -14, z + 12, Library.getRandomConcrete(), 0, 3);
		world.setBlock(x + 6, y + -14, z + 13, Library.getRandomConcrete(), 0, 3);
		world.setBlock(x + 7, y + -14, z + 13, Library.getRandomConcrete(), 0, 3);
		world.setBlock(x + 8, y + -14, z + 13, Blocks.air, 0, 3);
		world.setBlock(x + 9, y + -14, z + 13, Blocks.air, 0, 3);
		world.setBlock(x + 10, y + -14, z + 13, Blocks.air, 0, 3);
		world.setBlock(x + 11, y + -14, z + 13, Library.getRandomConcrete(), 0, 3);
		world.setBlock(x + 12, y + -14, z + 13, Library.getRandomConcrete(), 0, 3);
		world.setBlock(x + 8, y + -14, z + 14, Library.getRandomConcrete(), 0, 3);
		world.setBlock(x + 9, y + -14, z + 14, Library.getRandomConcrete(), 0, 3);
		world.setBlock(x + 10, y + -14, z + 14, Library.getRandomConcrete(), 0, 3);
		world.setBlock(x + 7, y + -13, z + 1, Library.getRandomConcrete(), 0, 3);
		world.setBlock(x + 8, y + -13, z + 1, Library.getRandomConcrete(), 0, 3);
		world.setBlock(x + 9, y + -13, z + 1, Library.getRandomConcrete(), 0, 3);
		world.setBlock(x + 10, y + -13, z + 1, Library.getRandomConcrete(), 0, 3);
		world.setBlock(x + 11, y + -13, z + 1, Library.getRandomConcrete(), 0, 3);
		world.setBlock(x + 7, y + -13, z + 2, Library.getRandomConcrete(), 0, 3);
		world.setBlock(x + 8, y + -13, z + 2, Library.getRandomConcrete(), 0, 3);
		world.setBlock(x + 10, y + -13, z + 2, Library.getRandomConcrete(), 0, 3);
		world.setBlock(x + 11, y + -13, z + 2, Library.getRandomConcrete(), 0, 3);
		world.setBlock(x + 7, y + -13, z + 3, Library.getRandomConcrete(), 0, 3);
		world.setBlock(x + 8, y + -13, z + 3, Library.getRandomConcrete(), 0, 3);
		world.setBlock(x + 9, y + -13, z + 3, Library.getRandomConcrete(), 0, 3);
		world.setBlock(x + 10, y + -13, z + 3, Library.getRandomConcrete(), 0, 3);
		world.setBlock(x + 11, y + -13, z + 3, Library.getRandomConcrete(), 0, 3);
		world.setBlock(x + 7, y + -13, z + 4, Library.getRandomConcrete(), 0, 3);
		world.setBlock(x + 8, y + -13, z + 4, Library.getRandomConcrete(), 0, 3);
		world.setBlock(x + 9, y + -13, z + 4, Library.getRandomConcrete(), 0, 3);
		world.setBlock(x + 10, y + -13, z + 4, Library.getRandomConcrete(), 0, 3);
		world.setBlock(x + 11, y + -13, z + 4, Library.getRandomConcrete(), 0, 3);
		world.setBlock(x + 12, y + -13, z + 4, Library.getRandomConcrete(), 0, 3);
		world.setBlock(x + 13, y + -13, z + 4, Library.getRandomConcrete(), 0, 3);
		world.setBlock(x + 14, y + -13, z + 4, Library.getRandomConcrete(), 0, 3);
		world.setBlock(x + 15, y + -13, z + 4, Library.getRandomConcrete(), 0, 3);
		world.setBlock(x + 7, y + -13, z + 5, Library.getRandomConcrete(), 0, 3);
		world.setBlock(x + 8, y + -13, z + 5, Library.getRandomConcrete(), 0, 3);
		world.setBlock(x + 10, y + -13, z + 5, Blocks.redstone_wire, 0, 3);
		world.setBlock(x + 11, y + -13, z + 5, Blocks.stone_slab, 8, 3);
		world.setBlock(x + 12, y + -13, z + 5, Library.getRandomConcrete(), 0, 3);
		world.setBlock(x + 13, y + -13, z + 5, Library.getRandomConcrete(), 0, 3);
		world.setBlock(x + 14, y + -13, z + 5, Library.getRandomConcrete(), 0, 3);
		world.setBlock(x + 15, y + -13, z + 5, Library.getRandomConcrete(), 0, 3);
		world.setBlock(x + 7, y + -13, z + 6, Library.getRandomConcrete(), 0, 3);
		world.setBlock(x + 8, y + -13, z + 6, Library.getRandomConcrete(), 0, 3);
		world.setBlock(x + 9, y + -13, z + 6, Library.getRandomConcrete(), 0, 3);
		world.setBlock(x + 10, y + -13, z + 6, Library.getRandomConcrete(), 0, 3);
		world.setBlock(x + 11, y + -13, z + 6, Library.getRandomConcrete(), 0, 3);
		world.setBlock(x + 12, y + -13, z + 6, Library.getRandomConcrete(), 0, 3);
		world.setBlock(x + 13, y + -13, z + 6, Library.getRandomConcrete(), 0, 3);
		world.setBlock(x + 14, y + -13, z + 6, Library.getRandomConcrete(), 0, 3);
		world.setBlock(x + 15, y + -13, z + 6, Library.getRandomConcrete(), 0, 3);
		world.setBlock(x + 6, y + -13, z + 7, Library.getRandomConcrete(), 0, 3);
		world.setBlock(x + 7, y + -13, z + 7, Library.getRandomConcrete(), 0, 3);
		world.setBlock(x + 8, y + -13, z + 7, Blocks.air, 0, 3);
		world.setBlock(x + 9, y + -13, z + 7, Blocks.air, 0, 3);
		world.setBlock(x + 10, y + -13, z + 7, Blocks.air, 0, 3);
		world.setBlock(x + 11, y + -13, z + 7, Library.getRandomConcrete(), 0, 3);
		world.setBlock(x + 12, y + -13, z + 7, Library.getRandomConcrete(), 0, 3);
		world.setBlock(x + 6, y + -13, z + 8, Library.getRandomConcrete(), 0, 3);
		world.setBlock(x + 7, y + -13, z + 8, Blocks.air, 0, 3);
		world.setBlock(x + 8, y + -13, z + 8, Blocks.air, 0, 3);
		world.setBlock(x + 9, y + -13, z + 8, Blocks.air, 0, 3);
		world.setBlock(x + 10, y + -13, z + 8, Blocks.air, 0, 3);
		world.setBlock(x + 11, y + -13, z + 8, Blocks.air, 0, 3);
		world.setBlock(x + 12, y + -13, z + 8, Library.getRandomConcrete(), 0, 3);
		world.setBlock(x + 5, y + -13, z + 9, Library.getRandomConcrete(), 0, 3);
		world.setBlock(x + 6, y + -13, z + 9, Blocks.air, 0, 3);
		world.setBlock(x + 7, y + -13, z + 9, Blocks.air, 0, 3);
		world.setBlock(x + 8, y + -13, z + 9, Blocks.air, 0, 3);
		world.setBlock(x + 9, y + -13, z + 9, Blocks.air, 0, 3);
		world.setBlock(x + 10, y + -13, z + 9, Blocks.air, 0, 3);
		world.setBlock(x + 11, y + -13, z + 9, Blocks.air, 0, 3);
		world.setBlock(x + 12, y + -13, z + 9, Blocks.air, 0, 3);
		world.setBlock(x + 13, y + -13, z + 9, Library.getRandomConcrete(), 0, 3);
		world.setBlock(x + 5, y + -13, z + 10, Library.getRandomConcrete(), 0, 3);
		world.setBlock(x + 6, y + -13, z + 10, Blocks.air, 0, 3);
		world.setBlock(x + 7, y + -13, z + 10, Blocks.air, 0, 3);
		world.setBlock(x + 8, y + -13, z + 10, Blocks.air, 0, 3);
		world.setBlock(x + 9, y + -13, z + 10, Blocks.air, 0, 3);
		world.setBlock(x + 10, y + -13, z + 10, Blocks.air, 0, 3);
		world.setBlock(x + 11, y + -13, z + 10, Blocks.air, 0, 3);
		world.setBlock(x + 12, y + -13, z + 10, Blocks.air, 0, 3);
		world.setBlock(x + 13, y + -13, z + 10, Library.getRandomConcrete(), 0, 3);
		world.setBlock(x + 5, y + -13, z + 11, Library.getRandomConcrete(), 0, 3);
		world.setBlock(x + 6, y + -13, z + 11, Blocks.air, 0, 3);
		world.setBlock(x + 7, y + -13, z + 11, Blocks.air, 0, 3);
		world.setBlock(x + 8, y + -13, z + 11, Blocks.air, 0, 3);
		world.setBlock(x + 9, y + -13, z + 11, Blocks.air, 0, 3);
		world.setBlock(x + 10, y + -13, z + 11, Blocks.air, 0, 3);
		world.setBlock(x + 11, y + -13, z + 11, Blocks.air, 0, 3);
		world.setBlock(x + 12, y + -13, z + 11, Blocks.air, 0, 3);
		world.setBlock(x + 13, y + -13, z + 11, Library.getRandomConcrete(), 0, 3);
		world.setBlock(x + 6, y + -13, z + 12, Library.getRandomConcrete(), 0, 3);
		world.setBlock(x + 7, y + -13, z + 12, Blocks.air, 0, 3);
		world.setBlock(x + 8, y + -13, z + 12, Blocks.air, 0, 3);
		world.setBlock(x + 9, y + -13, z + 12, Blocks.air, 0, 3);
		world.setBlock(x + 10, y + -13, z + 12, Blocks.air, 0, 3);
		world.setBlock(x + 11, y + -13, z + 12, Blocks.air, 0, 3);
		world.setBlock(x + 12, y + -13, z + 12, Library.getRandomConcrete(), 0, 3);
		world.setBlock(x + 6, y + -13, z + 13, Library.getRandomConcrete(), 0, 3);
		world.setBlock(x + 7, y + -13, z + 13, Library.getRandomConcrete(), 0, 3);
		world.setBlock(x + 8, y + -13, z + 13, Blocks.air, 0, 3);
		world.setBlock(x + 9, y + -13, z + 13, Blocks.air, 0, 3);
		world.setBlock(x + 10, y + -13, z + 13, Blocks.air, 0, 3);
		world.setBlock(x + 11, y + -13, z + 13, Library.getRandomConcrete(), 0, 3);
		world.setBlock(x + 12, y + -13, z + 13, Library.getRandomConcrete(), 0, 3);
		world.setBlock(x + 8, y + -13, z + 14, Library.getRandomConcrete(), 0, 3);
		world.setBlock(x + 9, y + -13, z + 14, Library.getRandomConcrete(), 0, 3);
		world.setBlock(x + 10, y + -13, z + 14, Library.getRandomConcrete(), 0, 3);
		world.setBlock(x + 7, y + -12, z + 1, Library.getRandomConcrete(), 0, 3);
		world.setBlock(x + 8, y + -12, z + 1, Library.getRandomConcrete(), 0, 3);
		world.setBlock(x + 9, y + -12, z + 1, Block3, 0, 3);
		world.setBlock(x + 10, y + -12, z + 1, Library.getRandomConcrete(), 0, 3);
		world.setBlock(x + 11, y + -12, z + 1, Library.getRandomConcrete(), 0, 3);
		world.setBlock(x + 7, y + -12, z + 2, Library.getRandomConcrete(), 0, 3);
		world.setBlock(x + 8, y + -12, z + 2, Library.getRandomConcrete(), 0, 3);
		world.setBlock(x + 10, y + -12, z + 2, Library.getRandomConcrete(), 0, 3);
		world.setBlock(x + 11, y + -12, z + 2, Library.getRandomConcrete(), 0, 3);
		world.setBlock(x + 7, y + -12, z + 3, Library.getRandomConcrete(), 0, 3);
		world.setBlock(x + 8, y + -12, z + 3, Library.getRandomConcrete(), 0, 3);
		world.setBlock(x + 9, y + -12, z + 3, Library.getRandomConcrete(), 0, 3);
		world.setBlock(x + 10, y + -12, z + 3, Library.getRandomConcrete(), 0, 3);
		world.setBlock(x + 11, y + -12, z + 3, Library.getRandomConcrete(), 0, 3);
		world.setBlock(x + 7, y + -12, z + 4, Library.getRandomConcrete(), 0, 3);
		world.setBlock(x + 8, y + -12, z + 4, Library.getRandomConcrete(), 0, 3);
		world.setBlock(x + 9, y + -12, z + 4, Library.getRandomConcrete(), 0, 3);
		world.setBlock(x + 10, y + -12, z + 4, Library.getRandomConcrete(), 0, 3);
		world.setBlock(x + 11, y + -12, z + 4, Library.getRandomConcrete(), 0, 3);
		world.setBlock(x + 12, y + -12, z + 4, Library.getRandomConcrete(), 0, 3);
		world.setBlock(x + 13, y + -12, z + 4, Library.getRandomConcrete(), 0, 3);
		world.setBlock(x + 14, y + -12, z + 4, Library.getRandomConcrete(), 0, 3);
		world.setBlock(x + 15, y + -12, z + 4, Library.getRandomConcrete(), 0, 3);
		world.setBlock(x + 7, y + -12, z + 5, Library.getRandomConcrete(), 0, 3);
		world.setBlock(x + 8, y + -12, z + 5, Blocks.redstone_wire, 15, 3);
		world.setBlock(x + 9, y + -12, z + 5, Blocks.stone_slab, 8, 3);
		world.setBlock(x + 10, y + -12, z + 5, Library.getRandomConcrete(), 0, 3);
		world.setBlock(x + 11, y + -12, z + 5, Library.getRandomConcrete(), 0, 3);
		world.setBlock(x + 12, y + -12, z + 5, Library.getRandomConcrete(), 0, 3);
		world.setBlock(x + 13, y + -12, z + 5, Library.getRandomConcrete(), 0, 3);
		world.setBlock(x + 14, y + -12, z + 5, Library.getRandomConcrete(), 0, 3);
		world.setBlock(x + 15, y + -12, z + 5, Library.getRandomConcrete(), 0, 3);
		world.setBlock(x + 7, y + -12, z + 6, Library.getRandomConcrete(), 0, 3);
		world.setBlock(x + 8, y + -12, z + 6, Library.getRandomConcrete(), 0, 3);
		world.setBlock(x + 9, y + -12, z + 6, Library.getRandomConcrete(), 0, 3);
		world.setBlock(x + 10, y + -12, z + 6, Library.getRandomConcrete(), 0, 3);
		world.setBlock(x + 11, y + -12, z + 6, Library.getRandomConcrete(), 0, 3);
		world.setBlock(x + 12, y + -12, z + 6, Library.getRandomConcrete(), 0, 3);
		world.setBlock(x + 13, y + -12, z + 6, Library.getRandomConcrete(), 0, 3);
		world.setBlock(x + 14, y + -12, z + 6, Library.getRandomConcrete(), 0, 3);
		world.setBlock(x + 15, y + -12, z + 6, Library.getRandomConcrete(), 0, 3);
		world.setBlock(x + 6, y + -12, z + 7, Library.getRandomConcrete(), 0, 3);
		world.setBlock(x + 7, y + -12, z + 7, Library.getRandomConcrete(), 0, 3);
		world.setBlock(x + 8, y + -12, z + 7, Blocks.air, 0, 3);
		world.setBlock(x + 9, y + -12, z + 7, Blocks.air, 0, 3);
		world.setBlock(x + 10, y + -12, z + 7, Blocks.air, 0, 3);
		world.setBlock(x + 11, y + -12, z + 7, Library.getRandomConcrete(), 0, 3);
		world.setBlock(x + 12, y + -12, z + 7, Library.getRandomConcrete(), 0, 3);
		world.setBlock(x + 6, y + -12, z + 8, Library.getRandomConcrete(), 0, 3);
		world.setBlock(x + 7, y + -12, z + 8, Blocks.air, 0, 3);
		world.setBlock(x + 8, y + -12, z + 8, Blocks.air, 0, 3);
		world.setBlock(x + 9, y + -12, z + 8, Blocks.air, 0, 3);
		world.setBlock(x + 10, y + -12, z + 8, Blocks.air, 0, 3);
		world.setBlock(x + 11, y + -12, z + 8, Blocks.air, 0, 3);
		world.setBlock(x + 12, y + -12, z + 8, Library.getRandomConcrete(), 0, 3);
		world.setBlock(x + 5, y + -12, z + 9, Library.getRandomConcrete(), 0, 3);
		world.setBlock(x + 6, y + -12, z + 9, Blocks.air, 0, 3);
		world.setBlock(x + 7, y + -12, z + 9, Blocks.air, 0, 3);
		world.setBlock(x + 8, y + -12, z + 9, Blocks.air, 0, 3);
		world.setBlock(x + 9, y + -12, z + 9, Blocks.air, 0, 3);
		world.setBlock(x + 10, y + -12, z + 9, Blocks.air, 0, 3);
		world.setBlock(x + 11, y + -12, z + 9, Blocks.air, 0, 3);
		world.setBlock(x + 12, y + -12, z + 9, Blocks.air, 0, 3);
		world.setBlock(x + 13, y + -12, z + 9, Library.getRandomConcrete(), 0, 3);
		world.setBlock(x + 5, y + -12, z + 10, Library.getRandomConcrete(), 0, 3);
		world.setBlock(x + 6, y + -12, z + 10, Blocks.air, 0, 3);
		world.setBlock(x + 7, y + -12, z + 10, Blocks.air, 0, 3);
		world.setBlock(x + 8, y + -12, z + 10, Blocks.air, 0, 3);
		world.setBlock(x + 9, y + -12, z + 10, Blocks.air, 0, 3);
		world.setBlock(x + 10, y + -12, z + 10, Blocks.air, 0, 3);
		world.setBlock(x + 11, y + -12, z + 10, Blocks.air, 0, 3);
		world.setBlock(x + 12, y + -12, z + 10, Blocks.air, 0, 3);
		world.setBlock(x + 13, y + -12, z + 10, Library.getRandomConcrete(), 0, 3);
		world.setBlock(x + 5, y + -12, z + 11, Library.getRandomConcrete(), 0, 3);
		world.setBlock(x + 6, y + -12, z + 11, Blocks.air, 0, 3);
		world.setBlock(x + 7, y + -12, z + 11, Blocks.air, 0, 3);
		world.setBlock(x + 8, y + -12, z + 11, Blocks.air, 0, 3);
		world.setBlock(x + 9, y + -12, z + 11, Blocks.air, 0, 3);
		world.setBlock(x + 10, y + -12, z + 11, Blocks.air, 0, 3);
		world.setBlock(x + 11, y + -12, z + 11, Blocks.air, 0, 3);
		world.setBlock(x + 12, y + -12, z + 11, Blocks.air, 0, 3);
		world.setBlock(x + 13, y + -12, z + 11, Library.getRandomConcrete(), 0, 3);
		world.setBlock(x + 6, y + -12, z + 12, Library.getRandomConcrete(), 0, 3);
		world.setBlock(x + 7, y + -12, z + 12, Blocks.air, 0, 3);
		world.setBlock(x + 8, y + -12, z + 12, Blocks.air, 0, 3);
		world.setBlock(x + 9, y + -12, z + 12, Blocks.air, 0, 3);
		world.setBlock(x + 10, y + -12, z + 12, Blocks.air, 0, 3);
		world.setBlock(x + 11, y + -12, z + 12, Blocks.air, 0, 3);
		world.setBlock(x + 12, y + -12, z + 12, Library.getRandomConcrete(), 0, 3);
		world.setBlock(x + 6, y + -12, z + 13, Library.getRandomConcrete(), 0, 3);
		world.setBlock(x + 7, y + -12, z + 13, Library.getRandomConcrete(), 0, 3);
		world.setBlock(x + 8, y + -12, z + 13, Blocks.air, 0, 3);
		world.setBlock(x + 9, y + -12, z + 13, Blocks.air, 0, 3);
		world.setBlock(x + 10, y + -12, z + 13, Blocks.air, 0, 3);
		world.setBlock(x + 11, y + -12, z + 13, Library.getRandomConcrete(), 0, 3);
		world.setBlock(x + 12, y + -12, z + 13, Library.getRandomConcrete(), 0, 3);
		world.setBlock(x + 8, y + -12, z + 14, Library.getRandomConcrete(), 0, 3);
		world.setBlock(x + 9, y + -12, z + 14, Library.getRandomConcrete(), 0, 3);
		world.setBlock(x + 10, y + -12, z + 14, Library.getRandomConcrete(), 0, 3);
		world.setBlock(x + 7, y + -11, z + 1, Library.getRandomConcrete(), 0, 3);
		world.setBlock(x + 8, y + -11, z + 1, Library.getRandomConcrete(), 0, 3);
		world.setBlock(x + 9, y + -11, z + 1, Library.getRandomConcrete(), 0, 3);
		world.setBlock(x + 10, y + -11, z + 1, Library.getRandomConcrete(), 0, 3);
		world.setBlock(x + 11, y + -11, z + 1, Library.getRandomConcrete(), 0, 3);
		world.setBlock(x + 7, y + -11, z + 2, Library.getRandomConcrete(), 0, 3);
		world.setBlock(x + 8, y + -11, z + 2, Library.getRandomConcrete(), 0, 3);
		world.setBlock(x + 10, y + -11, z + 2, Library.getRandomConcrete(), 0, 3);
		world.setBlock(x + 11, y + -11, z + 2, Library.getRandomConcrete(), 0, 3);
		world.setBlock(x + 7, y + -11, z + 3, Library.getRandomConcrete(), 0, 3);
