package com.hbm.world.worldgen.components;

import java.util.Random;

import com.hbm.blocks.ModBlocks;

import net.minecraft.init.Blocks;
import net.minecraft.world.World;
import net.minecraft.world.gen.structure.StructureBoundingBox;

public class RuinFeatures {
	
	public static class NTMRuin1 extends Feature {
		
		private static ConcreteBricks RandomConcreteBricks = new ConcreteBricks();
		
		public NTMRuin1() {
			super();
		}
		
		public NTMRuin1(Random rand, int minX, int minY, int minZ) {
			super(rand, minX, minY, minZ, 8, 6, 10);
		}

		@Override
		public boolean addComponentParts(World world, Random rand, StructureBoundingBox box) {
			
			//System.out.println(this.coordBaseMode);
			if(!this.setAverageHeight(world, box, this.boundingBox.minY)) {
				return false;
			}
			//System.out.println("" + this.boundingBox.minX + ", " + this.boundingBox.minY + ", " + this.boundingBox.minZ);
			
			for(byte i = 0; i < sizeX + 1; i++) {
				for(byte j = 0; j < sizeZ + 1; j++) {
					this.func_151554_b(world, Blocks.stonebrick, 0, i, -1, j, box);
				}
			}
			
			int pillarMetaWE = this.getPillarMeta(4);
			int pillarMetaNS = this.getPillarMeta(8);
			
			this.fillWithBlocks(world, box, 0, 0, 0, 0, sizeY, 0, ModBlocks.concrete_pillar, Blocks.air, false); //Back Wall
			this.fillWithMetadataBlocks(world, box, 1, 3, 0, 3, 3, 0, ModBlocks.concrete_pillar, pillarMetaWE, Blocks.air, 0, false);
			this.fillWithBlocks(world, box, 4, 0, 0, 4, sizeY - 1, 0, ModBlocks.concrete_pillar, Blocks.air, false);
			this.fillWithMetadataBlocks(world, box, 5, 3, 0, sizeX - 1, 3, 0, ModBlocks.concrete_pillar, pillarMetaWE, Blocks.air, 0, false);
			this.fillWithBlocks(world, box, sizeX, 0, 0, sizeX, sizeY - 1, 0, ModBlocks.concrete_pillar, Blocks.air, false);
			this.fillWithRandomizedBlocks(world, box, 1, 0, 0, 3, 0, 0, false, rand, RandomConcreteBricks);
			this.fillWithRandomizedBlocks(world, box, 5, 0, 0, sizeX - 1, 0, 0, false, rand, RandomConcreteBricks);
			this.fillWithRandomizedBlocks(world, box, 1, 1, 0, 1, 2, 0, false, rand, RandomConcreteBricks);
			this.fillWithRandomizedBlocks(world, box, 3, 1, 0, 3, 2, 0, false, rand, RandomConcreteBricks);
			this.fillWithRandomizedBlocks(world, box, 5, 1, 0, 5, 2, 0, false, rand, RandomConcreteBricks);
			this.fillWithRandomizedBlocks(world, box, sizeX - 1, 1, 0, sizeX - 1, 2, 0, false, rand, RandomConcreteBricks);
			this.fillWithRandomizedBlocks(world, box, 1, 4, 0, 3, 4, 0, false, rand, RandomConcreteBricks);
			this.fillWithRandomizedBlocks(world, box, 5, 4, 0, sizeX - 1, 4, 0, false, rand, RandomConcreteBricks);
			this.fillWithMetadataBlocks(world, box, 0, 3, 1, 0, 3, sizeZ - 1, ModBlocks.concrete_pillar, pillarMetaNS, Blocks.air, 0, false); //Left Wall
			this.fillWithBlocks(world, box, 0, 0, sizeZ, 0, sizeY - 1, sizeZ, ModBlocks.concrete_pillar, Blocks.air, false);
			this.fillWithRandomizedBlocks(world, box, 0, 0, 1, 0, 0, sizeZ - 1, false, rand, RandomConcreteBricks);
			this.fillWithRandomizedBlocks(world, box, 0, 1, 1, 0, 2, 2, false, rand, RandomConcreteBricks);
			this.fillWithRandomizedBlocks(world, box, 0, 1, 4, 0, 2, 6, false, rand, RandomConcreteBricks);
			this.fillWithRandomizedBlocks(world, box, 0, 1, sizeZ - 2, 0, 2, sizeZ - 1, false, rand, RandomConcreteBricks);
			this.fillWithRandomizedBlocks(world, box, 0, 4, 1, 0, 4, 5, false, rand, RandomConcreteBricks);
			this.fillWithRandomizedBlocks(world, box, 0, 5, 1, 0, 5, 2, false, rand, RandomConcreteBricks);
			this.fillWithRandomizedBlocks(world, box, 0, 4, sizeZ - 2, 0, 4, sizeZ - 1, false, rand, RandomConcreteBricks);
			this.fillWithMetadataBlocks(world, box, 1, 3, sizeZ, 3, 3, sizeZ, ModBlocks.concrete_pillar, pillarMetaWE, Blocks.air, 0, false); //Front Wall
			this.fillWithBlocks(world, box, 4, 0, sizeZ, 4, sizeY - 2, sizeZ, ModBlocks.concrete_pillar, Blocks.air, false);
			this.fillWithMetadataBlocks(world, box, 5, 3, sizeZ, sizeX - 1, 3, sizeZ, ModBlocks.concrete_pillar, pillarMetaWE, Blocks.air, 0, false);
			this.fillWithBlocks(world, box, sizeX, 0, sizeZ, sizeX, sizeY - 2, sizeZ, ModBlocks.concrete_pillar, Blocks.air, false);
			this.fillWithRandomizedBlocks(world, box, 1, 0, sizeZ, 3, 0, sizeZ, false, rand, RandomConcreteBricks);
			this.fillWithRandomizedBlocks(world, box, 5, 0, sizeZ, sizeX - 1, 0, sizeZ, false, rand, RandomConcreteBricks);
			this.fillWithRandomizedBlocks(world, box, 1, 1, sizeZ, 1, 2, sizeZ, false, rand, RandomConcreteBricks);
			this.fillWithRandomizedBlocks(world, box, 3, 1, sizeZ, 3, 2, sizeZ, false, rand, RandomConcreteBricks);
			this.fillWithRandomizedBlocks(world, box, 5, 1, sizeZ, 5, 2, sizeZ, false, rand, RandomConcreteBricks);
			this.fillWithRandomizedBlocks(world, box, sizeX - 1, 1, sizeZ, sizeX - 1, 2, sizeZ, false, rand, RandomConcreteBricks);
			this.fillWithMetadataBlocks(world, box, sizeX, 3, 1, sizeX, 3, 2, ModBlocks.concrete_pillar, pillarMetaNS, Blocks.air, 0, false); //Right Wall
			this.fillWithMetadataBlocks(world, box, sizeX, 3, sizeZ - 1, sizeX, 3, sizeZ - 1, ModBlocks.concrete_pillar, pillarMetaNS, Blocks.air, 0, false);
			this.fillWithRandomizedBlocks(world, box, sizeX, 0, 1, sizeX, 0, 4, false, rand, RandomConcreteBricks);
			this.fillWithRandomizedBlocks(world, box, sizeX, 1, 1, sizeX, 2, 2, false, rand, RandomConcreteBricks);
			this.fillWithRandomizedBlocks(world, box, sizeX, 0, 6, sizeX, 0, 6, false, rand, RandomConcreteBricks);
			this.fillWithRandomizedBlocks(world, box, sizeX, 0, sizeZ - 2, sizeX, 1, sizeZ - 1, false, rand, RandomConcreteBricks);
			this.fillWithRandomizedBlocks(world, box, sizeX, 2, sizeZ - 1, sizeX, 2, sizeZ - 1, false, rand, RandomConcreteBricks);
			
			this.randomlyFillWithBlocks(world, box, rand, 0.25F, 1, 0, 1, sizeX - 1, 0, sizeZ - 1, Blocks.gravel, Blocks.air, false);
			
			return true;
		}
	}
	
	public static class NTMRuin2 extends Feature {
		
		private static ConcreteBricks RandomConcreteBricks = new ConcreteBricks();
		
		public NTMRuin2() {
			super();
		}
		
		public NTMRuin2(Random rand, int minX, int minY, int minZ) {
			super(rand, minX, minY, minZ, 7, 5, 10);
		}

		@Override
		public boolean addComponentParts(World world, Random rand, StructureBoundingBox box) {
			
			//System.out.println(this.coordBaseMode);
			if(!this.setAverageHeight(world, box, this.boundingBox.minY)) {
				return false;
			}
			//System.out.println("" + this.boundingBox.minX + ", " + this.boundingBox.minY + ", " + this.boundingBox.minZ);
			
			for(byte i = 0; i < sizeX + 1; i++) {
				for(byte j = 0; j < sizeZ + 1; j++) {
					this.func_151554_b(world, Blocks.stonebrick, 0, i, -1, j, box);
				}
			}
			
			int pillarMetaWE = this.getPillarMeta(4);
			int pillarMetaNS = this.getPillarMeta(8);
			
			this.fillWithBlocks(world, box, 0, 0, 0, 0, 3, 0, ModBlocks.concrete_pillar, Blocks.air, false); //Back Wall
			this.fillWithMetadataBlocks(world, box, 1, 3, 0, sizeX - 1, 3, 0, ModBlocks.concrete_pillar, pillarMetaWE, Blocks.air, 0, false);
			this.fillWithBlocks(world, box, sizeX, 0, 0, sizeX, sizeY, 0, ModBlocks.concrete_pillar, Blocks.air, false);
			this.fillWithRandomizedBlocks(world, box, 1, 0, 0, sizeX - 1, 0, 0, false, rand, RandomConcreteBricks);
			this.fillWithRandomizedBlocks(world, box, 1, 1, 0, 1, 2, 0, false, rand, RandomConcreteBricks);
			this.fillWithRandomizedBlocks(world, box, 3, 1, 0, 4, 2, 0, false, rand, RandomConcreteBricks);
			this.fillWithRandomizedBlocks(world, box, sizeX - 1, 1, 0, sizeX - 1, 2, 0, false, rand, RandomConcreteBricks);
			this.fillWithRandomizedBlocks(world, box, 3, 4, 0, sizeX - 1, 4, 0, false, rand, RandomConcreteBricks);
			this.fillWithRandomizedBlocks(world, box, sizeX - 1, sizeY, 0, sizeX - 1, sizeY, 0, false, rand, RandomConcreteBricks);
			this.fillWithMetadataBlocks(world, box, 0, 3, 1, 0, 3, 4, ModBlocks.concrete_pillar, pillarMetaNS, Blocks.air, 0, false); //Left Wall
			this.fillWithBlocks(world, box, 0, 0, 5, 0, 0, 5, ModBlocks.concrete_pillar, Blocks.air, false);
			this.fillWithBlocks(world, box, 0, 0, sizeZ, 0, 2, sizeZ, ModBlocks.concrete_pillar, Blocks.air, false);
			this.fillWithRandomizedBlocks(world, box, 0, 0, 1, 0, 2, 3, false, rand, RandomConcreteBricks);
			this.fillWithRandomizedBlocks(world, box, 0, 0, sizeZ - 3, 0, 0, sizeZ - 1, false, rand, RandomConcreteBricks);
			this.fillWithRandomizedBlocks(world, box, 0, 1, sizeZ - 1, 0, 1, sizeZ - 1, false, rand, RandomConcreteBricks);
			this.fillWithMetadataBlocks(world, box, sizeX - 1, 3, sizeZ, sizeX - 1, 3, sizeZ, ModBlocks.concrete_pillar, pillarMetaWE, Blocks.air, 0, false); //Front Wall
			this.fillWithBlocks(world, box, sizeX, 0, sizeZ, sizeX, 3, sizeZ, ModBlocks.concrete_pillar, Blocks.air, false);
			this.fillWithRandomizedBlocks(world, box, 1, 0, sizeZ, sizeX - 1, 0, sizeZ, false, rand, RandomConcreteBricks);
			this.fillWithRandomizedBlocks(world, box, 1, 1, sizeZ, 1, 2, sizeZ, false, rand, RandomConcreteBricks);
			this.fillWithRandomizedBlocks(world, box, sizeX - 1, 1, sizeZ, sizeX - 1, 2, sizeZ, false, rand, RandomConcreteBricks);
			this.fillWithMetadataBlocks(world, box, sizeX, 3, 1, sizeX, 3, 4, ModBlocks.concrete_pillar, pillarMetaNS, Blocks.air, 0, false); //Right Wall
			this.fillWithBlocks(world, box, sizeX, 0, 5, sizeX, 4, 5, ModBlocks.concrete_pillar, Blocks.air, false);
			this.fillWithMetadataBlocks(world, box, sizeX, 3, sizeZ - 2, sizeX, 3, sizeZ - 1, ModBlocks.concrete_pillar, pillarMetaNS, Blocks.air, 0, false);
			this.fillWithRandomizedBlocks(world, box, sizeX, 0, 1, sizeX, 0, 4, false, rand, RandomConcreteBricks);
			this.fillWithRandomizedBlocks(world, box, sizeX, 1, 1, sizeX, 2, 1, false, rand, RandomConcreteBricks);
			this.fillWithRandomizedBlocks(world, box, sizeX, 1, 3, sizeX, 2, 3, false, rand, RandomConcreteBricks);
			this.fillWithRandomizedBlocks(world, box, sizeX, 1, 4, sizeX, 1, 4, false, rand, RandomConcreteBricks);
			this.fillWithRandomizedBlocks(world, box, sizeX, 0, 6, sizeX, 0, sizeZ - 1, false, rand, RandomConcreteBricks);
			this.fillWithRandomizedBlocks(world, box, sizeX, 1, 6, sizeX, 1, 7, false, rand, RandomConcreteBricks);
			this.fillWithRandomizedBlocks(world, box, sizeX, 1, sizeZ - 1, sizeX, 2, sizeZ - 1, false, rand, RandomConcreteBricks);
			
			this.randomlyFillWithBlocks(world, box, rand, 0.25F, 1, 0, 1, sizeX - 1, 0, sizeZ - 1, Blocks.gravel, Blocks.air, false);
			
			return true;
		}
	}
	
	public static class NTMRuin3 extends Feature {
		
		private static ConcreteBricks RandomConcreteBricks = new ConcreteBricks();
		
		public NTMRuin3() {
			super();
		}
		
		public NTMRuin3(Random rand, int minX, int minY, int minZ) {
			super(rand, minX, minY, minZ, 8, 3, 10);
		}

		@Override
		public boolean addComponentParts(World world, Random rand, StructureBoundingBox box) {
			
			//System.out.println(this.coordBaseMode);
			if(!this.setAverageHeight(world, box, this.boundingBox.minY)) {
				return false;
			}
			//System.out.println("" + this.boundingBox.minX + ", " + this.boundingBox.minY + ", " + this.boundingBox.minZ);
			
			for(byte i = 0; i < sizeZ + 1; i++) {
					this.func_151554_b(world, Blocks.stonebrick, 0, 0, -1, i, box);
					this.func_151554_b(world, Blocks.stonebrick, 0, sizeX, -1, i, box);
			}
			
			for(byte i = 1; i < sizeX; i++) {
				this.func_151554_b(world, Blocks.stonebrick, 0, i, -1, 0, box);
				this.func_151554_b(world, Blocks.stonebrick, 0, i, -1, 4, box);
			}
			
			this.fillWithBlocks(world, box, 0, 0, 0, 0, sizeY, 0, ModBlocks.concrete_pillar, Blocks.air, false); //Back Wall
			this.fillWithBlocks(world, box, sizeX, 0, 0, sizeX, 1, 0, ModBlocks.concrete_pillar, Blocks.air, false);
			this.fillWithRandomizedBlocks(world, box, 1, 0, 0, sizeX - 1, 0, 0, false, rand, RandomConcreteBricks);
			this.fillWithRandomizedBlocks(world, box, 1, 1, 0, 1, 1, 0, false, rand, RandomConcreteBricks);
			this.fillWithRandomizedBlocks(world, box, 4, 1, 0, 4, 1, 0, false, rand, RandomConcreteBricks);
			this.fillWithRandomizedBlocks(world, box, sizeX - 1, 1, 0, sizeX - 1, 1, 0, false, rand, RandomConcreteBricks);
			this.fillWithRandomizedBlocks(world, box, 1, 2, 0, sizeX - 2, 2, 0, false, rand, RandomConcreteBricks);
			this.fillWithBlocks(world, box, 0, 0, 4, 0, 1, 4, ModBlocks.concrete_pillar, Blocks.air, false); //Left Wall
			this.placeBlockAtCurrentPosition(world, ModBlocks.concrete_pillar, 0, 0, 0, sizeZ, box);
			this.fillWithRandomizedBlocks(world, box, 0, 0, 1, 0, 0, 3, false, rand, RandomConcreteBricks);
			this.fillWithRandomizedBlocks(world, box, 0, 0, 5, 0, 0, sizeZ - 1, false, rand, RandomConcreteBricks);
			this.fillWithRandomizedBlocks(world, box, 0, 1, 5, 0, 1, 5, false, rand, RandomConcreteBricks);
			this.fillWithRandomizedBlocks(world, box, 0, 1, 7, 0, 1, 7, false, rand, RandomConcreteBricks);
			this.fillWithBlocks(world, box, sizeX, 0, 4, sizeX, 1, 4, ModBlocks.concrete_pillar, Blocks.air, false); //Right Wall
			this.fillWithBlocks(world, box, sizeX, 0, sizeZ, sizeX, 1, sizeZ, ModBlocks.concrete_pillar, Blocks.air, false);
			this.fillWithRandomizedBlocks(world, box, sizeX, 0, 1, sizeX, 1, 3, false, rand, RandomConcreteBricks);
			this.fillWithRandomizedBlocks(world, box, sizeX, 0, 5, sizeX, 0, 6, false, rand, RandomConcreteBricks);
			this.fillWithRandomizedBlocks(world, box, sizeX, 0, sizeZ - 1, sizeX, 0, sizeZ - 1, false, rand, RandomConcreteBricks);
			this.fillWithRandomizedBlocks(world, box, sizeX - 1, 0, sizeZ, sizeX - 1, 0, sizeZ, false, rand, RandomConcreteBricks);
			this.fillWithBlocks(world, box, 4, 0, 4, 4, 2, 4, ModBlocks.concrete_pillar, Blocks.air, false); //Center Wall
			this.fillWithRandomizedBlocks(world, box, 3, 0, 4, 3, 1, 4, false, rand, RandomConcreteBricks);
			this.fillWithRandomizedBlocks(world, box, 5, 0, 4, sizeX - 1, 1, 4, false, rand, RandomConcreteBricks);
			
			this.randomlyFillWithBlocks(world, box, rand, 0.05F, 1, 0, 1, sizeX - 1, 0, 3, Blocks.gravel, Blocks.air, false);
			this.randomlyFillWithBlocks(world, box, rand, 0.05F, 1, 0, 5, sizeX - 1, 0, sizeZ - 1, Blocks.gravel, Blocks.air, false);
			
			return true;
		}
	}
	
	public static class NTMRuin4 extends Feature {
		
		private static ConcreteBricks RandomConcreteBricks = new ConcreteBricks();
		
		public NTMRuin4() {
			super();
		}
		
		public NTMRuin4(Random rand, int minX, int minY, int minZ) {
			super(rand, minX, minY, minZ, 10, 2, 11);
		}

		@Override
		public boolean addComponentParts(World world, Random rand, StructureBoundingBox box) {
			
			//System.out.println(this.coordBaseMode);
			if(!this.setAverageHeight(world, box, this.boundingBox.minY)) {
				return false;
			}
			//System.out.println("" + this.boundingBox.minX + ", " + this.boundingBox.minY + ", " + this.boundingBox.minZ);
			
			for(byte i = 0; i < sizeZ + 1; i++) {
				this.func_151554_b(world, Blocks.stonebrick, 0, 0, -1, i, box);
				this.func_151554_b(world, Blocks.stonebrick, 0, i >= 5 ? sizeX : 5, -1, i, box); //elegant solution
			}
			
			for(byte i = 1; i < sizeX; i++) {
				this.func_151554_b(world, Blocks.stonebrick, 0, i, -1, sizeZ, box);
				this.func_151554_b(world, Blocks.stonebrick, 0, i, -1, i > 4 ? 5 : 0, box); //ternary operators my beloved
			}
			
			this.fillWithBlocks(world, box, 0, 0, 0, 0, 1, 0, ModBlocks.concrete_pillar, Blocks.air, false); //Back Wall Pt. 1
			this.fillWithBlocks(world, box, 5, 0, 0, 5, sizeY, 0, ModBlocks.concrete_pillar, Blocks.air, false);
			this.fillWithRandomizedBlocks(world, box, 1, 0, 0, 4, 0, 0, false, rand, RandomConcreteBricks);
			this.fillWithRandomizedBlocks(world, box, 4, 1, 0, 4, 1, 0, false, rand, RandomConcreteBricks);
			this.fillWithBlocks(world, box, 5, 0, 5, 5, sizeY, 5, ModBlocks.concrete_pillar, Blocks.air, false); //Right Wall Pt. 1
			this.fillWithRandomizedBlocks(world, box, 5, 0, 1, 5, 0, 4, false, rand, RandomConcreteBricks);
			this.fillWithRandomizedBlocks(world, box, 5, 1, 1, 5, 1, 1, false, rand, RandomConcreteBricks);
			this.fillWithRandomizedBlocks(world, box, 5, 1, 4, 5, 1, 4, false, rand, RandomConcreteBricks);
			this.fillWithRandomizedBlocks(world, box, 5, 2, 1, 5, 2, 4, false, rand, RandomConcreteBricks);
			this.fillWithBlocks(world, box, sizeX, 0, 5, sizeX, 1, 5, ModBlocks.concrete_pillar, Blocks.air, false); //Back Wall Pt. 2
			this.fillWithRandomizedBlocks(world, box, 6, 0, 5, sizeX - 1, 0, 5, false, rand, RandomConcreteBricks);
			this.fillWithRandomizedBlocks(world, box, 6, 1, 5, 6, 1, 5, false, rand, RandomConcreteBricks);
			this.fillWithRandomizedBlocks(world, box, sizeX - 1, 1, 5, sizeX - 1, 1, 5, false, rand, RandomConcreteBricks);
			this.fillWithBlocks(world, box, sizeX, 0, sizeZ, sizeX, 1, sizeZ, ModBlocks.concrete_pillar, Blocks.air, false); //Right Wall Pt. 2
			this.fillWithRandomizedBlocks(world, box, sizeX, 0, 6, sizeX, 0, sizeZ - 1, false, rand, RandomConcreteBricks);
			this.fillWithRandomizedBlocks(world, box, sizeX, 1, 6, sizeX, 1, sizeZ - 3, false, rand, RandomConcreteBricks);
			this.fillWithBlocks(world, box, 0, 0, sizeZ, 0, 0, sizeZ, ModBlocks.concrete_pillar, Blocks.air, false); //Front Wall
			this.fillWithRandomizedBlocks(world, box, 1, 0, sizeZ, 1, 0, sizeZ, false, rand, RandomConcreteBricks);
			this.fillWithRandomizedBlocks(world, box, 6, 0, sizeZ, 7, 0, sizeZ, false, rand, RandomConcreteBricks);
			this.fillWithRandomizedBlocks(world, box, sizeX - 1, 0, sizeZ, sizeX - 1, 0, sizeZ, false, rand, RandomConcreteBricks);
			this.fillWithRandomizedBlocks(world, box, 0, 0, 1, 0, 0, sizeZ - 1, false, rand, RandomConcreteBricks); //Left Wall
			this.fillWithRandomizedBlocks(world, box, 0, 1, 1, 0, 1, 1, false, rand, RandomConcreteBricks);
			this.fillWithRandomizedBlocks(world, box, 0, 1, 4, 0, 1, 7, false, rand, RandomConcreteBricks);
			
			this.randomlyFillWithBlocks(world, box, rand, 0.05F, 1, 0, 1, 4, 0, 5, Blocks.gravel, Blocks.air, false);
			this.randomlyFillWithBlocks(world, box, rand, 0.05F, 1, 0, 6, sizeX - 1, 0, sizeZ - 1, Blocks.gravel, Blocks.air, false);
			
			return true;
		}
	}
	
}
